Workbook
Name ____str1: #REF!
Name ____str2: #REF!
Name ____str3: #REF!
Name ___str1: #REF!
Name ___str2: #REF!
Name ___str3: #REF!
Name __str1: #REF!
Name __str2: #REF!
Name __str3: #REF!
Name _1Excel_BuiltIn_Print_Area_1_1: #REF!
Name _str1: #REF!
Name _str2: #REF!
Name _str3: #REF!
Name A: #REF!
Name A: #REF!
Name A: #REF!
Name A: #REF!
Name A: #REF!
Name A: #REF!
Name A: #REF!
Name A: #REF!
Name A: #REF!
Name A: #REF!
Name A: #REF!
Name A: #REF!
Name A: #REF!
Name A: #REF!
Name A: #REF!
Name ABL: '[1]Summary SN FP'!#REF!
Name ada: #REF!
Name ARCH_LAB: #REF!
Name ARCH_MAT: #REF!
Name Cavity_Pump: '[1]Summary SN FP'!#REF!
Name Decanter: '[1]Summary SN FP'!#REF!
Name Excel_BuiltIn_Print_Area: #REF!
Name Excel_BuiltIn_Print_Titles: #REF!
Name EXT_LAB: #REF!
Name EXT_MAT: #REF!
Name f: #REF!
Name FP: '[1]Summary SN FP'!#REF!
Name I: #REF!
Name I: #REF!
Name I: #REF!
Name I: #REF!
Name I: #REF!
Name I: #REF!
Name I: #REF!
Name I: #REF!
Name I: #REF!
Name I: #REF!
Name IX: #REF!
Name IX: #REF!
Name IX: #REF!
Name IX: #REF!
Name IX: #REF!
Name IX: #REF!
Name IX: #REF!
Name IX: #REF!
Name IX: #REF!
Name IY: #REF!

Sheet RC2_ปร.6
E1: แบบ ปร.6
A2: แบบสรุปราคาค่าก่อสร้างงานอาคาร
A4: โครงการ | C4: Ratchadamnoen Knowledge & Culture Avenue
A5: สถานที่ก่อสร้าง | C5: ถนนราชดำเนิน กรุงเทพ
A6: เจ้าของอาคาร | C6: สำนักงานบริหารและพัฒนาองค์ความรู้ (องค์การมหาชน)
A7: หน่วยงานออกแบบแปลนและรายการ | C7: บริษัท จีโอเดสิค ดีไซน์ จำกัด ,บริษัท เอ็มสเปซ จำกัด และบริษัท จั่นอาร์คิเทค จำกัด
A8: แบบ ปร.4 และ ปร.5 ที่แนบ | C8: 141 แผ่น
A9: คำนวนราคาโดย | C9: บริษัท ฟิวเจอร์เอ็นจิเนียริ่งคอนซัลแตนท์ จำกัด
A10: เมื่อวันที่ | C10: มิถุนายน 2567
A12: ลำดับที่ | B12: รายการ | E12: ค่าก่อสร้าง | F12: หมายเหตุ
E13: (บาท)
B14: กลุ่มงานอาคาร
B15: อาคาร Ratchadamnoen Center 2 | G15: ราคาผู้ออกแบบ | H15: ส่วนต่าง
A16: 1 | B16: =+'RC2_ปร.5 (ก)'!B2 -> ส่วนที่ 1 ค่าวัสดุและแรงงานหมวดงานก่อสร้าง | E16: =+'RC2_ปร.5 (ก)'!I18 -> 1.0769656e+08 | G16: =+'RC2_ปร.5 (ก)'!L18 -> 0 | H16: =+E16-G16 -> 1.0769656e+08
A17: 2 | B17: =+'แบบ ปร.5(ข)'!B14 -> ส่วนที่ 2 ค่าครุภัณฑ์สั่งซื้อหรือจัดซื้อ | E17: =+'แบบ ปร.5(ข)'!E22 -> 33207814 | G17: =+'แบบ ปร.5(ข)'!H22 -> 0 | H17: =+E17-G17 -> 33207814
A19: สรุป | B19: รวมค่าก่อสร้างเป็นเงินทั้งสิ้น | E19: =SUM(E15:E18) -> 1.4090437e+08 | G19: 1.5861999e+08 | H19: =+E19-G19 -> -17715623
B20: ="("&BAHTTEXT(E19)&")" -> (หนึ่งร้อยสี่สิบล้านเก้าแสนสี่พันสามร้อยเจ็ดสิบบาทสามสิบหกสตางค์)
B21: เฉลี่ยราคาประมาณ | D21: บาท/ตารางเมตร

Sheet NKC2
A1: WBS-1 | B1: WBS-2 | C1: WBS-3 | D1: WBS-4 | E1: Description | F1: Unit | G1: Qty | H1: Material | I1: Labor | J1: Amount
A2: Structure | B2: Tiolet-Pantry | E2: =IF(LEN(Str!C26)>0, Str!C26, Str!B26) -> อาคารห้องน้ำและห้องเตรียมอาหาร | F2: =Str!F26 -> 0 | G2: =Str!E26 -> 0 | H2: =Str!I26 -> 0 | I2: =Str!L26 -> 0 | J2: =Str!M26 -> 0
A3: Structure | F3: =Str!F27 -> 0 | G3: =Str!E27 -> 0 | H3: =Str!I27 -> 0 | I3: =Str!L27 -> 0 | J3: =Str!M27 -> 0
A4: Structure | B4: Tiolet-Pantry | E4: =IF(LEN(Str!C28)>0, Str!C28, Str!B28) -> อาคารห้องน้ำและห้องเตรียมอาหาร | F4: =Str!F28 -> 0 | G4: =Str!E28 -> 0 | H4: =Str!I28 -> 0 | I4: =Str!L28 -> 0 | J4: =Str!M28 -> 0
A5: Structure | B5: Tiolet-Pantry | C5: Sub-structure | D5: Pilling | E5: =IF(LEN(Str!C29)>0, Str!C29, Str!B29) -> งานเสาเข็ม | F5: =Str!F29 -> 0 | G5: =Str!E29 -> 0 | H5: =Str!I29 -> 0 | I5: =Str!L29 -> 0 | J5: =Str!M29 -> 0
A6: Structure | B6: Tiolet-Pantry | C6: Sub-structure | D6: Pilling | E6: =IF(LEN(Str!C30)>0, Str!C30, Str!B30) -> เสาเข็มเจาะระบบแห้งขนาด Dia. 0.35 x 21 ม. | F6: =Str!F30 -> ต้น | G6: =Str!E30 -> 34 | H6: =Str!I30 -> 365549.05 | I6: =Str!L30 -> 0 | J6: =Str!M30 -> 365549.05
A7: Structure | B7: Tiolet-Pantry | C7: Sub-structure | D7: Pilling | E7: =IF(LEN(Str!C31)>0, Str!C31, Str!B31) -> งานตัดหัวเข็ม | F7: =Str!F31 -> ต้น | G7: =Str!E31 -> 34 | H7: =Str!I31 -> 0 | I7: =Str!L31 -> 11125.406 | J7: =Str!M31 -> 11125.406
A8: Structure | B8: Tiolet-Pantry | C8: Sub-structure | D8: Foundation | E8: =IF(LEN(Str!C32)>0, Str!C32, Str!B32) -> งานโครงสร้างฐานราก | F8: =Str!F32 -> 0 | G8: =Str!E32 -> 0 | H8: =Str!I32 -> 0 | I8: =Str!L32 -> 0 | J8: =Str!M32 -> 0
A9: Structure | B9: Tiolet-Pantry | C9: Sub-structure | D9: Foundation | E9: =IF(LEN(Str!C33)>0, Str!C33, Str!B33) -> งานปรับระดับขุดดินทำฐานราก/ถมกลับ | F9: =Str!F33 -> ลบ.ม. | G9: =Str!E33 -> 57.2 | H9: =Str!I33 -> 0 | I9: =Str!L33 -> 5989.3949 | J9: =Str!M33 -> 5989.3949
A10: Structure | B10: Tiolet-Pantry | C10: Sub-structure | D10: Foundation | E10: =IF(LEN(Str!C34)>0, Str!C34, Str!B34) -> งานถมทรายบดอัดรองฐานราก | F10: =Str!F34 -> ลบ.ม. | G10: =Str!E34 -> 3.3 | H10: =Str!I34 -> 1568.298 | I10: =Str!L34 -> 320.86044 | J10: =Str!M34 -> 1889.1584
A11: Structure | B11: Tiolet-Pantry | C11: Sub-structure | D11: Foundation | E11: =IF(LEN(Str!C35)>0, Str!C35, Str!B35) -> งานคอนกรีตหยาบรองฐานราก | F11: =Str!F35 -> ลบ.ม. | G11: =Str!E35 -> 3.3 | H11: =Str!I35 -> 7589.5835 | I11: =Str!L35 -> 1314.2937 | J11: =Str!M35 -> 8903.8773
A12: Structure | B12: Tiolet-Pantry | C12: Sub-structure | D12: Foundation | E12: =IF(LEN(Str!C36)>0, Str!C36, Str!B36) -> งานคอนกรีตโครงสร้าง (fc' 240 ksc, Cyl.) ผสมน้ำยากันซึม | F12: =Str!F36 -> ลบ.ม. | G12: =Str!E36 -> 16.8 | H12: =Str!I36 -> 33258.419 | I12: =Str!L36 -> 8151.6502 | J12: =Str!M36 -> 41410.069
A13: Structure | B13: Tiolet-Pantry | C13: Sub-structure | D13: Foundation | E13: =IF(LEN(Str!C37)>0, Str!C37, Str!B37) -> เหล็กเสริม | F13: =Str!F37 -> 0 | G13: =Str!E37 -> 0 | H13: =Str!I37 -> 0 | I13: =Str!L37 -> 0 | J13: =Str!M37 -> 0
A14: Structure | B14: Tiolet-Pantry | C14: Sub-structure | D14: Foundation | E14: =IF(LEN(Str!C38)>0, Str!C38, Str!B38) -> งานเหล็กเสริมคอนกรีต RB 9 (SR-24) | F14: =Str!F38 -> กก. | G14: =Str!E38 -> 36.9 | H14: =Str!I38 -> 676.1629 | I14: =Str!L38 -> 151.79167 | J14: =Str!M38 -> 827.95457
A15: Structure | B15: Tiolet-Pantry | C15: Sub-structure | D15: Foundation | E15: =IF(LEN(Str!C39)>0, Str!C39, Str!B39) -> งานเหล็กเสริมคอนกรีต DB 12 (SD-40) | F15: =Str!F39 -> กก. | G15: =Str!E39 -> 0 | H15: =Str!I39 -> 0 | I15: =Str!L39 -> 0 | J15: =Str!M39 -> 0
A16: Structure | B16: Tiolet-Pantry | C16: Sub-structure | D16: Foundation | E16: =IF(LEN(Str!C40)>0, Str!C40, Str!B40) -> งานเหล็กเสริมคอนกรีต DB 16 (SD-40) | F16: =Str!F40 -> กก. | G16: =Str!E40 -> 1030.1 | H16: =Str!I40 -> 18779.451 | I16: =Str!L40 -> 3466.9756 | J16: =Str!M40 -> 22246.427
... A34: Structure | B34: Tiolet-Pantry | C34: Sub-structure | D34: เสาต่อม่อ | E34: =IF(LEN(Str!C58)>0, Str!C58, Str!B58) -> ตะปู (ใช้ 25% ของไม้แบบ 1 ตร.ม.) | F34: =Str!F58 -> กก. | G34: =Str!E58 -> 1.98 | H34: =Str!I58 -> 43.242115 | I34: =Str!L58 -> 0 | J34: =Str!M58 -> 43.242115
A35: Structure | B35: Tiolet-Pantry | C35: Sub-structure
A36: Structure | B36: Tiolet-Pantry | C36: Ground Floor | E36: =IF(LEN(Str!C60)>0, Str!C60, Str!B60) -> งานโครงสร้าง เสา คาน พื้นชั้น 1 | F36: =Str!F60 -> 0 | G36: =Str!E60 -> 0 | H36: =Str!I60 -> 0 | I36: =Str!L60 -> 0 | J36: =Str!M60 -> 0
A37: Structure | B37: Tiolet-Pantry | C37: Ground Floor | D37: Beam | E37: =IF(LEN(Str!C61)>0, Str!C61, Str!B61) -> คาน | F37: =Str!F61 -> 0 | G37: =Str!E61 -> 0 | H37: =Str!I61 -> 0 | I37: =Str!L61 -> 0 | J37: =Str!M61 -> 0
A38: Structure | B38: Tiolet-Pantry | C38: Ground Floor | D38: Beam | E38: =IF(LEN(Str!C62)>0, Str!C62, Str!B62) -> งานคอนกรีตโครงสร้าง (fc' 240 ksc, Cyl.) ผสมน้ำยากันซึม | F38: =Str!F62 -> ลบ.ม. | G38: =Str!E62 -> 10.8 | H38: =Str!I62 -> 21380.412 | I38: =Str!L62 -> 5240.3466 | J38: =Str!M62 -> 26620.759
A39: Structure | B39: Tiolet-Pantry | C39: Ground Floor | D39: Beam | E39: =IF(LEN(Str!C63)>0, Str!C63, Str!B63) -> งานคอนกรีตหยาบรองท้องคาน (fc' 150 ksc, Cyl.) | F39: =Str!F63 -> ลบ.ม. | G39: =Str!E63 -> 2.2 | H39: =Str!I63 -> 3985.0456 | I39: =Str!L63 -> 1067.478 | J39: =Str!M63 -> 5052.5236
A40: Structure | B40: Tiolet-Pantry | C40: Ground Floor | D40: Beam | E40: =IF(LEN(Str!C64)>0, Str!C64, Str!B64) -> เหล็กเสริม | F40: =Str!F64 -> 0 | G40: =Str!E64 -> 0 | H40: =Str!I64 -> 0 | I40: =Str!L64 -> 0 | J40: =Str!M64 -> 0
A41: Structure | B41: Tiolet-Pantry | C41: Ground Floor | D41: Beam | E41: =IF(LEN(Str!C65)>0, Str!C65, Str!B65) -> งานเหล็กเสริมคอนกรีต RB 9 (SR-24) | F41: =Str!F65 -> กก. | G41: =Str!E65 -> 336.3 | H41: =Str!I65 -> 6162.4277 | I41: =Str!L65 -> 1383.4021 | J41: =Str!M65 -> 7545.8298
A42: Structure | B42: Tiolet-Pantry | C42: Ground Floor | D42: Beam | E42: =IF(LEN(Str!C66)>0, Str!C66, Str!B66) -> งานเหล็กเสริมคอนกรีต DB 12 (SD-40) | F42: =Str!F66 -> กก. | G42: =Str!E66 -> 0 | H42: =Str!I66 -> 0 | I42: =Str!L66 -> 0 | J42: =Str!M66 -> 0
A43: Structure | B43: Tiolet-Pantry | C43: Ground Floor | D43: Beam | E43: =IF(LEN(Str!C67)>0, Str!C67, Str!B67) -> งานเหล็กเสริมคอนกรีต DB 16 (SD-40) | F43: =Str!F67 -> กก. | G43: =Str!E67 -> 805.7 | H43: =Str!I67 -> 14688.481 | I43: =Str!L67 -> 2711.7195 | J43: =Str!M67 -> 17400.2
A44: Structure | B44: Tiolet-Pantry | C44: Ground Floor | D44: Beam | E44: =IF(LEN(Str!C68)>0, Str!C68, Str!B68) -> ลวดผูกเหล็ก | F44: =Str!F68 -> กก. | G44: =Str!E68 -> 20.6 | H44: =Str!I68 -> 521.92177 | I44: =Str!L68 -> 0 | J44: =Str!M68 -> 521.92177
A45: Structure | B45: Tiolet-Pantry | C45: Ground Floor | D45: Beam | E45: =IF(LEN(Str!C69)>0, Str!C69, Str!B69) -> ไม้แบบ ค้ำยัน นั่งร้าน | F45: =Str!F69 -> 0 | G45: =Str!E69 -> 0 | H45: =Str!I69 -> 0 | I45: =Str!L69 -> 0 | J45: =Str!M69 -> 0
A46: Structure | B46: Tiolet-Pantry | C46: Ground Floor | D46: Beam | E46: =IF(LEN(Str!C70)>0, Str!C70, Str!B70) -> ไม้แบบ ค้ำยัน นั่งร้าน (อาคาร 3 ชั้น ใช้ 60%) | F46: =Str!F70 -> ตร.ม. | G46: =Str!E70 -> 59.16 | H46: =Str!I70 -> 13561.806 | I46: =Str!L70 -> 0 | J46: =Str!M70 -> 13561.806
A47: Structure | B47: Tiolet-Pantry | C47: Ground Floor | D47: Beam | E47: =IF(LEN(Str!C71)>0, Str!C71, Str!B71) -> ค่าแรงประกอบและติดตั้งไม้แบบหล่อคอนกรีต (ใช้ 100%) | F47: =Str!F71 -> ตร.ม. | G47: =Str!E71 -> 98.6 | H47: =Str!I71 -> 0 | I47: =Str!L71 -> 11154.014 | J47: =Str!M71 -> 11154.014
A48: Structure | B48: Tiolet-Pantry | C48: Ground Floor | D48: Beam | E48: =IF(LEN(Str!C72)>0, Str!C72, Str!B72) -> ไม้เคร่า (ใช้ 30% ของไม้แบบ 1 ตร.ม.) | F48: =Str!F72 -> ลบ.ฟ. | G48: =Str!E72 -> 17.75 | H48: =Str!I72 -> 5134.7067 | I48: =Str!L72 -> 0 | J48: =Str!M72 -> 5134.7067
... A71: Structure | B71: Tiolet-Pantry | C71: Ground Floor | D71: Column | E71: =IF(LEN(Str!C95)>0, Str!C95, Str!B95) -> งานสีน้ำมัน เหล็ก 1 ตัน ต่อ ทาสี 25 ตร.ม. | F71: =Str!F95 -> ตร.ม. | G71: =Str!E95 -> 58.6 | H71: =Str!I95 -> 1770.671 | I71: =Str!L95 -> 1917.4964 | J71: =Str!M95 -> 3688.1674
A72: Structure | B72: Tiolet-Pantry | C72: Ground Floor | D72: Column | F72: =Str!F96 -> 0 | G72: =Str!E96 -> 0 | H72: =Str!I96 -> 0 | I72: =Str!L96 -> 0 | J72: =Str!M96 -> 0
A73: Structure | B73: Tiolet-Pantry | C73: Mezzanine | E73: =IF(LEN(Str!C97)>0, Str!C97, Str!B97) -> งานโครงสร้าง เสา คาน พื้นชั้นลอย | F73: =Str!F97 -> 0 | G73: =Str!E97 -> 0 | H73: =Str!I97 -> 0 | I73: =Str!L97 -> 0 | J73: =Str!M97 -> 0
A74: Structure | B74: Tiolet-Pantry | C74: Mezzanine | D74: Beam | E74: =IF(LEN(Str!C98)>0, Str!C98, Str!B98) -> คาน | F74: =Str!F98 -> 0 | G74: =Str!E98 -> 0 | H74: =Str!I98 -> 0 | I74: =Str!L98 -> 0 | J74: =Str!M98 -> 0
A75: Structure | B75: Tiolet-Pantry | C75: Mezzanine | D75: Beam | E75: =IF(LEN(Str!C99)>0, Str!C99, Str!B99) -> WF300x200x8x12 mm.-56.8 kg/m | F75: =Str!F99 -> กก. | G75: =Str!E99 -> 6216.8 | H75: =Str!I99 -> 184012.24 | I75: =Str!L99 -> 81369.909 | J75: =Str!M99 -> 265382.15
A76: Structure | B76: Tiolet-Pantry | C76: Mezzanine | D76: Beam | E76: =IF(LEN(Str!C100)>0, Str!C100, Str!B100) -> Steel Plate 12 mm.Thk. | F76: =Str!F100 -> กก. | G76: =Str!E100 -> 131.8 | H76: =Str!I100 -> 3076.8254 | I76: =Str!L100 -> 1725.0923 | J76: =Str!M100 -> 4801.9177
A77: Structure | B77: Tiolet-Pantry | C77: Mezzanine | D77: Slab | E77: =IF(LEN(Str!C101)>0, Str!C101, Str!B101) -> พื้น | F77: =Str!F101 -> 0 | G77: =Str!E101 -> 0 | H77: =Str!I101 -> 0 | I77: =Str!L101 -> 0 | J77: =Str!M101 -> 0
A78: Structure | B78: Tiolet-Pantry | C78: Mezzanine | D78: Slab | E78: =IF(LEN(Str!C102)>0, Str!C102, Str!B102) -> งานคอนกรีตโครงสร้าง (fc' 240 ksc, Cyl.) | F78: =Str!F102 -> ลบ.ม. | G78: =Str!E102 -> 12.4 | H78: =Str!I102 -> 29063.299 | I78: =Str!L102 -> 6016.6942 | J78: =Str!M102 -> 35079.994
A79: Structure | B79: Tiolet-Pantry | C79: Mezzanine | D79: Slab | E79: =IF(LEN(Str!C103)>0, Str!C103, Str!B103) -> เหล็กเสริม | F79: =Str!F103 -> 0 | G79: =Str!E103 -> 0 | H79: =Str!I103 -> 0 | I79: =Str!L103 -> 0 | J79: =Str!M103 -> 0
...

Sheet RC2_ปร.5 (ก)
B1: Description | C1: Unit | D1: Qty | E1: Material | F1: Labor | G1: Amount | H1: Factor | I1: Amount x Factor
B2: ส่วนที่ 1 ค่าวัสดุและแรงงานหมวดงานก่อสร้าง
B3: อาคาร Ratchadamnoen Center 2
A4: 1 | B4: งานสถาปัตยกรรม | G4: =Arch!M13 -> 39847480 | H4: 1.1924 | I4: =SUM(G4*H4) -> 47514136
A5: 2 | B5: งานสถาปัตยกรรมภายใน (BUILT-IN) | G5: =Built!M35 -> 5231343.4 | H5: =+H4 -> 1.1924 | I5: =SUM(G5*H5) -> 6237853.9
A6: 3 | B6: งานวิศวกรรมโครงสร้าง | G6: =Str!M16 -> 9866360.7 | H6: =+H4 -> 1.1924 | I6: =SUM(G6*H6) -> 11764648
A7: 4 | B7: งานระบบไฟฟ้าและสื่อสาร | G7: =+EE!M28 -> 24337107 | H7: =+H4 -> 1.1924 | I7: =SUM(G7*H7) -> 29019566
A8: 5 | B8: งานระบบสุขาภิบาลและดับเพลิง | G8: =SAN_FP!M15 -> 3680529.1 | H8: =+H4 -> 1.1924 | I8: =SUM(G8*H8) -> 4388662.9
A9: 6 | B9: งานระบบปรับอากาศและระบายอากาศ | G9: =AC!M18 -> 6479043.2 | H9: =+H4 -> 1.1924 | I9: =SUM(G9*H9) -> 7725611.1
A10: 7 | B10: งานภูมิสถาปัตยกรรม | G10: =LD!M15 -> 877287.83 | H10: =+H4 -> 1.1924 | I10: =SUM(G10*H10) -> 1046078
G11: =SUM(G4:G10) -> 90319152
B13: เงื่อนไข
B14: เงินล่วงหน้าจ่าย 0%
B15: เงินประกันผลงานหัก 10%
B16: ดอกเบี้ยเงินกู้ 7%
B17: ค่าภาษีมูลค่าเพิ่ม 7%
A18: สรุป | B18: รวมค่าก่อสร้าง ส่วนที่ 1 ค่าวัสดุและแรงงานหมวดงานก่อสร้าง | I18: =SUM(I2:I17) -> 1.0769656e+08 | K18: 1.1618515e+08
B19: ="("&BAHTTEXT(I18)&")" -> (หนึ่งร้อยเจ็ดล้านหกแสนเก้าหมื่นหกพันห้าร้อยห้าสิบหกบาทสามสิบสตางค์)
B20: พื้นที่อาคาร | G20: 5825 | H20: ตารางเมตร
B21: เฉลี่ยราคาประมาณ | G21: =+I18/G20 -> 18488.679 | H21: บาท/ตารางเมตร
G22: =+G21+'แบบ ปร.5(ข)'!C25 -> 24189.591
G25: =G11+'แบบ ปร.5(ข)'!C22+Oth!M21 -> 1.3587946e+08

Sheet Arch
C1: Description | E1: Qty | F1: Unit | G1: ราคา/หน่วย | H1: ราคา/หน่วย | I1: Material | J1: ราคา/หน่วย | K1: ราคา/หน่วย | L1: Labor | M1: Amount
B2: สรุปราคาค่าก่อสร้างงานสถาปัตยกรรม
B3: อาคาร Ratchadamnoen Center 2
A4: 1 | B4: งานผิวพื้น | M4: =M72 -> 4066978.5 | O4: =P4*0.934908047 -> 4066978.5 | P4: 4350137.5
A5: 2 | B5: งานผนัง | M5: =M139 -> 7267154.3 | O5: =P5*0.934908047 -> 7267154.3 | P5: 7773122
A6: 3 | B6: งานฝ้าเพดาน | M6: =M187 -> 3631278.2 | O6: =P6*0.934908047 -> 3631278.2 | P6: 3884102
A7: 4 | B7: งานประตูและอุปกรณ์ | M7: =M351 -> 9393678.4 | O7: =P7*0.934908047 -> 9393678.4 | P7: 10047703
A8: 5 | B8: งานหน้าต่าง | M8: =M438 -> 4972313.1 | O8: =P8*0.934908047 -> 4972313.1 | P8: 5318505
A9: 6 | B9: งานห้องน้ำและสุขภัณฑ์ | M9: =M473 -> 1728663.7 | O9: =P9*0.934908047 -> 1728663.7 | P9: 1849020
A10: 7 | B10: งานบันได ราวบันได ราวกันตก และส่วนประกอบ | M10: =M549 -> 3535107.7 | O10: =P10*0.934908047 -> 3535107.7 | P10: 3781235.7
A11: 8 | B11: งานหลังคา งานฉนวนกันความร้อน งานกันซึมและส่วนประกอบ | M11: =M632 -> 5252306.5 | O11: =P11*0.934908047 -> 5252306.5 | P11: 5617992.6
O12: =P12*0.934899332 -> 0
B13: รวมราคาค่าก่อสร้างงานสถาปัตยกรรม | M13: =SUM(M4:M12) -> 39847480 | O13: =SUM(O4:O12) -> 39847480 | P13: =SUM(P4:P12) -> 42621818
B21: Allow for any items not described above but deemed necessary
B22: to complete the works :-
A26: 1 | B26: งานผิวพื้น
A28: 1.1 | B28: F0 | C28: พื้น ค.ส.ล. เทปูนทรายปรับระดับ ปรับผิวเรียบ ( ดูรายละเอียดงาน ตกแต่งภายใน ) | E28: 0 | F28: ตร.ม. | G28: 0 | I28: 0 | J28: 0 | L28: 0 | M28: 0
A29: 1.2 | B29: F1.1 | C29: พื้น ค.ส.ล. เทปูนทรายปรับระดับ ผิวขัดมัน 30-50 มม. | E29: 0 | F29: ตร.ม. | G29: 0 | I29: 0 | J29: 0 | L29: 0 | M29: 0
A30: 1.3 | B30: F1.2 | C30: พื้น ค.ส.ล. เทปูนทรายปรับระดับ ผิวขัดมัน 30-50 มม. พร้อมงานระบบกันซึม | E30: 1090 | F30: ตร.ม. | G30: 113 | H30: =G30*O30 -> 105.64461 | I30: =H30*E30 -> 115152.62 | J30: 87 | K30: =J30*O30 -> 81.337 | L30: =K30*E30 -> 88657.33 | M30: =SUM(I30,L30) -> 203809.95 | O30: 0.93490805
C31: (งานกันซึมดูรายละเอียดงานระบบกันซึม) | O31: 0.93490805
A32: 1.4 | B32: F1.3 | C32: พื้น ค.ส.ล. ผิวของ Topping หรือผิวโครงสร้าง ทางวิศวกรรม แต่งเรียบ | E32: 897 | F32: ตร.ม. | G32: 0 | H32: =G32*O32 -> 0 | I32: =H32*E32 -> 0 | J32: 64 | K32: =J32*O32 -> 59.834115 | L32: =K32*E32 -> 53671.201 | M32: =SUM(I32,L32) -> 53671.201 | O32: 0.93490805
A33: 1.5 | B33: F2.1 | C33: พื้น ค.ส.ล. เทปูนทรายปรับระดับ ผิวหินขัดเบอร์ 4 1/2 - 5 ชนิดคัดเม็ดหิน | E33: 325 | F33: ตร.ม. | G33: 238 | H33: =G33*O33 -> 222.50812 | I33: =H33*E33 -> 72315.137 | J33: 161 | K33: =J33*O33 -> 150.5202 | L33: =K33*E33 -> 48919.064 | M33: =SUM(I33,L33) -> 121234.2 | O33: 0.93490805
C34: หรือขนาดอื่นๆ ตามแบบระบุภายหลัง | O34: 0.93490805
A35: 1.6 | B35: F2.2 | C35: พื้น ค.ส.ล. เทปูนทรายปรับระดับ ผิวหินล้างเบอร์ 4 1/2 - 5 ชนิดคัดเม็ดหิน | E35: 70 | F35: ตร.ม. | G35: 308 | H35: =G35*O35 -> 287.95168 | I35: =H35*E35 -> 20156.617 | J35: 104 | K35: =J35*O35 -> 97.230437 | L35: =K35*E35 -> 6806.1306 | M35: =SUM(I35,L35) -> 26962.748 | O35: 0.93490805 | Q35: ราคามีแก้ไขตามกระทรวงพาณิชย์ กทม. ธ.ค. 67
C36: หรือขนาดอื่นๆ ตามแบบระบุภายหลัง | O36: 0.93490805
A37: 1.7 | B37: F3.1 | C37: พื้น ค.ส.ล. เทปูนทรายปรับระดับ ผิวปูกระเบื้องเซรามิค ขนาด 400x400 มม. | E37: 11 | F37: ตร.ม. | G37: 299 | H37: =G37*O37 -> 279.53751 | I37: =H37*E37 -> 3074.9126 | J37: 158 | K37: =J37*O37 -> 147.71547 | L37: =K37*E37 -> 1624.8702 | M37: =SUM(I37,L37) -> 4699.7828 | O37: 0.93490805 | Q37: ราคามีแก้ไขตามกระทรวงพาณิชย์ กทม. ธ.ค. 67
A38: 1.8 | B38: F3.2 | C38: พื้น ค.ส.ล. พร้อมปูนทรายปรับระดับ ผิวปูกระเบื้อง Porcelain สีเทา | E38: 4 | F38: ตร.ม. | G38: 575 | H38: =G38*O38 -> 537.57213 | I38: =H38*E38 -> 2150.2885 | J38: 222 | K38: =J38*O38 -> 207.54959 | L38: =K38*E38 -> 830.19835 | M38: =SUM(I38,L38) -> 2980.4869 | O38: 0.93490805 | Q38: ราคามีแก้ไขตามกระทรวงพาณิชย์ กทม. ธ.ค. 67
C39: ขนาด 600x600 มม. | O39: 0.93490805
A40: 1.9 | B40: F3.3 | C40: พื้น ค.ส.ล. พร้อมปูนทรายปรับระดับ ผิวปูกระเบื้องลายหินขัด ขนาด 600x600 มม. | E40: 95 | F40: ตร.ม. | G40: 377 | H40: =G40*O40 -> 352.46033 | I40: =H40*E40 -> 33483.732 | J40: 222 | K40: =J40*O40 -> 207.54959 | L40: =K40*E40 -> 19717.211 | M40: =SUM(I40,L40) -> 53200.942 | O40: 0.93490805 | Q40: ราคามีแก้ไขตามกระทรวงพาณิชย์ กทม. ธ.ค. 67
A41: 1.1 | B41: F3.4 | C41: พื้น ค.ส.ล. พร้อมปูนทรายปรับระดับ ผิวปูหินแกรนิตดำอินเดีย (Indian Black) | E41: 270 | F41: ตร.ม. | G41: 1630 | H41: =G41*O41 -> 1523.9001 | I41: =H41*E41 -> 411453.03 | J41: 207 | K41: =J41*O41 -> 193.52597 | L41: =K41*E41 -> 52252.011 | M41: =SUM(I41,L41) -> 463705.04 | O41: 0.93490805 | Q41: ราคามีแก้ไขตามกระทรวงพาณิชย์ กทม. ธ.ค. 67
C42: ขนาด 300 x ( ตามแบบระบุ ) x 20 มม. | O42: 0.93490805
A43: 1.11 | B43: F3.5 | C43: พื้น ค.ส.ล. พร้อมปูนทรายปรับระดับ ผิวกรุหินอ่อน สีตามระบุในแบบ | O43: 0.93490805
C44: ขนาด 300 x ( ตามแบบระบุ ) x 20 มม. ผิวกึ่งมัน | O44: 0.93490805
B45: - | C45: ผิวกรุหินอ่อนสลับลายตามแบบขยายบันได | E45: 80 | F45: ตร.ม. | G45: 2110 | H45: =G45*O45 -> 1972.656 | I45: =H45*E45 -> 157812.48 | J45: 231 | K45: =J45*O45 -> 215.96376 | L45: =K45*E45 -> 17277.101 | M45: =SUM(I45,L45) -> 175089.58 | O45: 0.93490805 | Q45: ราคามีแก้ไขตามกระทรวงพาณิชย์ กทม. ธ.ค. 67
B46: - | C46: ผิวกรุหินอ่อน สีขาว | E46: 20 | F46: ตร.ม. | G46: 1780 | H46: =G46*O46 -> 1664.1363 | I46: =H46*E46 -> 33282.726 | J46: 207 | K46: =J46*O46 -> 193.52597 | L46: =K46*E46 -> 3870.5193 | M46: =SUM(I46,L46) -> 37153.246 | O46: 0.93490805 | Q46: ราคามีแก้ไขตามกระทรวงพาณิชย์ กทม. ธ.ค. 67
A47: 1.12 | B47: F3.6 | C47: พื้น ค.ส.ล. ผิวคอนกรีตขัดเงา ( Polished Cement ) หนา 50 มม. | E47: 42.94 | F47: ตร.ม. | G47: 250 | H47: =G47*O47 -> 233.72701 | I47: =H47*E47 -> 10036.238 | J47: 0 | K47: =J47*O47 -> 0 | L47: =K47*E47 -> 0 | M47: =SUM(I47,L47) -> 10036.238 | O47: 0.93490805
A48: 1.13 | B48: F4.1 | C48: พื้น ค.ส.ล. พร้อมปูนทรายปรับระดับ ผิวขัดมันหนา 30-50 มม. | E48: 956.78 | F48: ตร.ม. | G48: 650 | H48: =G48*O48 -> 607.69023 | I48: =H48*E48 -> 581425.86 | J48: 140 | K48: =J48*O48 -> 130.88713 | L48: =K48*E48 -> 125230.18 | M48: =SUM(I48,L48) -> 706656.04 | O48: 0.93490805
C49: ทำผิว Epoxy Self Leveling Flake หนา 2 มม. ( ผิวมันระบุสีภายหลัง ) | O49: 0.93490805
A50: 1.14 | B50: F4.2 | C50: พื้น ค.ส.ล. พร้อมปูนทรายปรับระดับ ผิวขัดมันหนา 30-50 มม. | E50: 45.9 | F50: ตร.ม. | G50: 350 | H50: =G50*O50 -> 327.21782 | I50: =H50*E50 -> 15019.298 | J50: 150 | K50: =J50*O50 -> 140.23621 | L50: =K50*E50 -> 6436.8419 | M50: =SUM(I50,L50) -> 21456.14 | O50: 0.93490805
C51: ทาสี Epoxy Coating หนา 500 ไมครอน | O51: 0.93490805
...

Sheet Built
C1: Description | E1: Qty | F1: Unit | I1: Material | L1: Labor | M1: Amount
B2: สรุปราคาค่าก่อสร้างงานสถาปัตยกรรมภายใน
B3: อาคาร Ratchadamnoen Center 2
A4: 1 | B4: งาน LOBBY (ชั้นล่าง) | M4: =M70 -> 250027.13 | O4: =P4*0.934908047 -> 250027.13 | P4: 267435 | Q4: =M4-O4 -> 0
A5: 2 | B5: งานห้อง Workshop (ชั้นล่าง) | M5: =M91 -> 519799.53 | O5: =P5*0.934908047 -> 519799.53 | P5: 555990 | Q5: =M5-O5 -> 0
A6: 3 | B6: งานสำนักงาน 1 (ชั้นล่าง) | M6: =M96 -> 117728.3 | O6: =P6*0.934908047 -> 117728.3 | P6: 125925 | Q6: =M6-O6 -> 0
A7: 4 | B7: งาน Print & Copy 1 (ชั้นล่าง) | M7: =M102 -> 63872.918 | O7: =P7*0.934908047 -> 63872.918 | P7: 68320 | Q7: =M7-O7 -> 0
A8: 5 | B8: งานห้องเตรียมอาหาร 1 (ชั้นล่าง) | M8: =M110 -> 66004.508 | O8: =P8*0.934908047 -> 66004.508 | P8: 70600 | Q8: =M8-O8 -> 0
A9: 6 | B9: งานห้องประชุม 1 (ชั้นลอย) | M9: =M122 -> 168732.2 | O9: =P9*0.934908047 -> 168732.2 | P9: 180480 | Q9: =M9-O9 -> 0
A10: 7 | B10: งาน Print & Copy 2 (ชั้นลอย) | M10: =M128 -> 56398.328 | O10: =P10*0.934908047 -> 56398.328 | P10: 60325 | Q10: =M10-O10 -> 0
A11: 8 | B11: งานสำนักงาน 3 (ชั้น 2) | M11: =M134 -> 87939.788 | O11: =P11*0.934908047 -> 87939.788 | P11: 94062.5 | Q11: =M11-O11 -> 0
A12: 9 | B12: งานห้องเก็บเอกสาร 1 (ชั้น 2) | M12: =M139 -> 112188.97 | O12: =P12*0.934908047 -> 112188.97 | P12: 120000 | Q12: =M12-O12 -> 0
A13: 10 | B13: งาน Print & Copy 3 (ชั้น 2) | M13: =M146 -> 98913.271 | O13: =P13*0.934908047 -> 98913.271 | P13: 105800 | Q13: =M13-O13 -> 0
A14: 11 | B14: งานห้องประชุม 2 (ชั้น 2) | M14: =M158 -> 341045.11 | O14: =P14*0.934908047 -> 341045.11 | P14: 364790 | Q14: =M14-O14 -> 0
A15: 12 | B15: งานห้องประชุม 3 (ชั้น 2) | M15: =M163 -> 50134.444 | O15: =P15*0.934908047 -> 50134.444 | P15: 53625 | Q15: =M15-O15 -> 0
A16: 13 | B16: งานห้องประชุม 4 (ชั้น 2) | M16: =M173 -> 93598.319 | O16: =P16*0.934908047 -> 93598.319 | P16: 100115 | Q16: =M16-O16 -> 0
A17: 14 | B17: งานห้องประชุม 5 (ชั้น 2) | M17: =M183 -> 53490.764 | O17: =P17*0.934908047 -> 53490.764 | P17: 57215 | Q17: =M17-O17 -> 0
A18: 15 | B18: งานสำนักงาน 4 (ชั้น 2) | M18: =M189 -> 87939.788 | O18: =P18*0.934908047 -> 87939.788 | P18: 94062.5 | Q18: =M18-O18 -> 0
A19: 16 | B19: งานห้องเก็บเอกสาร 2 (ชั้น 2) | M19: =M194 -> 153324.92 | O19: =P19*0.934908047 -> 153324.92 | P19: 164000 | Q19: =M19-O19 -> 0
A20: 17 | B20: งาน Print & Copy 4 (ชั้น 2) | M20: =M200 -> 93023.351 | O20: =P20*0.934908047 -> 93023.351 | P20: 99500 | Q20: =M20-O20 -> 0
A21: 18 | B21: งานห้องดิจิตอลแลป (ชั้น 2) | M21: =M204 -> 7946.7184 | O21: =P21*0.934908047 -> 7946.7184 | P21: 8500 | Q21: =M21-O21 -> 0
A22: 19 | B22: งานห้องเตรียมอาหาร 3 (ชั้น 2) | M22: =M213 -> 182236.95 | O22: =P22*0.934908047 -> 182236.95 | P22: 194925 | Q22: =M22-O22 -> 0
A23: 20 | B23: งานสำนักงาน 5 (ชั้น 3) | M23: =M219 -> 109384.24 | O23: =P23*0.934908047 -> 109384.24 | P23: 117000 | Q23: =M23-O23 -> 0
A24: 21 | B24: งานห้องเก็บเอกสาร 3 (ชั้น 3) | M24: =M226 -> 162253.29 | O24: =P24*0.934908047 -> 162253.29 | P24: 173550 | Q24: =M24-O24 -> 0
O25: =P25*0.934908047 -> 0 | Q25: =M25-O25 -> 0
O26: =P26*0.934908047 -> 0 | Q26: =M26-O26 -> 0
A27: 22 | B27: งาน Print & Copy 5 (ชั้น 3) | M27: =M232 -> 55393.302 | O27: =P27*0.934908047 -> 55393.302 | P27: 59250 | Q27: =M27-O27 -> 0
A28: 23 | B28: งานห้องประชุม 6 (ชั้น 3) | M28: =M241 -> 691084.03 | O28: =P28*0.934908047 -> 691084.03 | P28: 739200 | Q28: =M28-O28 -> 0
A29: 24 | B29: งานสำนักงาน 6 (ชั้น 3) | M29: =M248 -> 414094.15 | O29: =P29*0.934908047 -> 414094.15 | P29: 442925 | Q29: =M29-O29 -> 0
A30: 25 | B30: งาน Print & Copy 6 (ชั้น 3) | M30: =M254 -> 39125.902 | O30: =P30*0.934908047 -> 39125.902 | P30: 41850 | Q30: =M30-O30 -> 0
A31: 26 | B31: งานห้องเตรียมอาหาร 3 (ชั้น 3) | M31: =M263 -> 185906.47 | O31: =P31*0.934908047 -> 185906.47 | P31: 198850 | Q31: =M31-O31 -> 0
A32: 27 | B32: งานห้องเตรียมอาหาร 4 (ชั้น 3) | M32: =M270 -> 85637.577 | O32: =P32*0.934908047 -> 85637.577 | P32: 91600 | Q32: =M32-O32 -> 0
A33: 28 | B33: งานห้องสมุดและพักผ่อน (ชั้นดาดฟ้า) | M33: =M284 -> 884119.17 | O33: =P33*0.934908047 -> 884119.17 | P33: 945675 | Q33: =M33-O33 -> 0
O34: =P34*0.934899332 -> 0 | Q34: =M34-O34 -> 0
B35: รวมราคางานสถาปัตยกรรมภายใน อาคาร Ratchadamnoen Center 2 | M35: =SUM(M4:M34) -> 5231343.4 | O35: =SUM(O4:O34) -> 5231343.4 | P35: =SUM(P4:P34) -> 5595570 | Q35: =M35-O35 -> 0
A54: 1 | B54: งาน LOBBY (ชั้นล่าง)
A56: 1.1 | B56: งานผนัง
B57: P3.1 | C57: ผนังกระจก U GLASS ขนาด 262 x 60 x 7 มม. รุ่น Clarissimo + รุ่น Clarissimo | E57: * ดูรายละเอียดงานผนังและผิวผนัง
B58: - | C58: งานกระจก | E58: * ดูรายละเอียดงานผนังและผิวผนัง
B59: - | C59: งานโครงเคร่าเหล็กประกอบงานผนัง พร้อมงานทาสี | E59: * ดูรายละเอียดวิศวกรรมโครงสร้าง
...

Sheet Str
A1: ลำดับ | C1: Description | E1: Qty | F1: Unit | G1: ราคาวัสดุสิ่งของ | H1: Rate | I1: Material | J1: ค่าแรงงาน | K1: RAte | L1: Labor | M1: Amount | N1: หมายเหตุ
C2: สรุปราคาค่าก่อสร้างงานโครงสร้าง
C3: อาคาร Ratchadamnoen Center 2
A4: 1 | D4: อาคารห้องน้ำและห้องเตรียมอาหาร | M4: =M181 -> 2841633.4 | O4: =P4*0.934908047 -> 2841633.4 | P4: 3039479
A5: 2 | D5: อาคารโถงลิฟท์ | M5: =M308 -> 725488.87 | O5: =P5*0.934908047 -> 725488.87 | P5: 776000.24
A6: 3 | D6: บันได ST6 | M6: =M322 -> 43085.168 | O6: =P6*0.934908047 -> 43085.172 | P6: 46084.93
A7: 4 | D7: โครงสร้างทางเข้าอาคาร | M7: =M446 -> 132959.02 | O7: =P7*0.934908047 -> 132959.01 | P7: 142216.14
A8: 5 | D8: โครงสร้างชั้นลอย | M8: =M475 -> 3168993.6 | O8: =P8*0.934908047 -> 3168993.6 | P8: 3389631.4
A9: 6 | D9: โครงสร้างเพดานห้อง WORKSHOP | M9: =M494 -> 145432.5 | O9: =P9*0.934908047 -> 145432.5 | P9: 155558.08
A10: 7 | D10: โครงสร้างพื้นชั้น 2 | M10: =M534 -> 376822.58 | O10: =P10*0.934908047 -> 376822.58 | P10: 403058.44
A11: 8 | D11: โครงสร้างโครงหลังคาดาดฟ้า ห้องสนามหลวง/ห้องศาสนา | M11: =M569 -> 406080.11 | O11: =P11*0.934908047 -> 406080.11 | P11: 434353
A12: 9 | D12: โครงสร้างหลังคาอาคารหลัก | M12: =M605 -> 874869.25 | O12: =P12*0.934908047 -> 874869.25 | P12: 935781.07
A13: 10 | D13: โครงสร้างบ่อและแท่นคสล.สำหรับงานระบบ | M13: =M678 -> 411813.34 | O13: =P13*0.934908047 -> 411813.34 | P13: 440485.39
A14: 11 | D14: งานซ่อมแซมโครงสร้างอาคารเดิม | M14: =M686 -> 739182.81 | O14: =P14*0.934908047 -> 739182.81 | P14: 790647.61
O15: =P15*0.934899332 -> 0
D16: รวมราคาค่าก่อสร้างงานวิศวกรรมโครงสร้าง | M16: =SUM(M4:M15) -> 9866360.7 | O16: =SUM(O4:O15) -> 9866360.7 | P16: =SUM(P4:P15) -> 10553295
C26: อาคารห้องน้ำและห้องเตรียมอาหาร
A28: 1 | C28: อาคารห้องน้ำและห้องเตรียมอาหาร
C29: งานเสาเข็ม
A30: 1.1 | C30: เสาเข็มเจาะระบบแห้งขนาด Dia. 0.35 x 21 ม. | E30: 34 | F30: ต้น | G30: 11500 | H30: =G30*O30 -> 10751.443 | I30: =E30*H30 -> 365549.05 | J30: 0 | K30: =J30*O30 -> 0 | L30: =E30*K30 -> 0 | M30: =I30+L30 -> 365549.05 | O30: 0.93490805
A31: 1.2 | C31: งานตัดหัวเข็ม | E31: 34 | F31: ต้น | G31: 0 | H31: =G31*O31 -> 0 | I31: =E31*H31 -> 0 | J31: 350 | K31: =J31*O31 -> 327.21782 | L31: =E31*K31 -> 11125.406 | M31: =I31+L31 -> 11125.406 | O31: 0.93490805
C32: งานโครงสร้างฐานราก | O32: 0.93490805
A33: 1.3 | C33: งานปรับระดับขุดดินทำฐานราก/ถมกลับ | E33: 57.2 | F33: ลบ.ม. | G33: 0 | H33: =G33*O33 -> 0 | I33: =E33*H33 -> 0 | J33: 112 | K33: =J33*O33 -> 104.7097 | L33: =E33*K33 -> 5989.3949 | M33: =I33+L33 -> 5989.3949 | O33: 0.93490805
A34: 1.4 | C34: งานถมทรายบดอัดรองฐานราก | E34: 3.3 | F34: ลบ.ม. | G34: 508.33 | H34: =G34*O34 -> 475.24181 | I34: =E34*H34 -> 1568.298 | J34: 104 | K34: =J34*O34 -> 97.230437 | L34: =E34*K34 -> 320.86044 | M34: =I34+L34 -> 1889.1584 | O34: 0.93490805
A35: 1.5 | C35: งานคอนกรีตหยาบรองฐานราก | E35: 3.3 | F35: ลบ.ม. | G35: 2460 | H35: =G35*O35 -> 2299.8738 | I35: =E35*H35 -> 7589.5835 | J35: 426 | K35: =J35*O35 -> 398.27083 | L35: =E35*K35 -> 1314.2937 | M35: =I35+L35 -> 8903.8773 | O35: 0.93490805
A36: 1.6 | C36: งานคอนกรีตโครงสร้าง (fc' 240 ksc, Cyl.) ผสมน้ำยากันซึม | E36: 16.8 | F36: ลบ.ม. | G36: 2117.5 | H36: =G36*O36 -> 1979.6678 | I36: =E36*H36 -> 33258.419 | J36: 519 | K36: =J36*O36 -> 485.21728 | L36: =E36*K36 -> 8151.6502 | M36: =I36+L36 -> 41410.069 | O36: 0.93490805
C37: เหล็กเสริม | O37: 0.93490805
A38: 1.7 | C38: งานเหล็กเสริมคอนกรีต RB 9 (SR-24) | E38: 36.9 | F38: กก. | G38: 19.6 | H38: =G38*O38 -> 18.324198 | I38: =E38*H38 -> 676.1629 | J38: 4.4 | K38: =J38*O38 -> 4.1135954 | L38: =E38*K38 -> 151.79167 | M38: =I38+L38 -> 827.95457 | O38: 0.93490805 | Q38: ราคามีแก้ไขตามกระทรวงพาณิชย์ กทม. ธ.ค.67
A39: 1.8 | C39: งานเหล็กเสริมคอนกรีต DB 12 (SD-40) | F39: กก. | G39: 19.7 | H39: =G39*O39 -> 18.417689 | I39: =E39*H39 -> 0 | J39: 3.6 | K39: =J39*O39 -> 3.365669 | L39: =E39*K39 -> 0 | M39: =I39+L39 -> 0 | O39: 0.93490805 | Q39: ราคามีแก้ไขตามกระทรวงพาณิชย์ กทม. ธ.ค.67
A40: 1.9 | C40: งานเหล็กเสริมคอนกรีต DB 16 (SD-40) | E40: 1030.1 | F40: กก. | G40: 19.5 | H40: =G40*O40 -> 18.230707 | I40: =E40*H40 -> 18779.451 | J40: 3.6 | K40: =J40*O40 -> 3.365669 | L40: =E40*K40 -> 3466.9756 | M40: =I40+L40 -> 22246.427 | O40: 0.93490805 | Q40: ราคามีแก้ไขตามกระทรวงพาณิชย์ กทม. ธ.ค.67
A41: 1.1 | C41: ลวดผูกเหล็ก | E41: 19.1 | F41: กก. | G41: 27.1 | H41: =G41*O41 -> 25.336008 | I41: =E41*H41 -> 483.91775 | J41: 0 | K41: =J41*O41 -> 0 | L41: =E41*K41 -> 0 | M41: =I41+L41 -> 483.91775 | O41: 0.93490805 | Q41: ราคามีแก้ไขตามกระทรวงพาณิชย์ กทม. ธ.ค.67 | R41: =+E41+E53+E68+E80+E107+E129+E150+E171+E196+E210+E236+E267+E289+E334+E351+E369+E387+E404+E421+E438+E471+E510+E529+E593+E617+E636+E653+E670 -> 495.85 | S41: ปริมาณลวด
A42: 1.11 | C42: ไม้แบบ ค้ำยัน นั่งร้าน | O42: 0.93490805
C43: ไม้แบบ ค้ำยัน นั่งร้าน (อาคาร 3 ชั้น ใช้ 60%) | E43: 29.46 | F43: ตร.ม. | G43: 245.2 | H43: =G43*O43 -> 229.23945 | I43: =E43*H43 -> 6753.3943 | J43: 0 | K43: =J43*O43 -> 0 | L43: =E43*K43 -> 0 | M43: =I43+L43 -> 6753.3943 | O43: 0.93490805
C44: ค่าแรงประกอบและติดตั้งไม้แบบหล่อคอนกรีต (ใช้ 100%) | E44: 49.1 | F44: ตร.ม. | G44: 0 | H44: =G44*O44 -> 0 | I44: =E44*H44 -> 0 | J44: 121 | K44: =J44*O44 -> 113.12387 | L44: =E44*K44 -> 5554.3822 | M44: =I44+L44 -> 5554.3822 | O44: 0.93490805
C45: ไม้เคร่า (ใช้ 30% ของไม้แบบ 1 ตร.ม.) | E45: 8.84 | F45: ลบ.ฟ. | G45: 309.42 | H45: =G45*O45 -> 289.27925 | I45: =E45*H45 -> 2557.2286 | J45: 0 | K45: =J45*O45 -> 0 | L45: =E45*K45 -> 0 | M45: =I45+L45 -> 2557.2286 | O45: 0.93490805
C46: ตะปู (ใช้ 25% ของไม้แบบ 1 ตร.ม.) | E46: 7.37 | F46: กก. | G46: 23.36 | H46: =G46*O46 -> 21.839452 | I46: =E46*H46 -> 160.95676 | J46: 0 | K46: =J46*O46 -> 0 | L46: =E46*K46 -> 0 | M46: =I46+L46 -> 160.95676 | O46: 0.93490805 | Q46: ราคามีแก้ไขตามกระทรวงพาณิชย์ กทม. ธ.ค.67
C47: งานเสาชั้นตอม่อ | O47: 0.93490805
A48: 1.12 | C48: งานคอนกรีตโครงสร้าง (fc' 240 ksc, Cyl.) ผสมน้ำยากันซึม | E48: 0.4 | F48: ลบ.ม. | G48: 2117.5 | H48: =G48*O48 -> 1979.6678 | I48: =E48*H48 -> 791.86712 | J48: 519 | K48: =J48*O48 -> 485.21728 | L48: =E48*K48 -> 194.08691 | M48: =I48+L48 -> 985.95403 | O48: 0.93490805
C49: เหล็กเสริม | O49: 0.93490805
A50: 1.13 | C50: งานเหล็กเสริมคอนกรีต RB 9 (SR-24) | E50: 64.2 | F50: กก. | G50: 19.6 | H50: =G50*O50 -> 18.324198 | I50: =E50*H50 -> 1176.4135 | J50: 4.4 | K50: =J50*O50 -> 4.1135954 | L50: =E50*K50 -> 264.09283 | M50: =I50+L50 -> 1440.5063 | O50: 0.93490805 | Q50: ราคามีแก้ไขตามกระทรวงพาณิชย์ กทม. ธ.ค.67
...

Sheet EE
A1: ชื่อโครงการ | D1: =+'RC2_ปร.5 (ก)'!#REF! -> #REF! | J1: หมวดงาน | K1: หมวดงาน | L1: งานระบบไฟฟ้าและสื่อสาร (RKCA 2)
A2: สถานที่ก่อสร้าง | D2: =+'RC2_ปร.5 (ก)'!#REF! -> #REF! | J2: เมื่อวันที่ | K2: เมื่อวันที่ | L2: =+'RC2_ปร.5 (ก)'!#REF! -> #REF!
A3: คำนวณราคากลางโดย | D3: =+'RC2_ปร.5 (ก)'!#REF! -> #REF!
A5: ลำดับ | B5: รายการ | E5: จำนวน | F5: หน่วย | G5: ราคาวัสดุสิ่งของ | J5: ค่าแรงงาน | M5: รวมค่าวัสดุ | N5: หมายเหตุ
G6: ราคา/หน่วย | H6: ราคา/หน่วย | I6: จำนวนเงิน | J6: ราคา/หน่วย | L6: จำนวนเงิน | M6: และแรงงาน
B7: สรุปราคาค่าก่อสร้างงานระบบไฟฟ้าและสื่อสาร
B8: อาคาร Ratchadamnoen Center 2
A9: 1 | B9: ระบบไฟฟ้าแรงสูง | E9: 1 | F9: งาน | I9: =I39 -> 739053.23 | L9: =L39 -> 75554.594 | M9: =I9+L9 -> 814607.82 | O9: =P9*0.934908047 -> 814607.82 | P9: 871324 | Q9: =M9-O9 -> 0
A10: 2 | B10: Unit Substation | E10: 1 | F10: งาน | I10: =I46 -> 1719108.9 | L10: =L46 -> 28047.241 | M10: =I10+L10 -> 1747156.2 | O10: =P10*0.934908047 -> 1747156.2 | P10: 1868800 | Q10: =M10-O10 -> 0
A11: 3 | B11: งานอุปกรณ์ติดตั้งเครื่องกำเนิดไฟฟ้าสำรอง | E11: 1 | F11: งาน | I11: =I54 -> 75461.103 | L11: =L54 -> 9349.0805 | M11: =I11+L11 -> 84810.183 | O11: =P11*0.934908047 -> 84810.183 | P11: 90715 | Q11: =M11-O11 -> 0
A12: 4 | B12: งานอุปกรณ์ติดตั้งเครื่องจ่ายไฟแบบต่อเนื่อง UPS | E12: 1 | F12: งาน | I12: =I61 -> 1041721.3 | L12: =L61 -> 11218.897 | M12: =I12+L12 -> 1052940.2 | O12: =P12*0.934908047 -> 1052940.2 | P12: 1126250 | Q12: =M12-O12 -> 0
A13: 5 | B13: ตู้ไฟฟ้า | E13: 1 | F13: งาน | I13: =I160 -> 1760545 | L13: =L160 -> 48147.764 | M13: =I13+L13 -> 1808692.7 | O13: =P13*0.934908047 -> 1808692.7 | P13: 1934621 | Q13: =M13-O13 -> 0
A14: 6 | B14: สายไฟฟ้า | E14: 1 | F14: งาน | I14: =I185 -> 1590806.2 | L14: =L185 -> 714927.92 | M14: =I14+L14 -> 2305734.2 | O14: =P14*0.934908047 -> 2305734.2 | P14: 2466268.4 | Q14: =M14-O14 -> 0
A15: 7 | B15: ท่อและรางเดินสายไฟฟ้า | E15: 1 | F15: งาน | I15: =I206 -> 1279605.7 | L15: =L206 -> 623665 | M15: =I15+L15 -> 1903270.8 | O15: =P15*0.934908047 -> 1903270.8 | P15: 2035783.9 | Q15: =M15-O15 -> 0
A16: 8 | B16: ดวงโคมไฟฟ้า | E16: 1 | F16: งาน | I16: =I343 -> 5873749.8 | L16: =L343 -> 302472.67 | M16: =I16+L16 -> 6176222.4 | O16: =P16*0.934908047 -> 6176222.4 | P16: 6606235.2 | Q16: =M16-O16 -> 0
A17: 9 | B17: แสงสว่างฉุกเฉิน และป้ายทางออกฉุกเฉิน | E17: 1 | F17: งาน | I17: =I349 -> 120535.82 | L17: =L349 -> 9524.8432 | M17: =I17+L17 -> 130060.67 | O17: =P17*0.934908047 -> 130060.67 | P17: 139116 | Q17: =M17-O17 -> 0
A18: 10 | B18: สวิตช์ เต้ารับไฟฟ้า | E18: 1 | F18: งาน | I18: =I371 -> 142430.44 | L18: =L371 -> 59479.785 | M18: =I18+L18 -> 201910.22 | O18: =P18*0.934908047 -> 201910.22 | P18: 215968 | Q18: =M18-O18 -> 0
A19: 11 | B19: ระบบการต่อลงดิน และการป้องกันฟ้าผ่า | E19: 1 | F19: งาน | I19: =I390 -> 485432.12 | L19: =L390 -> 72829.337 | M19: =I19+L19 -> 558261.46 | O19: =P19*0.934908047 -> 558261.46 | P19: 597129.8 | Q19: =M19-O19 -> 0
A20: 12 | B20: ระบบป้องกันไฟลาม | E20: 1 | F20: งาน | I20: =I394 -> 70118.104 | L20: =L394 -> 9349.0805 | M20: =I20+L20 -> 79467.184 | O20: =P20*0.934908047 -> 79467.184 | P20: 85000 | Q20: =M20-O20 -> 0
A21: 13 | B21: ระบบควบคุมไฟฟ้าแสงสว่าง | E21: 1 | F21: งาน | I21: =I456 -> 772805.46 | L21: =L456 -> 77560.42 | M21: =I21+L21 -> 850365.88 | O21: =P21*0.934908047 -> 850365.88 | P21: 909571.68 | Q21: =M21-O21 -> 0
A22: 14 | B22: ระบบแจ้งเหตุเพลิงไหม้ | E22: 1 | F22: งาน | I22: =I485 -> 1326623.5 | L22: =L485 -> 264908.06 | M22: =I22+L22 -> 1591531.6 | O22: =P22*0.934908047 -> 1591531.6 | P22: 1702340.2 | Q22: =M22-O22 -> 0
A23: 15 | B23: ระบบควบคุมการเข้า-ออก | E23: 1 | F23: งาน | I23: =I515 -> 733997.71 | L23: =L515 -> 50391.544 | M23: =I23+L23 -> 784389.25 | O23: =P23*0.934908047 -> 784389.25 | P23: 839001.5 | Q23: =M23-O23 -> 0
A24: 16 | B24: ระบบกล้องวงจรปิด | E24: 1 | F24: งาน | I24: =I540 -> 1153340 | L24: =L540 -> 80980.8 | M24: =I24+L24 -> 1234320.8 | O24: =P24*0.934908047 -> 1234320.8 | P24: 1320259 | Q24: =M24-O24 -> 0
A25: 17 | B25: ระบบคอมพิวเตอร์ | E25: 1 | F25: งาน | I25: =I583 -> 2083470.8 | L25: =L583 -> 680274.21 | M25: =I25+L25 -> 2763745 | O25: =P25*0.934908047 -> 2763745 | P25: 2956167.8 | Q25: =M25-O25 -> 0
A26: 18 | B26: ค่าขยายเขตการไฟฟ้า | E26: 1 | F26: งาน | I26: =I591 -> 0 | J26: 0 | L26: =L591 -> 249620.45 | M26: =I26+L26 -> 249620.45 | O26: =P26*0.934908047 -> 249620.45 | P26: 267000 | Q26: =M26-O26 -> 0
O27: =P27*0.934899332 -> 0 | Q27: =M27-O27 -> 0
B28: รวมราคาค่าก่อสร้างงานระบบไฟฟ้าและสื่อสาร | I28: =SUM(I9:I26) -> 20968805 | L28: =SUM(L9:L26) -> 3368301.7 | M28: =SUM(M9:M26) -> 24337107 | O28: =SUM(O9:O27) -> 24337107 | P28: =SUM(P9:P27) -> 26031551 | Q28: =M28-O28 -> 0
A30: 1 | B30: ระบบไฟฟ้าแรงสูง
B31: 1.1 | C31: สายไฟฟ้าแรงสูง (HV Cable)
C32: สายไฟแรงสูงชนิด CU XLPE Cable 1C 12/20kV (24kV)
C33: - 70 มม2 | E33: 9 | F33: ม. | G33: 597 | H33: =G33*O33 -> 558.1401 | I33: =E33*H33 -> 5023.2609 | J33: 70 | K33: =J33*O33 -> 65.443563 | L33: =E33*K33 -> 588.99207 | M33: =I33+L33 -> 5612.253 | O33: 0.93490805
C34: - 240 มม2 | E34: 48 | F34: ม. | G34: 1212 | H34: =G34*O34 -> 1133.1086 | I34: =E34*H34 -> 54389.211 | J34: 155 | K34: =J34*O34 -> 144.91075 | L34: =E34*K34 -> 6955.7159 | M34: =I34+L34 -> 61344.926 | O34: 0.93490805
B35: 1.3 | C35: 2x2 DUCT BANK ∅127mm.(ID)RTRC. EMBERDED | E35: 13 | F35: ม. | G35: 4500 | H35: =G35*O35 -> 4207.0862 | I35: =E35*H35 -> 54692.121 | J35: 1350 | K35: =J35*O35 -> 1262.1259 | L35: =E35*K35 -> 16407.636 | M35: =I35+L35 -> 71099.757 | O35: 0.93490805
B36: 1.4 | C36: MANHOLE HV. TYPE A-1/2M | E36: 1 | F36: ชุด | G36: 158460 | H36: =G36*O36 -> 148145.53 | I36: =E36*H36 -> 148145.53 | J36: 35195 | K36: =J36*O36 -> 32904.089 | L36: =E36*K36 -> 32904.089 | M36: =I36+L36 -> 181049.62 | O36: 0.93490805
B37: 1.7 | C37: Outdoor Enclosure for Ring Main Unit With Meetering MEA. 24 kV | E37: 1 | F37: ชุด | G37: 500000 | H37: =G37*O37 -> 467454.02 | I37: =E37*H37 -> 467454.02 | J37: 20000 | K37: =J37*O37 -> 18698.161 | L37: =E37*K37 -> 18698.161 | M37: =I37+L37 -> 486152.18 | O37: 0.93490805
B38: 1.8 | C38: Concrete Foundation | E38: 1 | F38: ชุด | G38: 10000 | H38: =G38*O38 -> 9349.0805 | I38: =E38*H38 -> 9349.0805 | K38: =J38*O38 -> 0 | L38: =E38*K38 -> 0 | M38: =I38+L38 -> 9349.0805 | O38: 0.93490805
B39: รวมรายการที่ 1 | I39: =SUM(I30:I38) -> 739053.23 | L39: =SUM(L30:L38) -> 75554.594 | M39: =SUM(M30:M38) -> 814607.82 | O39: 0.93490805
O40: 0.93490805
A41: 2 | B41: Unit Substation | O41: 0.93490805
B42: 2.1 | C42: Outdoor Enclosure for Unit Substation | E42: 1 | F42: ชุด | G42: 1788800 | H42: =G42*O42 -> 1672363.5 | I42: =E42*H42 -> 1672363.5 | J42: 30000 | K42: =J42*O42 -> 28047.241 | L42: =E42*K42 -> 28047.241 | M42: =I42+L42 -> 1700410.8 | O42: 0.93490805
...

Sheet SAN_FP
A1: ชื่อโครงการ | D1: =+'RC2_ปร.5 (ก)'!#REF! -> #REF! | J1: หมวดงาน | K1: หมวดงาน | L1: งานระบบสุขาภิบาลและดับเพลิง (RKCA 2)
A2: สถานที่ก่อสร้าง | D2: =+'RC2_ปร.5 (ก)'!#REF! -> #REF! | J2: เมื่อวันที่ | K2: เมื่อวันที่ | L2: =+'RC2_ปร.5 (ก)'!#REF! -> #REF!
A3: คำนวณราคากลางโดย | D3: =+'RC2_ปร.5 (ก)'!#REF! -> #REF!
O4: 0.93489933
A5: ลำดับ | B5: รายการ | E5: จำนวน | F5: หน่วย | G5: ราคาวัสดุสิ่งของ | J5: ค่าแรงงาน | M5: รวมค่าวัสดุ | N5: หมายเหตุ
G6: ราคา/หน่วย | H6: ราคา/หน่วย | I6: จำนวนเงิน | J6: ราคา/หน่วย | K6: ราคา/หน่วย | L6: จำนวนเงิน | M6: และแรงงาน
B7: สรุปราคาค่าก่อสร้างงานระบบสุขาภิบาลและดับเพลิง
B8: อาคาร Ratchadamnoen Center 2
A9: 1 | B9: งานระบบประปา | E9: 1 | F9: งาน | I9: =I104 -> 1374631 | L9: =L104 -> 142541.69 | M9: =I9+L9 -> 1517172.7 | O9: =P9*0.934908047 -> 1517172.7 | P9: 1622804.2
A10: 2 | B10: งานระบบนำน้ำผ่านการบำบัดกลับมาใช้ | I10: =I107 -> 0 | L10: =L107 -> 0 | M10: =I10+L10 -> 0 | N10: ไม่มี | O10: =P10*0.934908047 -> 0
A11: 3 | B11: งานระบบน้ำเสีย | E11: 1 | F11: งาน | I11: =I175 -> 964182.36 | L11: =L175 -> 183393.43 | M11: =I11+L11 -> 1147575.8 | O11: =P11*0.934908047 -> 1147575.8 | P11: 1227474.5
A12: 4 | B12: งานระบบระบายน้ำฝน | E12: 1 | F12: งาน | I12: =I216 -> 329327.81 | L12: =L216 -> 91980.928 | M12: =I12+L12 -> 421308.74 | O12: =P12*0.934908047 -> 421308.74 | P12: 450641.9
A13: 5 | B13: งานระบบดับเพลิง | E13: 1 | F13: งาน | I13: =I256 -> 468373.33 | L13: =L256 -> 126098.53 | M13: =I13+L13 -> 594471.86 | O13: =P13*0.934908047 -> 594471.86 | P13: 635861.31
O14: =P14*0.934899332 -> 0
B15: รวมราคาค่าก่อสร้างงานระบบสุขาภิบาลและดับเพลิง | I15: =SUM(I9:I14) -> 3136514.5 | L15: =SUM(L9:L14) -> 544014.58 | M15: =SUM(M9:M14) -> 3680529.1 | O15: =SUM(O9:O14) -> 3680529.1 | P15: =SUM(P9:P14) -> 3936781.9
A25: 1 | B25: งานระบบประปา
B27: Main Equipment
B28: 1.1 | C28: เครื่องสูบน้ำเพิ่มแรงดัน และอุปกรณ์ประกอบ
C29: - PBS-01 | E29: 1 | F29: ชุด | G29: 577000 | H29: =G29*O29 -> 539441.94 | I29: =E29*H29 -> 539441.94 | J29: 8500 | K29: =J29*O29 -> 7946.7184 | L29: =E29*K29 -> 7946.7184 | M29: =I29+L29 -> 547388.66 | O29: 0.93490805
C30: - WT-01 | E30: 1 | F30: ชุด | G30: 240570 | H30: =G30*O30 -> 224910.83 | I30: =E30*H30 -> 224910.83 | J30: 6000 | K30: =J30*O30 -> 5609.4483 | L30: =E30*K30 -> 5609.4483 | M30: =I30+L30 -> 230520.28 | O30: 0.93490805
C31: - งานฐานราก WT-01 | E31: 1 | F31: ชุด | I31: =ROUNDDOWN(E31*G31,2) -> 0 | M31: =I31+L31 -> 0 | N31: ราคาอยู่ในงานโครงสร้าง | O31: 0.93490805
B32: งานท่อ (Piping Work) | O32: 0.93490805
B33: 1.2 | C33: ท่อ PP-R PN 10 | O33: 0.93490805
C34: - Ø 20 มม. (15 มม. ) | E34: 30 | F34: ม. | G34: 35 | H34: =G34*O34 -> 32.721782 | I34: =E34*H34 -> 981.65345 | J34: 30 | K34: =J34*O34 -> 28.047241 | L34: =E34*K34 -> 841.41724 | M34: =I34+L34 -> 1823.0707 | O34: 0.93490805
C35: - Ø 25 มม. (20 มม. ) | E35: 334 | F35: ม. | G35: 46 | H35: =G35*O35 -> 43.00577 | I35: =E35*H35 -> 14363.927 | J35: 30 | K35: =J35*O35 -> 28.047241 | L35: =E35*K35 -> 9367.7786 | M35: =I35+L35 -> 23731.706 | O35: 0.93490805 | Q35: กระทรวงพาณิชย์ | R35: 46
C36: - Ø 32 มม. (25 มม.) | E36: 275 | F36: ม. | G36: 76 | H36: =G36*O36 -> 71.053012 | I36: =E36*H36 -> 19539.578 | J36: 30 | K36: =J36*O36 -> 28.047241 | L36: =E36*K36 -> 7712.9914 | M36: =I36+L36 -> 27252.57 | O36: 0.93490805 | Q36: กระทรวงพาณิชย์ | R36: 76
C37: - Ø 40 มม. (32 มม.) | E37: 0 | F37: ม. | G37: 113 | H37: =G37*O37 -> 105.64461 | I37: =E37*H37 -> 0 | J37: 30 | K37: =J37*O37 -> 28.047241 | L37: =E37*K37 -> 0 | M37: =I37+L37 -> 0 | O37: 0.93490805 | Q37: กระทรวงพาณิชย์ | R37: 113
C38: - Ø 50 มม. (40 มม.) | E38: 163 | F38: ม. | G38: 180 | H38: =G38*O38 -> 168.28345 | I38: =E38*H38 -> 27430.202 | J38: 50 | K38: =J38*O38 -> 46.745402 | L38: =E38*K38 -> 7619.5006 | M38: =I38+L38 -> 35049.703 | O38: 0.93490805 | Q38: กระทรวงพาณิชย์ | R38: 180
C39: - Ø 63 มม. (50 มม.) | E39: 73 | F39: ม. | G39: 287 | H39: =G39*O39 -> 268.31861 | I39: =E39*H39 -> 19587.258 | J39: 75 | K39: =J39*O39 -> 70.118104 | L39: =E39*K39 -> 5118.6216 | M39: =I39+L39 -> 24705.88 | O39: 0.93490805 | Q39: กระทรวงพาณิชย์ | R39: 287
C40: - Ø 75 มม. (65 มม.) | E40: 53 | F40: ม. | G40: 402 | H40: =G40*O40 -> 375.83303 | I40: =E40*H40 -> 19919.151 | J40: 100 | K40: =J40*O40 -> 93.490805 | L40: =E40*K40 -> 4955.0126 | M40: =I40+L40 -> 24874.163 | O40: 0.93490805 | Q40: กระทรวงพาณิชย์ | R40: 402
C41: - Ø 90 มม. (80 มม.) | E41: 56 | F41: ม. | G41: 562 | H41: =G41*O41 -> 525.41832 | I41: =E41*H41 -> 29423.426 | J41: 120 | K41: =J41*O41 -> 112.18897 | L41: =E41*K41 -> 6282.5821 | M41: =I41+L41 -> 35706.008 | O41: 0.93490805 | Q41: กระทรวงพาณิชย์ | R41: 562
C42: - Ø 110 มม. (100 มม.) | E42: 9 | F42: ม. | G42: 834 | H42: =G42*O42 -> 779.71331 | I42: =E42*H42 -> 7017.4198 | J42: 150 | K42: =J42*O42 -> 140.23621 | L42: =E42*K42 -> 1262.1259 | M42: =I42+L42 -> 8279.5457 | O42: 0.93490805 | Q42: กระทรวงพาณิชย์ | R42: 643
B43: 1.3 | C43: ท่อ HDPE PN 10 | O43: 0.93490805
C44: - Ø 32 มม. (25 มม.) | E44: 0 | F44: ม. | G44: 33 | I44: =ROUNDDOWN(E44*G44,2) -> 0 | J44: 30 | L44: =ROUNDDOWN(E44*J44,2) -> 0 | M44: =I44+L44 -> 0 | O44: 0.93490805 | Q44: TAP | R44: 33
C45: - Ø 63 มม. (50 มม.) | E45: 0 | F45: ม. | G45: 117.7 | I45: =ROUNDDOWN(E45*G45,2) -> 0 | J45: 75 | L45: =ROUNDDOWN(E45*J45,2) -> 0 | M45: =I45+L45 -> 0 | O45: 0.93490805 | Q45: TAP | R45: 73.7
C46: - Ø 75 มม. (65 มม.) | E46: 0 | F46: ม. | G46: 166.1 | I46: =ROUNDDOWN(E46*G46,2) -> 0 | J46: 100 | L46: =ROUNDDOWN(E46*J46,2) -> 0 | M46: =I46+L46 -> 0 | O46: 0.93490805 | Q46: TAP | R46: 117.7
C47: - Ø 90 มม. (80 มม.) | E47: 69 | F47: ม. | G47: 228.8 | H47: =G47*O47 -> 213.90696 | I47: =E47*H47 -> 14759.58 | J47: 120 | K47: =J47*O47 -> 112.18897 | L47: =E47*K47 -> 7741.0386 | M47: =I47+L47 -> 22500.619 | O47: 0.93490805 | Q47: TAP | R47: 166.1
C48: - Ø 110 มม. (100 มม.) | E48: 0 | F48: ม. | G48: 341 | H48: =G48*O48 -> 318.80364 | I48: =ROUNDDOWN(E48*G48,2) -> 0 | J48: 150 | K48: =J48*O48 -> 140.23621 | L48: =E48*K48 -> 0 | M48: =I48+L48 -> 0 | O48: 0.93490805 | Q48: TAP | R48: 228.8
B49: 1.4 | C49: ข้อต่ออุปกรณ์ท่อ | E49: 1 | F49: เหมา | G49: 80979 | H49: =G49*O49 -> 75707.919 | I49: =E49*H49 -> 75707.919 | J49: 24294 | K49: =J49*O49 -> 22712.656 | L49: =E49*K49 -> 22712.656 | M49: =I49+L49 -> 98420.575 | O49: 0.93490805 | Q49: TAP | R49: 341
B50: 1.5 | C50: เหล็กยึดท่อ | E50: 1 | F50: เหมา | G50: 32392 | H50: =G50*O50 -> 30283.541 | I50: =E50*H50 -> 30283.541 | J50: 9718 | K50: =J50*O50 -> 9085.4364 | L50: =E50*K50 -> 9085.4364 | M50: =I50+L50 -> 39368.978 | O50: 0.93490805
...

Sheet AC
A1: ชื่อโครงการ | D1: =+'RC2_ปร.5 (ก)'!#REF! -> #REF! | J1: หมวดงาน | K1: หมวดงาน | L1: งานระบบปรับอากาศและระบายอากาศ
A2: สถานที่ก่อสร้าง | D2: =+'RC2_ปร.5 (ก)'!#REF! -> #REF! | J2: เมื่อวันที่ | K2: เมื่อวันที่ | L2: =+'RC2_ปร.5 (ก)'!#REF! -> #REF!
A3: คำนวณราคากลางโดย | D3: =+'RC2_ปร.5 (ก)'!#REF! -> #REF!
A5: ลำดับ | B5: รายการ | E5: จำนวน | F5: หน่วย | G5: ราคาวัสดุสิ่งของ | J5: ค่าแรงงาน | M5: รวมค่าวัสดุ | N5: หมายเหตุ
G6: ราคา/หน่วย | H6: ราคา/หน่วย | I6: จำนวนเงิน | J6: ราคา/หน่วย | K6: ราคา/หน่วย | L6: จำนวนเงิน | M6: และแรงงาน
B7: สรุปราคาค่าก่อสร้างงานระบบปรับอากาศและระบายอากาศ
A9: 1 | B9: เครื่องปรับอากาศแบบปรับปริมาณน้ำยาอัตโนมัติ(VRF) | E9: 1 | F9: งาน | I9: =I164 -> 0 | L9: =L164 -> 161271.64 | M9: =I9+L9 -> 161271.64 | O9: =P9*0.934908047 -> 161271.64 | P9: 172500
A10: 2 | B10: พัดลมระบายอากาศ | E10: 1 | F10: งาน | I10: =I223 -> 365140.49 | L10: =L223 -> 21970.339 | M10: =I10+L10 -> 387110.83 | O10: =P10*0.934908047 -> 387110.83 | P10: 414063
A11: 3 | B11: ท่อน้ำยาและท่อน้ำทิ้ง | E11: 1 | F11: งาน | I11: =I261 -> 1898494.4 | L11: =L261 -> 543574.8 | M11: =I11+L11 -> 2442069.2 | O11: =P11*0.934908047 -> 2442069.2 | P11: 2612095.6
A12: 4 | B12: งานท่อลม | E12: 1 | F12: งาน | I12: =I275 -> 1027837.9 | L12: =L275 -> 364913.31 | M12: =I12+L12 -> 1392751.2 | O12: =P12*0.934908047 -> 1392751.2 | P12: 1489720
A13: 5 | B13: หัวจ่ายลมและหน้ากากกลม | E13: 1 | F13: งาน | I13: =I333 -> 248484.18 | L13: =L333 -> 46556.773 | M13: =I13+L13 -> 295040.96 | O13: =P13*0.934908047 -> 295040.95 | P13: 315582.85
A14: 6 | B14: อุปกรณ์ควบคุมอัตโนมัติ (Automatic Control Equipment) | E14: 1 | F14: งาน | I14: =I344 -> 263326.2 | L14: =L344 -> 25726.8 | M14: =I14+L14 -> 289053 | O14: =P14*0.934908047 -> 289053 | P14: 309178
A15: 7 | B15: ระบบไฟฟ้าและควบคุม (Electrical & Control System) | E15: 1 | F15: งาน | I15: =I359 -> 1056446.1 | L15: =L359 -> 174827.8 | M15: =I15+L15 -> 1231273.9 | O15: =P15*0.934908047 -> 1231273.9 | P15: 1317000
A16: 8 | B16: ค่าดำเนินการอื่นๆ | E16: 1 | F16: งาน | I16: =I363 -> 186981.61 | L16: =L363 -> 93490.805 | M16: =I16+L16 -> 280472.41 | O16: =P16*0.934908047 -> 280472.41 | P16: 300000
B18: รวมราคาค่าก่อสร้างงานระบบปรับอากาศและระบายอากาศ | I18: =SUM(I9:I17) -> 5046710.9 | L18: =SUM(L9:L17) -> 1432332.3 | M18: =SUM(M9:M17) -> 6479043.2 | O18: =SUM(O9:O17) -> 6479043.1 | P18: =SUM(P9:P17) -> 6930139.4
A31: 1 | B31: เครื่องปรับอากาศแบบปรับปริมาณน้ำยาอัตโนมัติ(VRF)
B32: 1.1 | C32: เครื่องปรับอากาศแบบปรับปริมาณน้ำยาอัตโนมัติ(VRF)
B33: ชั้น 1
C34: FCU-101 | D34: 72,000 BTU ; CD | E34: 1 | F34: ชุด | I34: =ROUNDDOWN(E34*G34,2) -> 0 | J34: 1000 | K34: =J34*O34 -> 934.90805 | L34: =E34*K34 -> 934.90805 | M34: =I34+L34 -> 934.90805 | O34: 0.93490805
C35: FCU-102 | D35: 18,000 BTU ; CC4 | E35: 1 | F35: ชุด | I35: =ROUNDDOWN(E35*G35,2) -> 0 | J35: 1000 | K35: =J35*O35 -> 934.90805 | L35: =E35*K35 -> 934.90805 | M35: =I35+L35 -> 934.90805 | O35: 0.93490805
C36: FCU-103 | D36: 18,000 BTU ; CC4 | E36: 1 | F36: ชุด | I36: =ROUNDDOWN(E36*G36,2) -> 0 | J36: 1000 | K36: =J36*O36 -> 934.90805 | L36: =E36*K36 -> 934.90805 | M36: =I36+L36 -> 934.90805 | O36: 0.93490805
C37: FCU-104 | D37: 18,000 BTU ; CC4 | E37: 1 | F37: ชุด | I37: =ROUNDDOWN(E37*G37,2) -> 0 | J37: 1000 | K37: =J37*O37 -> 934.90805 | L37: =E37*K37 -> 934.90805 | M37: =I37+L37 -> 934.90805 | O37: 0.93490805
C38: FCU-105 | D38: 18,000 BTU ; CC4 | E38: 1 | F38: ชุด | I38: =ROUNDDOWN(E38*G38,2) -> 0 | J38: 1000 | K38: =J38*O38 -> 934.90805 | L38: =E38*K38 -> 934.90805 | M38: =I38+L38 -> 934.90805 | O38: 0.93490805
C39: FCU-106 | D39: 12,000 BTU ; CC4 | E39: 1 | F39: ชุด | I39: =ROUNDDOWN(E39*G39,2) -> 0 | J39: 1000 | K39: =J39*O39 -> 934.90805 | L39: =E39*K39 -> 934.90805 | M39: =I39+L39 -> 934.90805 | O39: 0.93490805
C40: FCU-107 | D40: 12,000 BTU ; CC4 | E40: 1 | F40: ชุด | I40: =ROUNDDOWN(E40*G40,2) -> 0 | J40: 1000 | K40: =J40*O40 -> 934.90805 | L40: =E40*K40 -> 934.90805 | M40: =I40+L40 -> 934.90805 | O40: 0.93490805
C41: FCU-108 | D41: 12,000 BTU ; CC4 | E41: 1 | F41: ชุด | I41: =ROUNDDOWN(E41*G41,2) -> 0 | J41: 1000 | K41: =J41*O41 -> 934.90805 | L41: =E41*K41 -> 934.90805 | M41: =I41+L41 -> 934.90805 | O41: 0.93490805
B42: ชั้น M | O42: 0.93490805
C43: OAU-M01 | D43: 150200 BTU | E43: 1 | F43: ชุด | I43: =ROUNDDOWN(E43*G43,2) -> 0 | J43: 2000 | K43: =J43*O43 -> 1869.8161 | L43: =E43*K43 -> 1869.8161 | M43: =I43+L43 -> 1869.8161 | O43: 0.93490805
C44: FCU-M01 | D44: 48,000 BTU ; CD | E44: 1 | F44: ชุด | I44: =ROUNDDOWN(E44*G44,2) -> 0 | J44: 1000 | K44: =J44*O44 -> 934.90805 | L44: =E44*K44 -> 934.90805 | M44: =I44+L44 -> 934.90805 | O44: 0.93490805
C45: FCU-M02 | D45: 30,000 BTU ; CD | E45: 1 | F45: ชุด | I45: =ROUNDDOWN(E45*G45,2) -> 0 | J45: 1000 | K45: =J45*O45 -> 934.90805 | L45: =E45*K45 -> 934.90805 | M45: =I45+L45 -> 934.90805 | O45: 0.93490805
C46: FCU-M03 | D46: 30,000 BTU ; CD | E46: 1 | F46: ชุด | I46: =ROUNDDOWN(E46*G46,2) -> 0 | J46: 1000 | K46: =J46*O46 -> 934.90805 | L46: =E46*K46 -> 934.90805 | M46: =I46+L46 -> 934.90805 | O46: 0.93490805
C47: FCU-M04 | D47: 30,000 BTU ; CD | E47: 1 | F47: ชุด | I47: =ROUNDDOWN(E47*G47,2) -> 0 | J47: 1000 | K47: =J47*O47 -> 934.90805 | L47: =E47*K47 -> 934.90805 | M47: =I47+L47 -> 934.90805 | O47: 0.93490805
C48: FCU-M05 | D48: 72,000 BTU ; CD | E48: 1 | F48: ชุด | I48: =ROUNDDOWN(E48*G48,2) -> 0 | J48: 1000 | K48: =J48*O48 -> 934.90805 | L48: =E48*K48 -> 934.90805 | M48: =I48+L48 -> 934.90805 | O48: 0.93490805
C49: FCU-M06 | D49: 30,000 BTU ; CC4 | E49: 1 | F49: ชุด | I49: =ROUNDDOWN(E49*G49,2) -> 0 | J49: 1000 | K49: =J49*O49 -> 934.90805 | L49: =E49*K49 -> 934.90805 | M49: =I49+L49 -> 934.90805 | O49: 0.93490805
C50: FCU-M07 | D50: 30,000 BTU ; CC4 | E50: 1 | F50: ชุด | I50: =ROUNDDOWN(E50*G50,2) -> 0 | J50: 1000 | K50: =J50*O50 -> 934.90805 | L50: =E50*K50 -> 934.90805 | M50: =I50+L50 -> 934.90805 | O50: 0.93490805
C51: FCU-M08 | D51: 30,000 BTU ; CC4 | E51: 1 | F51: ชุด | I51: =ROUNDDOWN(E51*G51,2) -> 0 | J51: 1000 | K51: =J51*O51 -> 934.90805 | L51: =E51*K51 -> 934.90805 | M51: =I51+L51 -> 934.90805 | O51: 0.93490805
C52: FCU-M09 | D52: 30,000 BTU ; CC4 | E52: 1 | F52: ชุด | I52: =ROUNDDOWN(E52*G52,2) -> 0 | J52: 1000 | K52: =J52*O52 -> 934.90805 | L52: =E52*K52 -> 934.90805 | M52: =I52+L52 -> 934.90805 | O52: 0.93490805
C53: FCU-M10 | D53: 24,000 BTU ; CC4 | E53: 1 | F53: ชุด | I53: =ROUNDDOWN(E53*G53,2) -> 0 | J53: 1000 | K53: =J53*O53 -> 934.90805 | L53: =E53*K53 -> 934.90805 | M53: =I53+L53 -> 934.90805 | O53: 0.93490805
C54: FCU-M11 | D54: 72,000 BTU ; CD | E54: 1 | F54: ชุด | I54: =ROUNDDOWN(E54*G54,2) -> 0 | J54: 1000 | K54: =J54*O54 -> 934.90805 | L54: =E54*K54 -> 934.90805 | M54: =I54+L54 -> 934.90805 | O54: 0.93490805
C55: FCU-M12 | D55: 30,000 BTU ; CD | E55: 1 | F55: ชุด | I55: =ROUNDDOWN(E55*G55,2) -> 0 | J55: 1000 | K55: =J55*O55 -> 934.90805 | L55: =E55*K55 -> 934.90805 | M55: =I55+L55 -> 934.90805 | O55: 0.93490805
...

Sheet LD
A1: ชื่อโครงการ | D1: =+'RC2_ปร.5 (ก)'!#REF! -> #REF! | J1: หมวดงาน | K1: หมวดงาน | L1: งานภูมิสถาปัตยกรรมส่วน HARDSCAPE (RC 2)
A2: สถานที่ก่อสร้าง | D2: =+'RC2_ปร.5 (ก)'!#REF! -> #REF! | J2: เมื่อวันที่ | K2: เมื่อวันที่ | L2: =+'RC2_ปร.5 (ก)'!#REF! -> #REF!
A3: คำนวณราคากลางโดย | D3: =+'RC2_ปร.5 (ก)'!#REF! -> #REF!
A5: ลำดับ | B5: รายการ | E5: จำนวน | F5: หน่วย | G5: ราคาวัสดุสิ่งของ | J5: ค่าแรงงาน | M5: รวมค่าวัสดุ | N5: หมายเหตุ
G6: ราคา/หน่วย | H6: ราคา/หน่วย | I6: จำนวนเงิน | J6: ราคา/หน่วย | K6: ราคา/หน่วย | L6: จำนวนเงิน | M6: และแรงงาน
B7: สรุปราคาค่าก่อสร้างงานภูมิสถาปัตยกรรมส่วน HARDSCAPE
B8: อาคาร Ratchadamnoen Center 2
A10: 1 | B10: งานพื้น | M10: =M40 -> 808892.17 | O10: =P10*0.934908047 -> 808892.17 | P10: 865210.41
A11: 2 | B11: งานผนัง | M11: =M44 -> 4851.4764 | O11: =P11*0.934908047 -> 4851.4809 | P11: 5189.26
A12: 3 | B12: งานขอบพื้น | M12: =M51 -> 63544.178 | O12: =P12*0.934908047 -> 63544.176 | P12: 67968.37
A13: 4 | B13: งานระบบรดน้ำ | M13: =M55 -> 0 | O13: =P13*0.934899332 -> 0
O14: =P14*0.934899332 -> 0
B15: รวมราคาค่าก่อสร้างงานภูมิสถาปัตยกรรม Hardscape | M15: =SUM(M10:M14) -> 877287.83 | O15: =SUM(O10:O14) -> 877287.83 | P15: =SUM(P10:P14) -> 938368.04
B31: หมวดงาน HARDSCAPE
A32: 1 | B32: งานพื้น
A33: 1.1 | B33: พื้นทรายปรับระดับบนดิน วางปูบล็อคซึมน้ำ หนา 60 มม. | E33: 884 | F33: ตร.ม. | G33: 647.5 | H33: =G33*O33 -> 605.35296 | I33: =H33*E33 -> 535132.02 | J33: 194.25 | K33: =J33*O33 -> 181.60589 | L33: =E33*K33 -> 160539.61 | M33: =SUM(I33,L33) -> 695671.62 | O33: 0.93490805
B34: พ1 | C34: สีเบจอ่อน | O34: 0.93490805
B35: พ2 | C35: สีเบจกลาง | O35: 0.93490805
B36: พ3 | C36: สีเบจเข้ม | O36: 0.93490805
B37: - | C37: ทรายหยาบปรับระดับ 50 มม. | E37: 44 | F37: ลบ.ม. | G37: 508.33 | H37: =G37*O37 -> 475.24181 | I37: =H37*E37 -> 20910.64 | J37: 112 | K37: =J37*O37 -> 104.7097 | L37: =E37*K37 -> 4607.2269 | M37: =SUM(I37,L37) -> 25517.866 | O37: 0.93490805
B38: - | C38: หินกรวดบดอัดหนา 150 มม. | E38: 133 | F38: ลบ.ม. | G38: 593.33 | H38: =G38*O38 -> 554.70899 | I38: =H38*E38 -> 73776.296 | J38: 112 | K38: =J38*O38 -> 104.7097 | L38: =E38*K38 -> 13926.39 | M38: =SUM(I38,L38) -> 87702.686 | O38: 0.93490805
B39: - | C39: แผ่นใยสังเคราะห์ | E39: 884 | F39: ลบ.ม. | G39: ดูรายละเอียดตามแบบวิศวกร | O39: 0.93490805
B40: รวมราคางานพื้น | M40: =SUM(M33:M38) -> 808892.17 | O40: 0.93490805
O41: 0.93490805
A42: 2 | B42: งานผนัง | O42: 0.93490805
A43: 2.1 | B43: ผ1 | C43: ที่นั่งค.ส.ล. ทำผิวหินขัดหนา 10 มม. | E43: 9 | F43: ตร.ม. | G43: 343.9389 | H43: =G43*O43 -> 321.55125 | I43: =H43*E43 -> 2893.9612 | J43: 232.645 | K43: =J43*O43 -> 217.50168 | L43: =E43*K43 -> 1957.5151 | M43: =SUM(I43,L43) -> 4851.4764 | O43: 0.93490805
B44: รวมราคางานผนัง | M44: =SUM(M43) -> 4851.4764 | O44: 0.93490805
O45: 0.93490805
A46: 3 | B46: งานขอบพื้น | O46: 0.93490805
A47: 3.1 | B47: ข1 | C47: ขอบค.ส.ล.ทำผิวหินขัด หนา 10 มม. | E47: 58 | F47: ตร.ม. | G47: 238.02 | H47: =G47*O47 -> 222.52681 | I47: =H47*E47 -> 12906.555 | J47: 161 | K47: =J47*O47 -> 150.5202 | L47: =E47*K47 -> 8730.1713 | M47: =I47+L47 -> 21636.727 | O47: 0.93490805
A48: 3.2 | B48: ข2 | C48: ขอบค.ส.ล.สำเร็จรูปมาตรฐาน ขนาด 150x300x1000 มม. | E48: 46 | F48: ม. | G48: 148.54 | H48: =G48*O48 -> 138.87124 | I48: =H48*E48 -> 6388.0771 | J48: 44.562 | K48: =J48*O48 -> 41.661372 | L48: =E48*K48 -> 1916.4231 | M48: =I48+L48 -> 8304.5002 | O48: 0.93490805
A49: 3.3 | B49: ข3 | C49: ขอบล้มค.ส.ล. ขนาด 150x600x1000 มม. | E49: 83 | F49: ม. | G49: 299.19 | H49: =G49*O49 -> 279.71514 | I49: =H49*E49 -> 23216.357 | J49: 68.13 | K49: =J49*O49 -> 63.695285 | L49: =E49*K49 -> 5286.7087 | M49: =I49+L49 -> 28503.065 | O49: 0.93490805
A50: 3.4 | B50: ข4 | C50: ขอบเหล็กแบนขนาด 1 นิ้ว หนา 12 มม. ทำสีดำ | E50: 51 | F50: ม. | G50: 72.2 | H50: =G50*O50 -> 67.500361 | I50: =H50*E50 -> 3442.5184 | J50: 34.76 | K50: =J50*O50 -> 32.497404 | L50: =E50*K50 -> 1657.3676 | M50: =I50+L50 -> 5099.886 | O50: 0.93490805
B51: รวมราคางานขอบพื้น | M51: =SUM(M47:M50) -> 63544.178
A53: 4 | B53: งานระบบรดน้ำ
A54: 4.1 | B54: งานระบบรดน้ำหัวก๊อก | E54: 3 | F54: จุด | G54: .
B55: รวมราคางานระบบรดน้ำ | M55: =SUM(M54) -> 0

Sheet แบบ ปร.5(ข)
F1: แบบ ปร.5ข
A2: แบบสรุปราคาค่าก่อสร้างงานครุภัณฑ์จัดซื้อ
A4: ชื่อโครงการ | C4: =+'RC2_ปร.5 (ก)'!#REF! -> #REF!
A5: สถานที่ก่อสร้าง | C5: =+'RC2_ปร.5 (ก)'!#REF! -> #REF!
A6: เจ้าของอาคาร | C6: สำนักงานบริหารและพัฒนาองค์ความรู้ (องค์การมหาชน)
A7: หน่วยงานออกแบบแปลนและรายการ | C7: กิจการร่วมค้าบริษัท จีโอเดสิค ดีไซน์ จำกัด , บริษัท เอ็มสเปซ จำกัด และ บริษัท จั่นอาร์คิเทค จำกัด
A8: แบบ ปร.4 (ข) ที่แนบ | C8: 30 แผ่น
A9: คำนวนราคาโดย | C9: =+'RC2_ปร.5 (ก)'!#REF! -> #REF!
A10: เมื่อวันที่ | C10: =+'RC2_ปร.5 (ก)'!#REF! -> #REF!
A12: ลำดับที่ | B12: รายการ | C12: ค่างาน | D12: ภาษีมูลค่าเพิ่ม | E12: ค่าก่อสร้าง | F12: หมายเหตุ
C13: (บาท) | E13: (บาท)
B14: ส่วนที่ 2 ค่าครุภัณฑ์สั่งซื้อหรือจัดซื้อ
B15: อาคาร Ratchadamnoen Center 2
A16: 1 | B16: งานครุภัณฑ์ประจำอาคาร | C16: =EQ!L14 -> 10154358 | D16: =SUM(C16*7/100) -> 710805.05 | E16: =SUM(C16:D16) -> 10865163
A17: 2 | B17: งานครุภัณฑ์ลอยตัว | C17: =Loose!L18 -> 13071078 | D17: =SUM(C17*7/100) -> 914975.48 | E17: =SUM(C17:D17) -> 13986054
A18: 3 | B18: งานครุภัณฑ์ภาพและเสียง | C18: =AV!M24 -> 7099177.5 | D18: =SUM(C18*7/100) -> 496942.43 | E18: =SUM(C18:D18) -> 7596119.9
A19: 4 | B19: งานครุภัณฑ์ Soft Scape | C19: =HC_SC!M13 -> 710726.49 | D19: =SUM(C19*7/100) -> 49750.855 | E19: =SUM(C19:D19) -> 760477.35
A22: สรุป | B22: รวมค่าก่อสร้าง ส่วนที่ 2 ค่าครุภัณฑ์สั่งซื้อหรือจัดซื้อ | C22: =SUM(C16:C21) -> 31035340 | E22: =SUM(E14:E21) -> 33207814
B23: ="("&BAHTTEXT(E22)&")" -> (สามสิบสามล้านสองแสนเจ็ดพันแปดร้อยสิบสี่บาทหกสตางค์)
B24: พื้นที่อาคาร | C24: =+'RC2_ปร.5 (ก)'!G20 -> 5825 | D24: ตารางเมตร
B25: เฉลี่ยราคาประมาณ | C25: =+E22/C24 -> 5700.9123 | D25: บาท/ตารางเมตร

Sheet EQ
A1: ชื่อโครงการ | D1: =+'แบบ ปร.5(ข)'!C4 -> #REF! | J1: หมวดงาน | K1: งานครุภัณฑ์ประจำอาคาร
A2: สถานที่ก่อสร้าง | D2: =+'แบบ ปร.5(ข)'!C5 -> #REF! | J2: เมื่อวันที่ | K2: =+'RC2_ปร.5 (ก)'!#REF! -> #REF!
A3: คำนวณราคากลางโดย | D3: =+'RC2_ปร.5 (ก)'!#REF! -> #REF!
A5: ลำดับ | B5: รายการ | E5: จำนวน | F5: หน่วย | G5: ราคาวัสดุสิ่งของ | J5: ค่าแรงงาน | L5: รวมค่าวัสดุ | M5: หมายเหตุ
G6: ราคา/หน่วย | H6: ราคา/หน่วย | I6: จำนวนเงิน | J6: ราคา/หน่วย | K6: จำนวนเงิน | L6: และแรงงาน
B7: สรุปราคาค่าก่อสร้างงานครุภัณฑ์ประจำอาคาร
B8: อาคาร Ratchadamnoen Center 2
A10: 1 | B10: งานครุภัณฑ์ลิฟต์ | L10: =L33 -> 1262125.9 | N10: =O10*0.934908047 -> 1262125.9 | O10: 1350000
A11: 2 | B11: งานครุภัณฑ์ระบบวิศวกรรมไฟฟ้า | L11: =L37 -> 820849.27 | N11: =O11*0.934908047 -> 820849.27 | O11: 878000
A12: 3 | B12: งานครุภัณฑ์งานระบบปรับอากาศและระบายอากาศ | L12: =+L167 -> 8071382.8 | N12: =O12*0.934908047 -> 8071382.8 | O12: 8633344
N13: =O13*0.934899332 -> 0
B14: รวมราคางานครุภัณฑ์ประจำอาคาร | L14: =SUM(L10:L13) -> 10154358 | N14: =SUM(N10:N13) -> 10154358 | O14: =SUM(O10:O13) -> 10861344
A31: 1 | B31: งานครุภัณฑ์ลิฟต์
B32: ลิฟต์แก้ว L1 | E32: 1 | F32: ชุด | G32: 1350000 | H32: =G32*N32 -> 1262125.9 | I32: =E32*H32 -> 1262125.9 | J32: 0 | K32: 0 | L32: =SUM(I32) -> 1262125.9 | N32: 0.93490805
B33: รวมราคางานครุภัณฑ์ลิฟต์ | L33: =SUM(L32:L32) -> 1262125.9 | N33: 0.93490805
A34: 2 | B34: งานครุภัณฑ์ระบบวิศวกรรมไฟฟ้า | N34: 0.93490805
A35: 2.1 | B35: เครื่องกำเนิดไฟฟ้าสำรอง | N35: 0.93490805
B36: - | C36: Generator Set 100 kVA 0.8PF Canopy Type | E36: 1 | F36: ชุด | G36: 878000 | H36: =G36*N36 -> 820849.27 | I36: =E36*H36 -> 820849.27 | K36: =ROUNDDOWN(E36*J36,2) -> 0 | L36: =I36+K36 -> 820849.27 | N36: 0.93490805
B37: รวมราคางานระบบวิศวกรรมไฟฟ้า | L37: =SUM(L36) -> 820849.27 | N37: 0.93490805
A38: 2 | B38: งานครุภัณฑ์งานระบบปรับอากาศและระบายอากาศ | N38: 0.93490805
B39: เครื่องปรับอากาศแบบปรับปริมาณน้ำยาอัตโนมัติ(VRF) | N39: 0.93490805
B40: ชั้น 1 | N40: 0.93490805
C41: FCU-101 | D41: 72,000 BTU ; CD | E41: 1 | F41: ชุด | G41: 65016 | H41: =G41*N41 -> 60783.982 | I41: =E41*H41 -> 60783.982 | K41: =ROUNDDOWN(E41*J41,2) -> 0 | L41: =I41+K41 -> 60783.982 | N41: 0.93490805
C42: FCU-102 | D42: 18,000 BTU ; CC4 | E42: 1 | F42: ชุด | G42: 30240 | H42: =G42*N42 -> 28271.619 | I42: =E42*H42 -> 28271.619 | K42: =ROUNDDOWN(E42*J42,2) -> 0 | L42: =I42+K42 -> 28271.619 | N42: 0.93490805
