Workbook
Name ____str1: #REF!
Name ____str1: #REF!
Name ____str1: #REF!
Name ____str1: #REF!
Name ____str1: #REF!
Name ____str1: #REF!
Name ____str1: #REF!
Name ____str2: #REF!
Name ____str2: #REF!
Name ____str2: #REF!
Name ____str2: #REF!
Name ____str2: #REF!
Name ____str2: #REF!
Name ____str3: #REF!
Name ____str3: #REF!
Name ____str3: #REF!
Name ____str3: #REF!
Name ____str3: #REF!
Name ____str3: #REF!
Name ___str1: #REF!
Name ___str2: #REF!
Name ___str3: #REF!
Name __str1: #REF!
Name __str2: #REF!
Name __str3: #REF!
Name _1Excel_BuiltIn_Print_Area_1_1: #REF!
Name _str1: #REF!
Name _str1: #REF!
Name _str1: #REF!
Name _str1: #REF!
Name _str1: #REF!
Name _str1: #REF!
Name _str2: #REF!
Name _str2: #REF!
Name _str2: #REF!
Name _str2: #REF!
Name _str3: #REF!
Name _str3: #REF!
Name A: #REF!
Name A: #REF!
Name A: #REF!
Name A: #REF!
Name A: #REF!
Name A: #REF!
Name A: #REF!
Name A: #REF!
Name A: #REF!
Name ABL: #REF!
Name ada: #REF!
Name ada: #REF!
Name ada: #REF!
Name ada: #REF!
Name ada: #REF!
Name ada: #REF!
Name ada: #REF!
Name ARCH_LAB: #REF!
Name ARCH_LAB: #REF!
Name ARCH_LAB: #REF!
Name ARCH_LAB: #REF!
Name ARCH_LAB: #REF!

Sheet OKMD
A1: WBS-1 | B1: WBS-2 | C1: WBS-3 | D1: WBS-4 | E1: Description | G1: Unit | H1: Qty | I1: Material | J1: Labor | K1: Amount
E2: {=_xlfn.LET(_xlpm.c,'RC1_Structure_RE'!C31, _xlpm.b, 'RC1_Structure_RE'!B31, IF(_xlpm.c<>"", _xlpm.c, _xlpm.b))} -> งานเสาเข็ม Pile wall และระบบค้ำยันใต้ดิน
A3: STR | B3: Sub-Structure | C3: Pilling | D3: Pilling | E3: {=_xlfn.LET(_xlpm.c,'RC1_Structure_RE'!C32, _xlpm.b, 'RC1_Structure_RE'!B32, IF(_xlpm.c<>"", _xlpm.c, _xlpm.b))} -> งานเสาเข็มอาคาร
A4: STR | B4: Sub-Structure | C4: Pilling | D4: Pilling | E4: {=_xlfn.LET(_xlpm.c,'RC1_Structure_RE'!C33, _xlpm.b, 'RC1_Structure_RE'!B33, IF(_xlpm.c<>"", _xlpm.c, _xlpm.b))} -> เสาเข็มเจาะชนิดเปียก Type-1 Dia 0.60 Pile Tip -35.00 m. | G4: ='RC1_Structure_RE'!F33 -> ต้น | H4: ='RC1_Structure_RE'!E33 -> 537 | I4: ='RC1_Structure_RE'!I33 -> 37149202 | J4: ='RC1_Structure_RE'!L33 -> 0 | K4: ='RC1_Structure_RE'!M33 -> 37149202
A5: STR | B5: Sub-Structure | C5: Pilling | D5: Pilling | E5: {=_xlfn.LET(_xlpm.c,'RC1_Structure_RE'!C34, _xlpm.b, 'RC1_Structure_RE'!B34, IF(_xlpm.c<>"", _xlpm.c, _xlpm.b))} -> เสาเข็มเจาะชนิดเปียก Type-2 Dia 0.60 Pile Tip -35.00 m. | G5: ='RC1_Structure_RE'!F34 -> ต้น | H5: ='RC1_Structure_RE'!E34 -> 9 | I5: ='RC1_Structure_RE'!I34 -> 687141.29 | J5: ='RC1_Structure_RE'!L34 -> 0 | K5: ='RC1_Structure_RE'!M34 -> 687141.29
A6: STR | B6: Sub-Structure | C6: Pilling | D6: Pilling | E6: {=_xlfn.LET(_xlpm.c,'RC1_Structure_RE'!C35, _xlpm.b, 'RC1_Structure_RE'!B35, IF(_xlpm.c<>"", _xlpm.c, _xlpm.b))} -> งานตัดหัวเสาเข็ม | G6: ='RC1_Structure_RE'!F35 -> ต้น | H6: ='RC1_Structure_RE'!E35 -> 537 | I6: ='RC1_Structure_RE'!I35 -> 0 | J6: ='RC1_Structure_RE'!L35 -> 301227.37 | K6: ='RC1_Structure_RE'!M35 -> 301227.37
A7: STR | B7: Sub-Structure | C7: Pilling | D7: Pilling | E7: {=_xlfn.LET(_xlpm.c,'RC1_Structure_RE'!C36, _xlpm.b, 'RC1_Structure_RE'!B36, IF(_xlpm.c<>"", _xlpm.c, _xlpm.b))} -> งานทดสอบเสาเข็ม | G7: ='RC1_Structure_RE'!F36 -> 0 | H7: ='RC1_Structure_RE'!E36 -> 0 | I7: ='RC1_Structure_RE'!I36 -> 0 | J7: ='RC1_Structure_RE'!L36 -> 0 | K7: ='RC1_Structure_RE'!M36 -> 0
A8: STR | B8: Sub-Structure | C8: Pilling | D8: Pilling | E8: {=_xlfn.LET(_xlpm.c,'RC1_Structure_RE'!C37, _xlpm.b, 'RC1_Structure_RE'!B37, IF(_xlpm.c<>"", _xlpm.c, _xlpm.b))} -> DYNAMIC LOAD TEST | G8: ='RC1_Structure_RE'!F37 -> ต้น | H8: ='RC1_Structure_RE'!E37 -> 3 | I8: ='RC1_Structure_RE'!I37 -> 11218.897 | J8: ='RC1_Structure_RE'!L37 -> 0 | K8: ='RC1_Structure_RE'!M37 -> 11218.897
A9: STR | B9: Sub-Structure | C9: Pilling | D9: Pilling | E9: {=_xlfn.LET(_xlpm.c,'RC1_Structure_RE'!C38, _xlpm.b, 'RC1_Structure_RE'!B38, IF(_xlpm.c<>"", _xlpm.c, _xlpm.b))} -> SEISMIC TEST | G9: ='RC1_Structure_RE'!F38 -> ต้น | H9: ='RC1_Structure_RE'!E38 -> 546 | I9: ='RC1_Structure_RE'!I38 -> 0 | J9: ='RC1_Structure_RE'!L38 -> 61255.175 | K9: ='RC1_Structure_RE'!M38 -> 61255.175
A10: STR | B10: Sub-Structure | C10: Soil Protection | D10: Pile Wall | E10: {=_xlfn.LET(_xlpm.c,'RC1_Structure_RE'!C39, _xlpm.b, 'RC1_Structure_RE'!B39, IF(_xlpm.c<>"", _xlpm.c, _xlpm.b))} -> งานเสาเข็ม Pilewall | G10: ='RC1_Structure_RE'!F39 -> 0 | H10: ='RC1_Structure_RE'!E39 -> 0 | I10: ='RC1_Structure_RE'!I39 -> 0 | J10: ='RC1_Structure_RE'!L39 -> 0 | K10: ='RC1_Structure_RE'!M39 -> 0
A11: STR | B11: Sub-Structure | C11: Soil Protection | D11: Pile Wall | E11: {=_xlfn.LET(_xlpm.c,'RC1_Structure_RE'!C40, _xlpm.b, 'RC1_Structure_RE'!B40, IF(_xlpm.c<>"", _xlpm.c, _xlpm.b))} -> เสาเข็มเจาะชนิดเปียก Type-1 Dia 0.60 x 18 m. | G11: ='RC1_Structure_RE'!F40 -> ต้น | H11: ='RC1_Structure_RE'!E40 -> 608 | I11: ='RC1_Structure_RE'!I40 -> 27376168 | J11: ='RC1_Structure_RE'!L40 -> 0 | K11: ='RC1_Structure_RE'!M40 -> 27376168
A12: STR | B12: Sub-Structure | C12: Soil Protection | D12: Pile Wall | E12: {=_xlfn.LET(_xlpm.c,'RC1_Structure_RE'!C41, _xlpm.b, 'RC1_Structure_RE'!B41, IF(_xlpm.c<>"", _xlpm.c, _xlpm.b))} -> เสาเข็มเจาะชนิดเปียก Type-2 Dia 0.60 x 18 m. | G12: ='RC1_Structure_RE'!F41 -> ต้น | H12: ='RC1_Structure_RE'!E41 -> 67 | I12: ='RC1_Structure_RE'!I41 -> 3164138.3 | J12: ='RC1_Structure_RE'!L41 -> 0 | K12: ='RC1_Structure_RE'!M41 -> 3164138.3
E30: {=_xlfn.LET(_xlpm.c,'RC1_Structure_RE'!C59, _xlpm.b, 'RC1_Structure_RE'!B59, IF(_xlpm.c<>"", _xlpm.c, _xlpm.b))} -> งานโครงสร้างฐานรากและชั้นใต้ดิน | G30: ='RC1_Structure_RE'!F59 -> 0 | H30: ='RC1_Structure_RE'!E59 -> 0 | I30: ='RC1_Structure_RE'!I59 -> 0 | J30: ='RC1_Structure_RE'!L59 -> 0 | K30: ='RC1_Structure_RE'!M59 -> 0
A31: STR | B31: Sub-Structure | C31: Foundation | D31: Foundation | E31: {=_xlfn.LET(_xlpm.c,'RC1_Structure_RE'!C60, _xlpm.b, 'RC1_Structure_RE'!B60, IF(_xlpm.c<>"", _xlpm.c, _xlpm.b))} -> โครงสร้างฐานราก | G31: ='RC1_Structure_RE'!F60 -> 0 | H31: ='RC1_Structure_RE'!E60 -> 0 | I31: ='RC1_Structure_RE'!I60 -> 0 | J31: ='RC1_Structure_RE'!L60 -> 0 | K31: ='RC1_Structure_RE'!M60 -> 0
A32: STR | B32: Sub-Structure | C32: Foundation | D32: Foundation | E32: {=_xlfn.LET(_xlpm.c,'RC1_Structure_RE'!C61, _xlpm.b, 'RC1_Structure_RE'!B61, IF(_xlpm.c<>"", _xlpm.c, _xlpm.b))} -> งานขุดดิน และถมกลับ | G32: ='RC1_Structure_RE'!F61 -> ลบ.ม. | H32: ='RC1_Structure_RE'!E61 -> 6016 | I32: ='RC1_Structure_RE'!I61 -> 0 | J32: ='RC1_Structure_RE'!L61 -> 629933.56 | K32: ='RC1_Structure_RE'!M61 -> 629933.56
A33: STR | B33: Sub-Structure | C33: Foundation | D33: Foundation | E33: {=_xlfn.LET(_xlpm.c,'RC1_Structure_RE'!C62, _xlpm.b, 'RC1_Structure_RE'!B62, IF(_xlpm.c<>"", _xlpm.c, _xlpm.b))} -> งานทรายหยาบบดอัดแน่น | G33: ='RC1_Structure_RE'!F62 -> ลบ.ม. | H33: ='RC1_Structure_RE'!E62 -> 80 | I33: ='RC1_Structure_RE'!I62 -> 38019.345 | J33: ='RC1_Structure_RE'!L62 -> 7778.435 | K33: ='RC1_Structure_RE'!M62 -> 45797.78
A34: STR | B34: Sub-Structure | C34: Foundation | D34: Foundation | E34: {=_xlfn.LET(_xlpm.c,'RC1_Structure_RE'!C63, _xlpm.b, 'RC1_Structure_RE'!B63, IF(_xlpm.c<>"", _xlpm.c, _xlpm.b))} -> งานคอนกรีตหยาบ | G34: ='RC1_Structure_RE'!F63 -> ลบ.ม. | H34: ='RC1_Structure_RE'!E63 -> 160 | I34: ='RC1_Structure_RE'!I63 -> 367979.81 | J34: ='RC1_Structure_RE'!L63 -> 63723.332 | K34: ='RC1_Structure_RE'!M63 -> 431703.14
A35: STR | B35: Sub-Structure | C35: Foundation | D35: Foundation | E35: {=_xlfn.LET(_xlpm.c,'RC1_Structure_RE'!C64, _xlpm.b, 'RC1_Structure_RE'!B64, IF(_xlpm.c<>"", _xlpm.c, _xlpm.b))} -> งานเหล็กเสริม | G35: ='RC1_Structure_RE'!F64 -> 0 | H35: ='RC1_Structure_RE'!E64 -> 0 | I35: ='RC1_Structure_RE'!I64 -> 0 | J35: ='RC1_Structure_RE'!L64 -> 0 | K35: ='RC1_Structure_RE'!M64 -> 0
A36: STR | B36: Sub-Structure | C36: Foundation | D36: Foundation | E36: {=_xlfn.LET(_xlpm.c,'RC1_Structure_RE'!C65, _xlpm.b, 'RC1_Structure_RE'!B65, IF(_xlpm.c<>"", _xlpm.c, _xlpm.b))} -> ขนาดเส้นผ่านศูนย์กลาง 12 ม.ม. SD-50 | G36: ='RC1_Structure_RE'!F65 -> กก. | H36: ='RC1_Structure_RE'!E65 -> 6914 | I36: ='RC1_Structure_RE'!I65 -> 125723.91 | J36: ='RC1_Structure_RE'!L65 -> 23270.235 | K36: ='RC1_Structure_RE'!M65 -> 148994.15
A37: STR | B37: Sub-Structure | C37: Foundation | D37: Foundation | E37: {=_xlfn.LET(_xlpm.c,'RC1_Structure_RE'!C66, _xlpm.b, 'RC1_Structure_RE'!B66, IF(_xlpm.c<>"", _xlpm.c, _xlpm.b))} -> ขนาดเส้นผ่านศูนย์กลาง 16 ม.ม. SD-50 | G37: ='RC1_Structure_RE'!F66 -> กก. | H37: ='RC1_Structure_RE'!E66 -> 13573 | I37: ='RC1_Structure_RE'!I66 -> 244273.01 | J37: ='RC1_Structure_RE'!L66 -> 45682.225 | K37: ='RC1_Structure_RE'!M66 -> 289955.23
A38: STR | B38: Sub-Structure | C38: Foundation | D38: Foundation | E38: {=_xlfn.LET(_xlpm.c,'RC1_Structure_RE'!C67, _xlpm.b, 'RC1_Structure_RE'!B67, IF(_xlpm.c<>"", _xlpm.c, _xlpm.b))} -> ขนาดเส้นผ่านศูนย์กลาง 20 ม.ม. SD-50 | G38: ='RC1_Structure_RE'!F67 -> กก. | H38: ='RC1_Structure_RE'!E67 -> 13680 | I38: ='RC1_Structure_RE'!I67 -> 246198.69 | J38: ='RC1_Structure_RE'!L67 -> 39647.58 | K38: ='RC1_Structure_RE'!M67 -> 285846.27
A39: STR | B39: Sub-Structure | C39: Foundation | D39: Foundation | E39: {=_xlfn.LET(_xlpm.c,'RC1_Structure_RE'!C68, _xlpm.b, 'RC1_Structure_RE'!B68, IF(_xlpm.c<>"", _xlpm.c, _xlpm.b))} -> ขนาดเส้นผ่านศูนย์กลาง 25 ม.ม. SD-50 | G39: ='RC1_Structure_RE'!F68 -> กก. | H39: ='RC1_Structure_RE'!E68 -> 64375 | I39: ='RC1_Structure_RE'!I68 -> 1158555.6 | J39: ='RC1_Structure_RE'!L68 -> 186572.59 | K39: ='RC1_Structure_RE'!M68 -> 1345128.2
A40: STR | B40: Sub-Structure | C40: Foundation | D40: Foundation | E40: {=_xlfn.LET(_xlpm.c,'RC1_Structure_RE'!C69, _xlpm.b, 'RC1_Structure_RE'!B69, IF(_xlpm.c<>"", _xlpm.c, _xlpm.b))} -> ขนาดเส้นผ่านศูนย์กลาง 28 ม.ม. SD-50 | G40: ='RC1_Structure_RE'!F69 -> กก. | H40: ='RC1_Structure_RE'!E69 -> 3222 | I40: ='RC1_Structure_RE'!I69 -> 57986.269 | J40: ='RC1_Structure_RE'!L69 -> 9338.0486 | K40: ='RC1_Structure_RE'!M69 -> 67324.318
A41: STR | B41: Sub-Structure | C41: Foundation | D41: Foundation | E41: {=_xlfn.LET(_xlpm.c,'RC1_Structure_RE'!C70, _xlpm.b, 'RC1_Structure_RE'!B70, IF(_xlpm.c<>"", _xlpm.c, _xlpm.b))} -> ลวดผูกเหล็ก | G41: ='RC1_Structure_RE'!F70 -> กก. | H41: ='RC1_Structure_RE'!E70 -> 1832 | I41: ='RC1_Structure_RE'!I70 -> 46415.567 | J41: ='RC1_Structure_RE'!L70 -> 0 | K41: ='RC1_Structure_RE'!M70 -> 46415.567
A42: STR | B42: Sub-Structure | C42: Foundation | D42: Foundation | E42: {=_xlfn.LET(_xlpm.c,'RC1_Structure_RE'!C71, _xlpm.b, 'RC1_Structure_RE'!B71, IF(_xlpm.c<>"", _xlpm.c, _xlpm.b))} -> งานไม้แบบ | G42: ='RC1_Structure_RE'!F71 -> 0 | H42: ='RC1_Structure_RE'!E71 -> 0 | I42: ='RC1_Structure_RE'!I71 -> 0 | J42: ='RC1_Structure_RE'!L71 -> 0 | K42: ='RC1_Structure_RE'!M71 -> 0
... A199: STR | B199: Sub-Structure | C199: Underground Tank | D199: Gutter | E199: {=_xlfn.LET(_xlpm.c,'RC1_Structure_RE'!C228, _xlpm.b, 'RC1_Structure_RE'!B228, IF(_xlpm.c<>"", _xlpm.c, _xlpm.b))} -> งานคอนกรีตโครงสร้าง 320 ksc.ผสมน้ำยากันซึม | G199: ='RC1_Structure_RE'!F228 -> ลบ.ม. | H199: ='RC1_Structure_RE'!E228 -> 136.8 | I199: ='RC1_Structure_RE'!I228 -> 289043.65 | J199: ='RC1_Structure_RE'!L228 -> 66377.723 | K199: ='RC1_Structure_RE'!M228 -> 355421.37
E216: {=_xlfn.LET(_xlpm.c,'RC1_Structure_RE'!C245, _xlpm.b, 'RC1_Structure_RE'!B245, IF(_xlpm.c<>"", _xlpm.c, _xlpm.b))} -> งานโครงสร้าง คาน พื้น เสา ผนังชั้น 1
E217: {=_xlfn.LET(_xlpm.c,'RC1_Structure_RE'!C246, _xlpm.b, 'RC1_Structure_RE'!B246, IF(_xlpm.c<>"", _xlpm.c, _xlpm.b))} -> 0 | G217: ='RC1_Structure_RE'!F246 -> 0 | H217: ='RC1_Structure_RE'!E246 -> 0 | I217: ='RC1_Structure_RE'!I246 -> 0 | J217: ='RC1_Structure_RE'!L246 -> 0 | K217: ='RC1_Structure_RE'!M246 -> 0
A218: STR | B218: Super Structure | C218: Gr.Floor | D218: Beam | E218: {=_xlfn.LET(_xlpm.c,'RC1_Structure_RE'!C247, _xlpm.b, 'RC1_Structure_RE'!B247, IF(_xlpm.c<>"", _xlpm.c, _xlpm.b))} -> โครงสร้างคาน ชั้น 1 | G218: ='RC1_Structure_RE'!F247 -> 0 | H218: ='RC1_Structure_RE'!E247 -> 0 | I218: ='RC1_Structure_RE'!I247 -> 0 | J218: ='RC1_Structure_RE'!L247 -> 0 | K218: ='RC1_Structure_RE'!M247 -> 0
A219: STR | B219: Super Structure | C219: Gr.Floor | D219: Beam | E219: {=_xlfn.LET(_xlpm.c,'RC1_Structure_RE'!C248, _xlpm.b, 'RC1_Structure_RE'!B248, IF(_xlpm.c<>"", _xlpm.c, _xlpm.b))} -> งานขุดดิน และถมกลับ | G219: ='RC1_Structure_RE'!F248 -> ลบ.ม. | H219: ='RC1_Structure_RE'!E248 -> 231 | I219: ='RC1_Structure_RE'!I248 -> 0 | J219: ='RC1_Structure_RE'!L248 -> 24187.941 | K219: ='RC1_Structure_RE'!M248 -> 24187.941
A220: STR | B220: Super Structure | C220: Gr.Floor | D220: Beam | E220: {=_xlfn.LET(_xlpm.c,'RC1_Structure_RE'!C249, _xlpm.b, 'RC1_Structure_RE'!B249, IF(_xlpm.c<>"", _xlpm.c, _xlpm.b))} -> งานทรายหยาบบดอัดแน่น | G220: ='RC1_Structure_RE'!F249 -> ลบ.ม. | H220: ='RC1_Structure_RE'!E249 -> 7 | I220: ='RC1_Structure_RE'!I249 -> 3326.6927 | J220: ='RC1_Structure_RE'!L249 -> 680.61306 | K220: ='RC1_Structure_RE'!M249 -> 4007.3057
A221: STR | B221: Super Structure | C221: Gr.Floor | D221: Beam | E221: {=_xlfn.LET(_xlpm.c,'RC1_Structure_RE'!C250, _xlpm.b, 'RC1_Structure_RE'!B250, IF(_xlpm.c<>"", _xlpm.c, _xlpm.b))} -> งานคอนกรีตหยาบ | G221: ='RC1_Structure_RE'!F250 -> ลบ.ม. | H221: ='RC1_Structure_RE'!E250 -> 7 | I221: ='RC1_Structure_RE'!I250 -> 16099.117 | J221: ='RC1_Structure_RE'!L250 -> 2787.8958 | K221: ='RC1_Structure_RE'!M250 -> 18887.012
A222: STR | B222: Super Structure | C222: Gr.Floor | D222: Beam | E222: {=_xlfn.LET(_xlpm.c,'RC1_Structure_RE'!C251, _xlpm.b, 'RC1_Structure_RE'!B251, IF(_xlpm.c<>"", _xlpm.c, _xlpm.b))} -> งานเหล็กเสริม | G222: ='RC1_Structure_RE'!F251 -> 0 | H222: ='RC1_Structure_RE'!E251 -> 0 | I222: ='RC1_Structure_RE'!I251 -> 0 | J222: ='RC1_Structure_RE'!L251 -> 0 | K222: ='RC1_Structure_RE'!M251 -> 0
A223: STR | B223: Super Structure | C223: Gr.Floor | D223: Beam | E223: {=_xlfn.LET(_xlpm.c,'RC1_Structure_RE'!C252, _xlpm.b, 'RC1_Structure_RE'!B252, IF(_xlpm.c<>"", _xlpm.c, _xlpm.b))} -> ขนาดเส้นผ่านศูนย์กลาง 9 ม.ม. SR-24 | G223: ='RC1_Structure_RE'!F252 -> กก. | H223: ='RC1_Structure_RE'!E252 -> 29 | I223: ='RC1_Structure_RE'!I252 -> 531.40173 | J223: ='RC1_Structure_RE'!L252 -> 119.29427 | K223: ='RC1_Structure_RE'!M252 -> 650.696
A224: STR | B224: Super Structure | C224: Gr.Floor | D224: Beam | E224: {=_xlfn.LET(_xlpm.c,'RC1_Structure_RE'!C253, _xlpm.b, 'RC1_Structure_RE'!B253, IF(_xlpm.c<>"", _xlpm.c, _xlpm.b))} -> ขนาดเส้นผ่านศูนย์กลาง 12 ม.ม. SD-50 | G224: ='RC1_Structure_RE'!F253 -> กก. | H224: ='RC1_Structure_RE'!E253 -> 21547 | I224: ='RC1_Structure_RE'!I253 -> 391809.82 | J224: ='RC1_Structure_RE'!L253 -> 72520.069 | K224: ='RC1_Structure_RE'!M253 -> 464329.89
A225: STR | B225: Super Structure | C225: Gr.Floor | D225: Beam | E225: {=_xlfn.LET(_xlpm.c,'RC1_Structure_RE'!C254, _xlpm.b, 'RC1_Structure_RE'!B254, IF(_xlpm.c<>"", _xlpm.c, _xlpm.b))} -> ขนาดเส้นผ่านศูนย์กลาง 16 ม.ม. SD-50 | G225: ='RC1_Structure_RE'!F254 -> กก. | H225: ='RC1_Structure_RE'!E254 -> 22957 | I225: ='RC1_Structure_RE'!I254 -> 413156.67 | J225: ='RC1_Structure_RE'!L254 -> 77265.663 | K225: ='RC1_Structure_RE'!M254 -> 490422.33
A226: STR | B226: Super Structure | C226: Gr.Floor | D226: Beam | E226: {=_xlfn.LET(_xlpm.c,'RC1_Structure_RE'!C255, _xlpm.b, 'RC1_Structure_RE'!B255, IF(_xlpm.c<>"", _xlpm.c, _xlpm.b))} -> ขนาดเส้นผ่านศูนย์กลาง 20 ม.ม. SD-50 | G226: ='RC1_Structure_RE'!F255 -> กก. | H226: ='RC1_Structure_RE'!E255 -> 1765 | I226: ='RC1_Structure_RE'!I255 -> 31764.67 | J226: ='RC1_Structure_RE'!L255 -> 5115.3494 | K226: ='RC1_Structure_RE'!M255 -> 36880.019
A227: STR | B227: Super Structure | C227: Gr.Floor | D227: Beam | E227: {=_xlfn.LET(_xlpm.c,'RC1_Structure_RE'!C256, _xlpm.b, 'RC1_Structure_RE'!B256, IF(_xlpm.c<>"", _xlpm.c, _xlpm.b))} -> ขนาดเส้นผ่านศูนย์กลาง 25 ม.ม. SD-50 | G227: ='RC1_Structure_RE'!F256 -> กก. | H227: ='RC1_Structure_RE'!E256 -> 6517 | I227: ='RC1_Structure_RE'!I256 -> 117286.32 | J227: ='RC1_Structure_RE'!L256 -> 18887.667 | K227: ='RC1_Structure_RE'!M256 -> 136173.98
A228: STR | B228: Super Structure | C228: Gr.Floor | D228: Beam | E228: {=_xlfn.LET(_xlpm.c,'RC1_Structure_RE'!C257, _xlpm.b, 'RC1_Structure_RE'!B257, IF(_xlpm.c<>"", _xlpm.c, _xlpm.b))} -> ลวดผูกเหล็ก | G228: ='RC1_Structure_RE'!F257 -> กก. | H228: ='RC1_Structure_RE'!E257 -> 951 | I228: ='RC1_Structure_RE'!I257 -> 24094.544 | J228: ='RC1_Structure_RE'!L257 -> 0 | K228: ='RC1_Structure_RE'!M257 -> 24094.544
A229: STR | B229: Super Structure | C229: Gr.Floor | D229: Beam | E229: {=_xlfn.LET(_xlpm.c,'RC1_Structure_RE'!C258, _xlpm.b, 'RC1_Structure_RE'!B258, IF(_xlpm.c<>"", _xlpm.c, _xlpm.b))} -> งานไม้แบบ | G229: ='RC1_Structure_RE'!F258 -> 0 | H229: ='RC1_Structure_RE'!E258 -> 0 | I229: ='RC1_Structure_RE'!I258 -> 0 | J229: ='RC1_Structure_RE'!L258 -> 0 | K229: ='RC1_Structure_RE'!M258 -> 0
...

Sheet แบบ ปร.6
E1: แบบ ปร.6
A2: สรุปราคาค่าก่อสร้าง
A4: ชื่อโครงการ | C4: โครงการจัดตั้งศูนย์การเรียนรู้แห่งชาติ OKMD : OKMD National Knowledge Center (Ratchadamnoen Center 1 และ 2)
A5: สถานที่ก่อสร้าง | C5: แขวงตลาดยอด เขตพระนคร กรุงเทพมหานคร
A6: เจ้าของอาคาร | C6: สำนักงานบริหารและพัฒนาองค์ความรู้ (องค์การมหาชน)
A7: หน่วยงานออกแบบแปลนและรายการ | C7: กิจการร่วมค้าบริษัท จีโอเดสิค ดีไซน์ จำกัด , บริษัท เอ็มสเปซ จำกัด และ บริษัท จั่นอาร์คิเทค จำกัด
A8: แบบ ปร.4 และ ปร. 5 ที่แนบ | C8: 348 แผ่น | F8: =136+212 -> 348
A9: คำนวนราคาโดย | C9: คณะกรรมการกำหนดราคากลาง
A10: เมื่อวันที่ | C10: 16 กรกฎาคม 2568
A12: ลำดับที่ | B12: รายการ | D12: ค่าก่อสร้าง | E12: หมายเหตุ
A14: 1 | B14: ส่วนที่ 1 ค่าวัสดุและแรงงานหมวดงานก่อสร้าง
B15: - งานอาคาร Ratchadamnoen Center 1 | D15: ='RKCA1_ปร.5 (ก)'!E31 -> 5.9269949e+08 | G15: 6.3438349e+08
B16: - งานอาคาร Ratchadamnoen Center 2 | D16: 1.0769656e+08 | G16: 1.1618515e+08
A18: 2 | B18: ส่วนที่ 2 ค่าครุภัณฑ์สั่งซื้อหรือจัดซื้อ
B19: - งานครุภัณฑ์จัดซื้ออาคาร Ratchadamnoen Center 1 | D19: ='แบบ ปร.5(ข)'!E25 -> 1.4887117e+08 | G19: 1.5923617e+08
B20: - งานครุภัณฑ์จัดซื้ออาคาร Ratchadamnoen Center 2 | D20: 33207814 | G20: 35519872
A22: 3 | B22: ส่วนที่ 3 ค่าใช้จ่ายพิเศษ
B23: -ค่าใช้จ่ายพิเศษตามข้อกำหนดและค่าใช้จ่ายอื่นที่จำเป็นต้องมี | D23: 14524968 | G23: 15536253
A26: สรุป | B26: รวมราคาค่าก่อสร้างทั้งโครงการ | D26: =SUM(D15:D25) -> 8.97e+08 | G26: =SUM(G15:G25) -> 9.6086093e+08
B27: ปัดเศษ คงเหลือ | D27: 897000000
B28: ค่าก่อสร้าง (ตัวอักษร) | C28: ="("&BAHTTEXT(D27)&")" -> (แปดร้อยเก้าสิบเจ็ดล้านบาทถ้วน)

Sheet RKCA1_ปร.5 (ก)
E1: แบบ ปร.5 (ก)
A2: แบบสรุปราคาค่าก่อสร้างงานอาคาร
A4: ชื่อโครงการ | C4: =+'แบบ ปร.6'!C4 -> โครงการจัดตั้งศูนย์การเรียนรู้แห่งชาติ OKMD : OKMD National Knowledge Center (Ratchadamnoen Center 1 และ 2)
A5: สถานที่ก่อสร้าง | C5: =+'แบบ ปร.6'!C5 -> แขวงตลาดยอด เขตพระนคร กรุงเทพมหานคร
A6: เจ้าของอาคาร | C6: =+'แบบ ปร.6'!C6 -> สำนักงานบริหารและพัฒนาองค์ความรู้ (องค์การมหาชน)
A7: หน่วยงานออกแบบแปลนและรายการ | C7: กิจการร่วมค้าบริษัท จีโอเดสิค ดีไซน์ จำกัด , บริษัท เอ็มสเปซ จำกัด และ บริษัท จั่นอาร์คิเทค จำกัด
A8: แบบ ปร.4 (ก) ที่แนบ | C8: 166 แผ่น | G8: =166+44+1+1 -> 212
A9: คำนวนราคาโดย | C9: =+'แบบ ปร.6'!C9 -> คณะกรรมการกำหนดราคากลาง
A10: เมื่อวันที่ | C10: =+'แบบ ปร.6'!C10 -> 16 กรกฎาคม 2568
A12: ลำดับที่ | B12: รายการ | C12: ค่างาน | D12: Factor F | E12: ค่าก่อสร้าง | F12: หมายเหตุ
C13: (บาท) | E13: (บาท)
B14: ส่วนที่ 1 ค่าวัสดุและแรงงานหมวดงานก่อสร้าง
B15: อาคาร Ratchadamnoen Center 1
A16: 1 | B16: งานสถาปัตยกรรม | C16: 1.1293628e+08 | D16: 1.1924 | E16: =SUM(C16*D16) -> 1.3466522e+08
A17: 2 | B17: งานสถาปัตยกรรมภายใน | C17: =RKCA1_Interior!M16 -> 29951398 | D17: =+D16 -> 1.1924 | E17: =SUM(C17*D17) -> 35714047
A18: 3 | B18: งานสถาปัตยกรรมภายใน (BUILT-IN) | C18: ='RKCA1_Built-in'!M21 -> 37557810 | D18: =+D16 -> 1.1924 | E18: =SUM(C18*D18) -> 44783933
A19: 4 | B19: งานวิศวกรรมโครงสร้าง | C19: 1.706938e+08 | D19: =+D16 -> 1.1924 | E19: =SUM(C19*D19) -> 2.0353529e+08
A20: 5 | B20: งานระบบไฟฟ้าและสื่อสาร | C20: =+RKCA1_Ele!M34 -> 96770786 | D20: =+D16 -> 1.1924 | E20: =SUM(C20*D20) -> 1.1538949e+08
A21: 6 | B21: งานระบบสุขาภิบาลและดับเพลิง | C21: ='RC1_San+FP'!M16 -> 23315775 | D21: =+D16 -> 1.1924 | E21: =SUM(C21*D21) -> 27801731
A22: 7 | B22: งานระบบปรับอากาศและระบายอากาศ | C22: 18486639 | D22: =+D16 -> 1.1924 | E22: =SUM(C22*D22) -> 22043469
A23: 8 | B23: งานภูมิสถาปัตยกรรม | C23: =HARDSCAPE!M16 -> 7351821.5 | D23: =+D16 -> 1.1924 | E23: =SUM(C23*D23) -> 8766312
B26: เงื่อนไข
B27: เงินล่วงหน้าจ่าย 0%
B28: เงินประกันผลงานหัก 10%
B29: ดอกเบี้ยเงินกู้ 7%
B30: ค่าภาษีมูลค่าเพิ่ม 7%
A31: สรุป | B31: รวมค่าก่อสร้างเป็นเงินทั้งสิ้น | E31: =SUM(E14:E30) -> 5.9269949e+08 | G31: 6.3396554e+08 | H31: =G31*0.934908047 -> 5.9269949e+08
B32: ="("&BAHTTEXT(E31)&")" -> (ห้าร้อยเก้าสิบสองล้านหกแสนเก้าหมื่นเก้าพันสี่ร้อยแปดสิบแปดบาทสิบสตางค์)
B33: พื้นที่อาคาร | C33: 16450 | D33: ตารางเมตร
B34: เฉลี่ยราคาประมาณ | C34: =+E31/C33 -> 36030.364 | D34: บาท/ตารางเมตร
C35: =+C34+'แบบ ปร.5(ข)'!C28 -> 45080.283

Sheet RC1_Arch
A1: ชื่อโครงการ | D1: =+'RKCA1_ปร.5 (ก)'!C4 -> โครงการจัดตั้งศูนย์การเรียนรู้แห่งชาติ OKMD : OKMD National Knowledge Center (Ratchadamnoen Center 1 และ 2) | J1: หมวดงาน | K1: หมวดงาน | L1: งานสถาปัตยกรรม (RC 1)
A2: สถานที่ก่อสร้าง | D2: =+'RKCA1_ปร.5 (ก)'!C5 -> แขวงตลาดยอด เขตพระนคร กรุงเทพมหานคร | J2: เมื่อวันที่ | K2: เมื่อวันที่ | L2: =+'RKCA1_ปร.5 (ก)'!C10 -> 16 กรกฎาคม 2568
A3: คำนวณราคากลางโดย | D3: =+'RKCA1_ปร.5 (ก)'!C9 -> คณะกรรมการกำหนดราคากลาง
A5: ลำดับ | B5: รายการ | E5: จำนวน | F5: หน่วย | G5: ราคาวัสดุสิ่งของ | J5: ค่าแรงงาน | M5: รวมค่าวัสดุ | N5: หมายเหตุ
G6: ราคา/หน่วย | H6: ราคา/หน่วย | I6: จำนวนเงิน | J6: ราคา/หน่วย | K6: ราคา/หน่วย | L6: จำนวนเงิน | M6: และแรงงาน
B7: สรุปราคาค่าก่อสร้างงานสถาปัตยกรรม
B8: อาคาร Ratchadamnoen Center 1
A9: 1 | B9: งานผิวพื้น | M9: =M75 -> 5837065.7 | O9: =P9*0.934908047 -> 5837065.7 | P9: 6243465
A10: 2 | B10: งานผนัง | M10: =M142 -> 17861361 | O10: =P10*0.934908047 -> 17861361 | P10: 19104939
A11: 3 | B11: งานฝ้าเพดาน | M11: =M202 -> 11773458 | O11: =P11*0.934908047 -> 11773458 | P11: 12593172
A12: 4 | B12: งานประตูและอุปกรณ์ | M12: =M309 -> 6357286.8 | O12: =P12*0.934908047 -> 6357286.8 | P12: 6799906
A13: 5 | B13: งานหน้าต่าง | M13: =M410 -> 32524967 | O13: =P13*0.934908047 -> 32524967 | P13: 34789482
A14: 6 | B14: งานห้องน้ำและสุขภัณฑ์ | M14: =M441 -> 3401585.8 | O14: =P14*0.934908047 -> 3401585.8 | P14: 3638417.5
A15: 7 | B15: งานบันได ราวบันได ราวกันตก และส่วนประกอบ | M15: =M577 -> 6553576.9 | O15: =P15*0.934908047 -> 6553576.9 | P15: 7009862.6
A16: 8 | B16: งานหลังคา งานฉนวนกันความร้อน งานกันซึมและส่วนประกอบ | M16: =M638 -> 11333993 | O16: =P16*0.934908047 -> 11333993 | P16: 12123110
A17: 9 | B17: งาน Facade และ Urban Void | M17: =M678 -> 16799204 | O17: =P17*0.934908047 -> 16799204 | P17: 17968830
A18: 10 | B18: งานเบ็ดเตล็ด | M18: =M702 -> 493784.21 | O18: =P18*0.934908047 -> 493784.21 | P18: 528163.4
B20: รวมราคาค่าก่อสร้างงานสถาปัตยกรรม | M20: =SUM(M9:M19) -> 1.1293628e+08 | O20: =SUM(O9:O19) -> 1.1293628e+08 | P20: =SUM(P9:P19) -> 1.2079935e+08
B26: Allow for any items not described above but deemed necessary
B27: to complete the works :-
A31: 1 | B31: งานผิวพื้น
A33: 1.1 | B33: F0 | C33: พื้น ค.ส.ล. พร้อมปูนทรายปรับระดับ ปรับผิวเรียบ (ดูรายละเอียดงานตกแต่งภายใน) | E33: 4755 | F33: ตร.ม. | G33: 80 | H33: =G33*O33 -> 74.792644 | I33: =H33*E33 -> 355639.02 | J33: 0 | L33: =J33*E33 -> 0 | M33: =SUM(I33,L33) -> 355639.02 | O33: 0.93490805
A34: 1.2 | B34: F1.1 | C34: พื้น ค.ส.ล. พร้อมปูนทรายปรับระดับ ผิวขัดมัน หนา 30-50 มม.ตีเส้นแบ่งแนวตามแบบ | E34: 465 | F34: ตร.ม. | G34: 96 | H34: =G34*O34 -> 89.751173 | I34: =H34*E34 -> 41734.295 | J34: 87 | K34: =J34*O34 -> 81.337 | L34: =K34*E34 -> 37821.705 | M34: =SUM(I34,L34) -> 79556 | O34: 0.93490805 | P34: ราคามีแก้ไขตามกระทรวงพาณิชย์ กทม. ธ.ค. 67
C35: ตามระบุในรายการประกอบแบบ | O35: 0.93490805
A36: 1.3 | B36: F1.2 | C36: พื้น ค.ส.ล. พร้อมปูนทรายปรับระดับ ผิวขัดเรียบ หนา 30-50 มม. | E36: ยกเลิกรายการ | O36: 0.93490805
A37: 1.4 | B37: F1.3 | C37: พื้น ค.ส.ล. พร้อมปูนทรายปรับระดับ ผสมน้ำยากันซึม ผิวขัดมัน หนา 30-50 มม. | E37: ยกเลิกรายการ | O37: 0.93490805
A38: 1.5 | B38: F1.4 | C38: พื้น ค.ส.ล. ผิวโครงสร้างแต่งเรียบทำระบบกันซึม (งานกันซึมดูรายละเอียดงานกันซึม) | E38: 1595 | F38: ตร.ม. | G38: 80 | H38: =G38*O38 -> 74.792644 | I38: =H38*E38 -> 119294.27 | J38: 80 | K38: =J38*O38 -> 74.792644 | L38: =K38*E38 -> 119294.27 | M38: =SUM(I38,L38) -> 238588.53 | O38: 0.93490805
A39: 1.6 | B39: F1.5 | C39: พื้น ค.ส.ล. ทำผิว Floor Hardener สีมาตรฐาน ผิวด้าน | E39: 2447 | F39: ตร.ม. | G39: 100 | H39: =G39*O39 -> 93.490805 | I39: =H39*E39 -> 228772 | J39: 60 | K39: =J39*O39 -> 56.094483 | L39: =K39*E39 -> 137263.2 | M39: =SUM(I39,L39) -> 366035.2 | O39: 0.93490805
A40: 1.7 | B40: F2.1 | C40: พื้น ค.ส.ล. พร้อมปูนทรายปรับระดับ ผิวขัดมันหนา 30-50 มม. ทาสี Epoxy Coating | E40: 597 | F40: ตร.ม. | G40: 350 | H40: =G40*O40 -> 327.21782 | I40: =H40*E40 -> 195349.04 | J40: 150 | K40: =J40*O40 -> 140.23621 | L40: =K40*E40 -> 83721.016 | M40: =SUM(I40,L40) -> 279070.05 | O40: 0.93490805
C41: ความหนา 500 ไมครอน (ระบุสีภายหลัง) | O41: 0.93490805
A42: 1.8 | B42: F2.2 | C42: พื้น ค.ส.ล. พร้อมปูนทรายปรับระดับ ผิวขัดมันหนา 30-50 มม. | E42: 210 | F42: ตร.ม. | G42: 650 | H42: =G42*O42 -> 607.69023 | I42: =H42*E42 -> 127614.95 | J42: 140 | K42: =J42*O42 -> 130.88713 | L42: =K42*E42 -> 27486.297 | M42: =SUM(I42,L42) -> 155101.24 | O42: 0.93490805
C43: ทำผิว Epoxy Self Leveling หนา 2 มม. ( ผิวและสีระบุภายหลัง ) | O43: 0.93490805
A44: 1.9 | B44: F3.1 | C44: พื้น ค.ส.ล. พร้อมปูนทรายปรับระดับ ทำผิวหินขัด (Cement Base) ชนิดคัดเม็ดหิน | E44: 3800 | F44: ตร.ม. | G44: 388 | H44: =G44*O44 -> 362.74432 | I44: =H44*E44 -> 1378428.4 | J44: 161 | K44: =J44*O44 -> 150.5202 | L44: =K44*E44 -> 571976.74 | M44: =SUM(I44,L44) -> 1950405.2 | O44: 0.93490805
C45: สีขาว-เทา เบอร์ 4½ หรือขนาดอื่นๆตามแบบระบุภายหลัง พร้อมลงน้ำยาเคลือบผิว | O45: 0.93490805
A46: 1.1 | B46: F3.2 | C46: พื้น ค.ส.ล. พร้อมปูนทรายปรับระดับ ทำผิวหินขัด (Cement Base) ชนิดคัดเม็ดหิน | E46: 1165 | F46: ตร.ม. | G46: 388 | H46: =G46*O46 -> 362.74432 | I46: =H46*E46 -> 422597.14 | J46: 161 | K46: =J46*O46 -> 150.5202 | L46: =K46*E46 -> 175356.03 | M46: =SUM(I46,L46) -> 597953.16 | O46: 0.93490805
C47: สีดำ เบอร์ 4½ หรือขนาดอื่นๆตามแบบระบุภายหลัง พร้อมลงน้ำยาเคลือบผิว | O47: 0.93490805
A48: 1.11 | B48: F3.3 | C48: พื้น ค.ส.ล. พร้อมปูนทรายปรับระดับ ผิวหินขัดสำเร็จรูป เม็ดหินขาว – มุก | E48: 115 | F48: ตร.ม. | G48: 469 | H48: =G48*O48 -> 438.47187 | I48: =H48*E48 -> 50424.266 | J48: 222 | K48: =J48*O48 -> 207.54959 | L48: =K48*E48 -> 23868.202 | M48: =SUM(I48,L48) -> 74292.468 | O48: 0.93490805 | P48: ราคามีแก้ไขตามกระทรวงพาณิชย์ กทม. ธ.ค. 67
C49: เบอร์ 4½ ระบุขนาดและลายภายหลัง พร้อมลงน้ำยาเคลือบ | O49: 0.93490805
A50: 1.12 | B50: F3.4 | C50: พื้น ค.ส.ล. พร้อมปูนทรายปรับระดับ ผิวหินขัดสำเร็จรูปขนาด 600x600 มม. | E50: 555 | F50: ตร.ม. | G50: 469 | H50: =G50*O50 -> 438.47187 | I50: =H50*E50 -> 243351.89 | J50: 222 | K50: =J50*O50 -> 207.54959 | L50: =K50*E50 -> 115190.02 | M50: =SUM(I50,L50) -> 358541.91 | O50: 0.93490805 | P50: ราคามีแก้ไขตามกระทรวงพาณิชย์ กทม. ธ.ค. 67
C51: หรือขนาดตามแบบระบุ เม็ดหินสีดำ ระบุขนาดและลายภายหลัง พร้อมลงน้ำยาเคลือบผิว | O51: 0.93490805
...

Sheet RKCA1_Interior
A1: ชื่อโครงการ | D1: =+'RKCA1_ปร.5 (ก)'!C4 -> โครงการจัดตั้งศูนย์การเรียนรู้แห่งชาติ OKMD : OKMD National Knowledge Center (Ratchadamnoen Center 1 และ 2) | J1: หมวดงาน | K1: หมวดงาน | L1: งานสถาปัตยกรรมภายใน (RC 1)
A2: สถานที่ก่อสร้าง | D2: =+'RKCA1_ปร.5 (ก)'!C5 -> แขวงตลาดยอด เขตพระนคร กรุงเทพมหานคร | J2: เมื่อวันที่ | K2: เมื่อวันที่ | L2: =+'RKCA1_ปร.5 (ก)'!C10 -> 16 กรกฎาคม 2568
A3: คำนวณราคากลางโดย | D3: =+'RKCA1_ปร.5 (ก)'!C9 -> คณะกรรมการกำหนดราคากลาง
A5: ลำดับ | B5: รายการ | E5: จำนวน | F5: หน่วย | G5: ราคาวัสดุสิ่งของ | J5: ค่าแรงงาน | M5: รวมค่าวัสดุ | N5: หมายเหตุ
G6: ราคา/หน่วย | H6: ราคา/หน่วย | I6: จำนวนเงิน | J6: ราคา/หน่วย | K6: ราคา/หน่วย | L6: จำนวนเงิน | M6: และแรงงาน
B7: สรุปราคาค่าก่อสร้างงานสถาปัตยกรรมภายใน
B8: อาคาร Ratchadamnoen Center 1
A10: 1 | B10: งานผิวพื้น | E10: 5338 | F10: ตร.ม. | I10: =I53 -> 7220159.3 | L10: =L53 -> 1794574.7 | M10: =M53 -> 9014734 | O10: =P10*0.934908047 -> 9014734 | P10: 9642375
A11: 2 | B11: งานผนัง | E11: 501.55055 | F11: ตร.ม. | I11: =I63 -> 590057.86 | L11: =L63 -> 157840.53 | M11: =M63 -> 747898.39 | O11: =P11*0.934908047 -> 747898.39 | P11: 799970
A12: 3 | B12: งานฝ้าตกแต่ง | E12: 4207 | F12: ตร.ม. | I12: =I98 -> 3361350.6 | L12: =L98 -> 1061329.1 | M12: =M98 -> 4422679.7 | O12: =P12*0.934908047 -> 4422679.7 | P12: 4730604
A13: 4 | B13: งานประตูพิเศษ | E13: 66 | F13: ชุด | I13: =I162 -> 13428305 | L13: =L162 -> 1582524.5 | M13: =M162 -> 15010829 | O13: =P13*0.934908047 -> 15010829 | P13: 16055942
A14: 5 | B14: งานเบ็ดเตล็ด | I14: =I183 -> 755256.12 | L14: =L183 -> 0 | M14: =M183 -> 755256.12 | O14: =P14*0.934908047 -> 755256.12 | P14: 807840
B16: รวมราคาค่าก่อสร้างงานสถาปัตยกรรมภายใน | E16: 10112.551 | F16: ตร.ม. | I16: =SUM(I10:I14) -> 25355129 | L16: =SUM(L10:L14) -> 4596268.8 | M16: =SUM(M10:M14) -> 29951398 | O16: =SUM(O10:O15) -> 29951398 | P16: =SUM(P10:P15) -> 32036731
A31: 1 | B31: งานผิวพื้น
B32: IN-F1.1 | C32: พื้นคอนกรีตปรับระดับ ขัดพื้นคอนกรีตด้วยเครื่องขัดรอบความเร็วสูง | E32: 699 | F32: ตร.ม. | G32: 450 | H32: =G32*O32 -> 420.70862 | I32: =E32*H32 -> 294075.33 | J32: 153 | K32: =J32*O32 -> 143.04093 | L32: =E32*K32 -> 99985.611 | M32: =I32+L32 -> 394060.94 | O32: 0.93490805
B33: IN-F1.2 | C33: พื้น ค.ส.ล. พร้อมปูนทรายปรับระดับ ผิวขัดเรียบ หนา 30-50 มม. | E33: 6 | F33: ตร.ม. | G33: 96 | H33: =G33*O33 -> 89.751173 | I33: =E33*H33 -> 538.50704 | J33: 40 | K33: =J33*O33 -> 37.396322 | L33: =E33*K33 -> 224.37793 | M33: =I33+L33 -> 762.88497 | O33: 0.93490805 | P33: ราคามีแก้ไขตามกระทรวงพาณิชย์ กทม. ธ.ค. 67
B34: IN-F3.1 | C34: พื้นคอนกรีตทำผิวหินขัด สีเทา | E34: 113 | F34: ตร.ม. | G34: 238 | H34: =G34*O34 -> 222.50812 | I34: =E34*H34 -> 25143.417 | J34: 161 | K34: =J34*O34 -> 150.5202 | L34: =E34*K34 -> 17008.782 | M34: =I34+L34 -> 42152.199 | O34: 0.93490805
B35: IN-F3.2 | C35: พื้นคอนกรีตทำผิวหินขัด สีเทา | E35: *รวมในงานสถาปัตย์ | O35: 0.93490805
B36: IN-F3.3 | C36: พื้นคอนกรีตทำผิวหินขัด สีเทา | E36: *รวมในงานสถาปัตย์ | O36: 0.93490805
B37: IN-F3.4 | C37: พื้นคอนกรีตทำผิวหินขัด สีเทา | E37: 120 | F37: ตร.ม. | G37: 238 | H37: =G37*O37 -> 222.50812 | I37: =E37*H37 -> 26700.974 | J37: 161 | K37: =J37*O37 -> 150.5202 | L37: =E37*K37 -> 18062.423 | M37: =I37+L37 -> 44763.397 | O37: 0.93490805
B38: IN-F4.1 | C38: พื้นไม้เอ็นจิเนียร์ OAK ขนาด 1"x6" X60 cm ปูบนไม้อัด 20 mm. | E38: 511 | F38: ตร.ม. | G38: 2000 | H38: =G38*O38 -> 1869.8161 | I38: =E38*H38 -> 955476.02 | J38: 600 | K38: =J38*O38 -> 560.94483 | L38: =E38*K38 -> 286642.81 | M38: =I38+L38 -> 1242118.8 | O38: 0.93490805
B39: IN-F5.1 | C39: พื้นปูไม้Compound Maple ขนาด 1"x6" X60 cm ปูบน Fiber Cement 20 mm. | E39: 158 | F39: ตร.ม. | G39: 2250 | H39: =G39*O39 -> 2103.5431 | I39: =E39*H39 -> 332359.81 | J39: 600 | K39: =J39*O39 -> 560.94483 | L39: =E39*K39 -> 88629.283 | M39: =I39+L39 -> 420989.09 | O39: 0.93490805
B40: IN-F5.2 | C40: พื้นปูไม้Compound OAK ขนาด 1"x6" X60 cm ปูบน Fiber Cement 20 mm. | E40: 430 | F40: ตร.ม. | G40: 2500 | H40: =G40*O40 -> 2337.2701 | I40: =E40*H40 -> 1005026.2 | J40: 600 | K40: =J40*O40 -> 560.94483 | L40: =E40*K40 -> 241206.28 | M40: =I40+L40 -> 1246232.4 | O40: 0.93490805
B41: IN-F5.3 | C41: พื้นไม้เอ็นจิเนียร์ OAK ขนาด 1"x6" X60 cm ปูบน Fiber Cement 20 mm. | E41: 430 | F41: ตร.ม. | G41: 2000 | H41: =G41*O41 -> 1869.8161 | I41: =E41*H41 -> 804020.92 | J41: 600 | K41: =J41*O41 -> 560.94483 | L41: =E41*K41 -> 241206.28 | M41: =I41+L41 -> 1045227.2 | O41: 0.93490805
B42: IN-F5.4 | C42: พื้นไม้เอ็นจิเนียร์ OAK ขนาด 1"x6" X60 cm | E42: 105 | F42: ตร.ม. | G42: 2000 | H42: =G42*O42 -> 1869.8161 | I42: =E42*H42 -> 196330.69 | J42: 600 | K42: =J42*O42 -> 560.94483 | L42: =E42*K42 -> 58899.207 | M42: =I42+L42 -> 255229.9 | O42: 0.93490805
B43: IN-F5.5 | C43: พื้นไม้เอ็นจิเนียร์ OAK ขนาด 1"x6" X60 cm | E43: 113 | F43: ตร.ม. | G43: 2000 | H43: =G43*O43 -> 1869.8161 | I43: =E43*H43 -> 211289.22 | J43: 600 | K43: =J43*O43 -> 560.94483 | L43: =E43*K43 -> 63386.766 | M43: =I43+L43 -> 274675.98 | O43: 0.93490805
B44: IN-F5.6 | C44: พื้นไม้เอ็นจิเนียร์ OAK ขนาด 1"x6" X60 cm ปูบน Fiber Cement 20 mm. | E44: 95 | F44: ตร.ม. | G44: 2000 | H44: =G44*O44 -> 1869.8161 | I44: =E44*H44 -> 177632.53 | J44: 600 | K44: =J44*O44 -> 560.94483 | L44: =E44*K44 -> 53289.759 | M44: =I44+L44 -> 230922.29 | O44: 0.93490805
B45: IN-F8.1 | C45: พื้นคอนกรีตปรับระดับ ปูกระเบื้องยาง SPC ลายไม้ความหนาไม่น้อยกว่า 4 mm | E45: 31 | F45: ตร.ม. | G45: 695 | H45: =G45*O45 -> 649.76109 | I45: =E45*H45 -> 20142.594 | J45: 225 | K45: =J45*O45 -> 210.35431 | L45: =E45*K45 -> 6520.9836 | M45: =I45+L45 -> 26663.578 | O45: 0.93490805
B46: IN-F8.2 | C46: ACCESS FLOOR SYSTEM ขนาด600x600x35mm. และกรุด้วยกระเบื้องยาง | E46: 19 | F46: ตร.ม. | G46: 2200 | H46: =G46*O46 -> 2056.7977 | I46: =E46*H46 -> 39079.156 | J46: 350 | K46: =J46*O46 -> 327.21782 | L46: =E46*K46 -> 6217.1385 | M46: =I46+L46 -> 45296.295 | O46: 0.93490805
B47: IN-F8.3 | C47: กระเบื้องยางไวนิล Acoustic แบบม้วน ชนิด Heterogeneous ความหนาไม่น้อยกว่า 3.4 mm | E47: 171 | F47: ตร.ม. | G47: 1210 | H47: =G47*O47 -> 1131.2387 | I47: =E47*H47 -> 193441.82 | J47: 295 | K47: =J47*O47 -> 275.79787 | L47: =E47*K47 -> 47161.436 | M47: =I47+L47 -> 240603.26 | O47: 0.93490805
B48: IN-F9.1 | C48: พื้นคอนกรีต ปรับระดับ ปูพรม Acoustic Carpet Tile แบบแผ่น ขนาด 0.25 x 1.00 m.ความหนาไม่น้อยกว่า 8 mm | E48: 529 | F48: ตร.ม. | G48: 600 | H48: =G48*O48 -> 560.94483 | I48: =E48*H48 -> 296739.81 | J48: 225 | K48: =J48*O48 -> 210.35431 | L48: =E48*K48 -> 111277.43 | M48: =I48+L48 -> 408017.24 | O48: 0.93490805
... B51: IN-F10.1 | C51: พื้นผิวนิรภัยสำหรับสนามเด็กเล่น (PLAYGROUND PROTECTIVE SURFACING) EPDM ความหนาไม่น้อยกว่า 10 mm | E51: 50 | F51: ตร.ม. | G51: 2610 | H51: =G51*O51 -> 2440.11 | I51: =E51*H51 -> 122005.5 | J51: 2630.5 | K51: =J51*O51 -> 2459.2756 | L51: =E51*K51 -> 122963.78 | M51: =I51+L51 -> 244969.28 | O51: 0.93490805
O52: 0.93490805
B53: รวมราคาหมวดงานผิวพื้น | E53: 5338 | F53: ตร.ม. | I53: =SUM(I32:I52) -> 7220159.3 | L53: =SUM(L32:L52) -> 1794574.7 | M53: =SUM(M32:M52) -> 9014734 | O53: 0.93490805
O54: 0.93490805
O55: 0.93490805
O56: 0.93490805
A57: 2 | B57: งานผนัง | O57: 0.93490805
B58: IN.W01 | C58: ระบบผนังเบากันเสียง STC เทียบเท่า 62 | E58: 296 | F58: ตร.ม. | G58: 660 | H58: =G58*O58 -> 617.03931 | I58: =E58*H58 -> 182643.64 | J58: 200 | K58: =J58*O58 -> 186.98161 | L58: =E58*K58 -> 55346.556 | M58: =I58+L58 -> 237990.19 | O58: 0.93490805
B59: IN.W02 | C59: ระบบผนังเบากันเสียง STC เทียบเท่า 66 | E59: 205 | F59: ตร.ม. | G59: 1290 | H59: =G59*O59 -> 1206.0314 | I59: =E59*H59 -> 247236.43 | J59: 200 | K59: =J59*O59 -> 186.98161 | L59: =E59*K59 -> 38331.23 | M59: =I59+L59 -> 285567.66 | O59: 0.93490805
...

Sheet RKCA1_Built-in
A1: ชื่อโครงการ | D1: =+'RKCA1_ปร.5 (ก)'!C4 -> โครงการจัดตั้งศูนย์การเรียนรู้แห่งชาติ OKMD : OKMD National Knowledge Center (Ratchadamnoen Center 1 และ 2) | J1: หมวดงาน | K1: หมวดงาน | L1: งานสถาปัตยกรรมภายใน Built In (RC 1)
A2: สถานที่ก่อสร้าง | D2: =+'RKCA1_ปร.5 (ก)'!C5 -> แขวงตลาดยอด เขตพระนคร กรุงเทพมหานคร | J2: เมื่อวันที่ | K2: เมื่อวันที่ | L2: =+'RKCA1_ปร.5 (ก)'!C10 -> 16 กรกฎาคม 2568
A3: คำนวณราคากลางโดย | D3: =+'RKCA1_ปร.5 (ก)'!C9 -> คณะกรรมการกำหนดราคากลาง
A5: ลำดับ | B5: รายการ | E5: จำนวน | F5: หน่วย | G5: ราคาวัสดุสิ่งของ | J5: ค่าแรงงาน | M5: รวมค่าวัสดุ | N5: หมายเหตุ
G6: ราคา/หน่วย | H6: ราคา/หน่วย | I6: จำนวนเงิน | J6: ราคา/หน่วย | K6: ราคา/หน่วย | L6: จำนวนเงิน | M6: และแรงงาน
B7: สรุปราคาค่าก่อสร้างงานสถาปัตยกรรมภายใน Built In
B8: อาคาร Ratchadamnoen Center 1
A9: 1 | B9: ZONE 0.A | I9: =I89 -> 3587168.2 | L9: =L89 -> 0 | M9: =M89 -> 3587168.2 | O9: =P9*0.934908047 -> 3587168.2 | P9: 3836920.9
A10: 2 | B10: ZONE 0.B | I10: =I170 -> 1886150.8 | L10: =L170 -> 251719.32 | M10: =M170 -> 2137870.1 | O10: =P10*0.934908047 -> 2137870.1 | P10: 2286717
A11: 3 | B11: ZONE 0.C | I11: =I221 -> 1751818.8 | L11: =L221 -> 69940.354 | M11: =M221 -> 1821759.2 | O11: =P11*0.934908047 -> 1821759.2 | P11: 1948597.1
A12: 4 | B12: ZONE 1.A | I12: =I322 -> 7390602.4 | L12: =L322 -> 0 | M12: =M322 -> 7496536.8 | O12: =P12*0.934908047 -> 7496536.8 | P12: 8018475
A13: 5 | B13: ZONE 1.B | I13: =I374 -> 3418150 | L13: =L374 -> 414608.35 | M13: =M374 -> 3832758.4 | O13: =P13*0.934908047 -> 3832758.4 | P13: 4099610
A14: 6 | B14: ZONE 2.A | I14: =I406 -> 2040904.3 | L14: =L406 -> 89423.955 | M14: =M406 -> 2130328.2 | O14: =P14*0.934908047 -> 2130328.2 | P14: 2278650
A15: 7 | B15: ZONE 2.B | I15: =I414 -> 338207.66 | L15: =L414 -> 5132.6452 | M15: =M414 -> 343340.31 | O15: =P15*0.934908047 -> 343340.31 | P15: 367245
A16: 8 | B16: ZONE 3.A | I16: =I487 -> 11997682 | L16: =L487 -> 76653.111 | M16: =M487 -> 12074335 | O16: =P16*0.934908047 -> 12074335 | P16: 12914997
A17: 9 | B17: ZONE 3.B | I17: =I570 -> 2224810 | L17: =L570 -> 60862.514 | M17: =M570 -> 2285672.5 | O17: =P17*0.934908047 -> 2285672.5 | P17: 2444810
A18: 10 | B18: ZONE 3.C | I18: =I660 -> 1465424.4 | L18: =L660 -> 80818.126 | M18: =M660 -> 1546242.5 | O18: =P18*0.934908047 -> 1546242.5 | P18: 1653898
A19: 11 | B19: ZONE 4.A | I19: =I685 -> 300771.14 | L19: =L685 -> 1028.3989 | M19: =M685 -> 301799.54 | O19: =P19*0.934908047 -> 301799.54 | P19: 322812
B21: รวมราคาค่าก่อสร้างงานสถาปัตยกรรมภายใน Built In | I21: =SUM(I9:I19) -> 36401689 | L21: =SUM(L9:L19) -> 1050186.8 | M21: =SUM(M9:M19) -> 37557810 | O21: =SUM(O9:O20) -> 37557810 | P21: =SUM(P9:P20) -> 40172732
A31: 1 | B31: ZONE 0.A
B32: B16 | C32: COOKING STUDIO
B33: 0.A-BF01 | C33: ตู้ ขนาด 0.60x8.80x3.85 ม.(กxยxส) | E33: 1 | F33: ชุด | G33: (เมตรละ 46,560 บ) | H33: (เมตรละ 46,560 บ)
B34: ชั้นพับ | C34: SS-04 | D34: STAINLESS04-HAIRLINE | E34: 8 | F34: ตร.ม. | G34: 3330 | H34: =G34*O34 -> 3113.2438 | I34: =E34*H34 -> 24905.95 | L34: =E34*J34 -> 0 | M34: =I34+L34 -> 24905.95 | O34: 0.93490805
B35: หน้าบาน | C35: SS-04 | D35: STAINLESS04-HAIRLINE | E35: 30 | F35: ตร.ม. | G35: 3330 | H35: =G35*O35 -> 3113.2438 | I35: =E35*H35 -> 93397.314 | L35: =E35*J35 -> 0 | M35: =I35+L35 -> 93397.314 | O35: 0.93490805
B36: ชั้นว่างของปรับระดับ | C36: LM06B | E36: 8.6 | F36: ม. | G36: 32000 | H36: =G36*O36 -> 29917.058 | I36: =E36*H36 -> 257286.69 | L36: =E36*J36 -> 0 | M36: =I36+L36 -> 257286.69 | O36: 0.93490805
B37: ขาแขวนทีวี (ในห้อง) ขาแขวนทีวีประเภทปรับมุมมองได้ทุกทิศทาง | E37: 1 | F37: ชุด | G37: 7990 | H37: =G37*O37 -> 7469.9153 | I37: =E37*H37 -> 7469.9153 | M37: =I37+L37 -> 7469.9153 | O37: 0.93490805
B38: 0.A-BF02 | C38: ตู้ ขนาด 0.60x8.80x3.85 ม.(กxยxส) | E38: 1 | F38: ชุด | G38: (เมตรละ 40,399 บ) | H38: (เมตรละ 40,399 บ) | O38: 0.93490805
B39: หน้าบาน | C39: SS-04A | D39: STAINLESS04 | E39: 23 | F39: ตร.ม. | G39: 3330 | H39: =G39*O39 -> 3113.2438 | I39: =E39*H39 -> 71604.607 | J39: 0 | L39: =E39*J39 -> 0 | M39: =I39+L39 -> 71604.607 | O39: 0.93490805
B40: ฝ้าเหนือเคาน์เตอร์ | C40: SS-04 | D40: STAINLESS04 | E40: 4 | F40: ตร.ม. | G40: 3330 | H40: =G40*O40 -> 3113.2438 | I40: =E40*H40 -> 12452.975 | J40: 0 | L40: =E40*J40 -> 0 | M40: =I40+L40 -> 12452.975 | O40: 0.93490805
B41: โครงตู้ | C41: HMR01 | D41: HMR+สีพ่น | E41: 8.3 | F41: ม. | G41: 32000 | H41: =G41*O41 -> 29917.058 | I41: =E41*H41 -> 248311.58 | L41: =E41*J41 -> 0 | M41: =I41+L41 -> 248311.58 | O41: 0.93490805
B42: 0.A-BF03 | C42: ตู้ ขนาด 0.60x6.60x3.85 ม.(กxยxส) | E42: 1 | F42: ชุด | G42: (เมตรละ 49,550 บ) | H42: (เมตรละ 49,550 บ) | O42: 0.93490805
B43: หน้าบาน | C43: SS01 | D43: STAINLESS01-Silver Hairline | E43: 5 | F43: ตร.ม. | G43: 3330 | H43: =G43*O43 -> 3113.2438 | I43: =E43*H43 -> 15566.219 | J43: 0 | L43: =E43*J43 -> 0 | M43: =I43+L43 -> 15566.219 | O43: 0.93490805
B44: หน้าบาน | C44: WV02A | D44: VENEER02A | E44: 0 | F44: ม. | H44: =G44*O44 -> 0 | I44: =E44*H44 -> 0 | M44: =I44+L44 -> 0 | O44: 0.93490805
B45: ชั้นตู้ | C45: WV02A | D45: VENEER02A | E45: 6.5 | F45: ตร.ม. | G45: 32000 | H45: =G45*O45 -> 29917.058 | I45: =E45*H45 -> 194460.87 | M45: =I45+L45 -> 194460.87 | O45: 0.93490805
B46: เคาน์เตอร์+ผนัง | C46: ST-03 | D46: STONE03-Calacatta | E46: 7 | F46: ตร.ม. | G46: 9700 | H46: =G46*O46 -> 9068.6081 | I46: =E46*H46 -> 63480.256 | J46: 0 | L46: =E46*J46 -> 0 | M46: =I46+L46 -> 63480.256 | O46: 0.93490805
B47: อ่างล้างจาน | C47: อ่างล้างจานสแตนเลสชนิดติดตั้งใต้เคาน์เตอร์ท็อป 1 หลุม | E47: 3 | F47: ชุด | G47: 11495 | H47: =G47*O47 -> 10746.768 | I47: =E47*H47 -> 32240.304 | L47: =E47*J47 -> 0 | M47: =I47+L47 -> 32240.304 | O47: 0.93490805
O48: 0.93490805
B49: เครื่องดูดควัน | C49: กำลังลมในการดูด 1200 ลบ.ม./ชม. | E49: 2 | F49: ชุด | G49: 32000 | H49: =G49*O49 -> 29917.058 | I49: =E49*H49 -> 59834.115 | L49: =E49*J49 -> 0 | M49: =I49+L49 -> 59834.115 | O49: 0.93490805
B50: เตาไฟฟ้า | C50: เตาระบบ induction 4 หัวตา ขนาด 60 ซม. | E50: 2 | F50: ชุด | G50: 13900 | H50: =G50*O50 -> 12995.222 | I50: =E50*H50 -> 25990.444 | L50: =E50*J50 -> 0 | M50: =I50+L50 -> 25990.444 | O50: 0.93490805
B51: เตาอบ | C51: เตาอบมัลติฟังก์ชั่น เทอร์โบ 60 ซม. ความจุ: 71/70 ลิตร | E51: 2 | F51: ชุด | G51: 59900 | H51: =G51*O51 -> 56000.992 | I51: =E51*H51 -> 112001.98 | L51: =E51*J51 -> 0 | M51: =I51+L51 -> 112001.98 | O51: 0.93490805
...

Sheet RC1_Structure_RE
A1: ชื่อโครงการ | D1: =+'RKCA1_ปร.5 (ก)'!C4 -> โครงการจัดตั้งศูนย์การเรียนรู้แห่งชาติ OKMD : OKMD National Knowledge Center (Ratchadamnoen Center 1 และ 2) | J1: หมวดงาน | K1: หมวดงาน | L1: งานวิศวกรรมโครงสร้าง (RKCA 1)
A2: สถานที่ก่อสร้าง | D2: =+'RKCA1_ปร.5 (ก)'!C5 -> แขวงตลาดยอด เขตพระนคร กรุงเทพมหานคร | J2: เมื่อวันที่ | K2: เมื่อวันที่ | L2: =+'RKCA1_ปร.5 (ก)'!C10 -> 16 กรกฎาคม 2568
A3: คำนวณราคากลางโดย | D3: =+'RKCA1_ปร.5 (ก)'!C9 -> คณะกรรมการกำหนดราคากลาง
A5: ลำดับ | B5: รายการ | E5: จำนวน | F5: หน่วย | G5: ราคาวัสดุสิ่งของ | J5: ค่าแรงงาน | M5: รวมค่าวัสดุ | N5: หมายเหตุ
G6: ราคา/หน่วย | H6: ราคา/หน่วย | I6: จำนวนเงิน | J6: ราคา/หน่วย | K6: ราคา/หน่วย | L6: จำนวนเงิน | M6: และแรงงาน
B7: สรุปราคาค่าก่อสร้างงานวิศวกรรมโครงสร้าง
B8: อาคาร Ratchadamnoen Center 1
A9: 1 | B9: งานเสาเข็ม Pile wall และระบบค้ำยันใต้ดิน | M9: =M45 -> 68750351 | O9: =P9*0.934908047 -> 68750351 | P9: 73537020
A10: 2 | B10: งานโครงสร้างฐานราก และชั้นใต้ดิน | M10: =M230 -> 37614118 | O10: =P10*0.934908047 -> 37614118 | P10: 40232960
A11: 3 | B11: งานโครงสร้าง คาน พื้น เสา ผนังชั้น 1 | M11: =M347 -> 18623859 | O11: =P11*0.934908047 -> 18623859 | P11: 19920525
A12: 4 | B12: งานโครงสร้าง คาน พื้น เสา ผนังชั้น 2 | M12: =M430 -> 11816618 | O12: =P12*0.934908047 -> 11816618 | P12: 12639337
A13: 5 | B13: งานโครงสร้าง คาน พื้น เสา ผนังชั้น 3 | M13: =M522 -> 12005322 | O13: =P13*0.934908047 -> 12005322 | P13: 12841179
A14: 6 | B14: งานโครงสร้าง คาน พื้น เสา ผนังชั้น 3 (ชั้นลอย) | M14: =M604 -> 2885741.8 | O14: =P14*0.934908047 -> 2885741.8 | P14: 3086658.4
A15: 7 | B15: งานโครงสร้าง คาน พื้น ผนังดาดฟ้า | M15: =M648 -> 1688762.4 | O15: =P15*0.934908047 -> 1688762.4 | P15: 1806340.6
A16: 8 | B16: งานโครงสร้างเหล็กหลังคา | M16: =M714 -> 13721188 | O16: =P16*0.934908047 -> 13721188 | P16: 14676511
A17: 9 | B17: งานบันไดคอนกรีตเสริมเหล็ก | M17: =M833 -> 827189.43 | O17: =P17*0.934908047 -> 827189.43 | P17: 884781.59
A18: 10 | B18: งานบันไดโครงสร้างเหล็ก | M18: =M903 -> 1945721.7 | O18: =P18*0.934908047 -> 1945721.7 | P18: 2081190.5
A19: 11 | B19: โครงสร้าง Support furniture | M19: =M917 -> 814928.76 | O19: =P19*0.934908047 -> 814928.76 | P19: 871667.29
B21: รวมราคาค่าก่อสร้างงานวิศวกรรมโครงสร้าง | M21: =SUM(M8:M20) -> 1.706938e+08 | O21: =SUM(O9:O20) -> 1.706938e+08 | P21: =SUM(P9:P20) -> 1.8257817e+08
A31: 1 | B31: งานเสาเข็ม Pile wall และระบบค้ำยันใต้ดิน
A32: 1.1 | B32: งานเสาเข็มอาคาร
B33: - | C33: เสาเข็มเจาะชนิดเปียก Type-1 Dia 0.60 Pile Tip -35.00 m. | E33: 537 | F33: ต้น | G33: 73995.67 | H33: =G33*O33 -> 69179.147 | I33: =H33*E33 -> 37149202 | J33: 0 | K33: =J33*O33 -> 0 | L33: =K33*E33 -> 0 | M33: =L33+I33 -> 37149202 | O33: 0.93490805
B34: - | C34: เสาเข็มเจาะชนิดเปียก Type-2 Dia 0.60 Pile Tip -35.00 m. | E34: 9 | F34: ต้น | G34: 81664.75 | H34: =G34*O34 -> 76349.032 | I34: =H34*E34 -> 687141.29 | J34: 0 | K34: =J34*O34 -> 0 | L34: =K34*E34 -> 0 | M34: =L34+I34 -> 687141.29 | O34: 0.93490805
A35: 1.2 | B35: งานตัดหัวเสาเข็ม | E35: 537 | F35: ต้น | G35: 0 | H35: =G35*O35 -> 0 | I35: =H35*E35 -> 0 | J35: 600 | K35: =J35*O35 -> 560.94483 | L35: =K35*E35 -> 301227.37 | M35: =L35+I35 -> 301227.37 | O35: 0.93490805
A36: 1.3 | B36: งานทดสอบเสาเข็ม | G36: 0 | H36: =G36*O36 -> 0 | I36: =H36*E36 -> 0 | J36: 0 | K36: =J36*O36 -> 0 | L36: =K36*E36 -> 0 | M36: =L36+I36 -> 0 | O36: 0.93490805
B37: - | C37: DYNAMIC LOAD TEST | E37: 3 | F37: ต้น | G37: 4000 | H37: =G37*O37 -> 3739.6322 | I37: =H37*E37 -> 11218.897 | J37: 0 | K37: =J37*O37 -> 0 | L37: =K37*E37 -> 0 | M37: =L37+I37 -> 11218.897 | O37: 0.93490805
B38: - | C38: SEISMIC TEST | E38: 546 | F38: ต้น | G38: 0 | H38: =G38*O38 -> 0 | I38: =H38*E38 -> 0 | J38: 120 | K38: =J38*O38 -> 112.18897 | L38: =K38*E38 -> 61255.175 | M38: =L38+I38 -> 61255.175 | O38: 0.93490805
A39: 1.4 | B39: งานเสาเข็ม Pilewall | G39: 0 | H39: =G39*O39 -> 0 | I39: =H39*E39 -> 0 | J39: 0 | K39: =J39*O39 -> 0 | L39: =K39*E39 -> 0 | M39: =L39+I39 -> 0 | O39: 0.93490805
B40: - | C40: เสาเข็มเจาะชนิดเปียก Type-1 Dia 0.60 x 18 m. | E40: 608 | F40: ต้น | G40: 48161.52 | H40: =G40*O40 -> 45026.593 | I40: =H40*E40 -> 27376168 | J40: 0 | K40: =J40*O40 -> 0 | L40: =K40*E40 -> 0 | M40: =L40+I40 -> 27376168 | O40: 0.93490805
B41: - | C41: เสาเข็มเจาะชนิดเปียก Type-2 Dia 0.60 x 18 m. | E41: 67 | F41: ต้น | G41: 50514 | H41: =G41*O41 -> 47225.945 | I41: =H41*E41 -> 3164138.3 | J41: 0 | K41: =J41*O41 -> 0 | L41: =K41*E41 -> 0 | M41: =L41+I41 -> 3164138.3 | O41: 0.93490805
O42: 0.93490805
O43: 0.93490805
O44: 0.93490805
B45: รวมราคางานเสาเข็ม Pile wall และระบบค้ำยันใต้ดิน | M45: =SUM(M33:M44) -> 68750351 | O45: 0.93490805
O46: 0.93490805
O47: 0.93490805
O48: 0.93490805
O49: 0.93490805
O50: 0.93490805
O51: 0.93490805
...

Sheet RKCA1_Ele
A1: ชื่อโครงการ | C1: =+'RKCA1_ปร.5 (ก)'!C4 -> โครงการจัดตั้งศูนย์การเรียนรู้แห่งชาติ OKMD : OKMD National Knowledge Center (Ratchadamnoen Center 1 และ 2) | J1: หมวดงาน | K1: หมวดงาน | L1: งานระบบสุขาภิบาลและดับเพลิง (RKCA 1)
A2: สถานที่ก่อสร้าง | C2: =+'RKCA1_ปร.5 (ก)'!C5 -> แขวงตลาดยอด เขตพระนคร กรุงเทพมหานคร | J2: เมื่อวันที่ | K2: เมื่อวันที่ | L2: =+'RKCA1_ปร.5 (ก)'!C10 -> 16 กรกฎาคม 2568
A3: คำนวณราคากลางโดย | C3: =+'RKCA1_ปร.5 (ก)'!C9 -> คณะกรรมการกำหนดราคากลาง
A5: ลำดับ | B5: รายการ | E5: จำนวน | F5: หน่วย | G5: ราคาวัสดุสิ่งของ | J5: ค่าแรงงาน | M5: รวมค่าวัสดุ | N5: หมายเหตุ
G6: ราคา/หน่วย | H6: ราคา/หน่วย | I6: จำนวนเงิน | J6: ราคา/หน่วย | K6: ราคา/หน่วย | L6: จำนวนเงิน | M6: และแรงงาน
B7: สรุปราคาค่าก่อสร้างงานระบบไฟฟ้าและสื่อสาร
B8: อาคาร Ratchadamnoen Center 1
A10: 1 | B10: ระบบไฟฟ้าแรงสูง | E10: 1 | F10: งาน | I10: =I50 -> 3571854.5 | L10: =L50 -> 237737.77 | M10: =I10+L10 -> 3809592.3 | O10: =P10*0.934908047 -> 3809592.3 | P10: 4074831 | Q10: =M10-O10 -> 0
A11: 2 | B11: งานอุปกรณ์ติดตั้งหม้อแปลงไฟฟ้า | E11: 1 | F11: งาน | I11: =I54 -> 37396.322 | L11: =L54 -> 56094.483 | M11: =I11+L11 -> 93490.805 | O11: =P11*0.934908047 -> 93490.805 | P11: 100000 | Q11: =M11-O11 -> 0
A12: 3 | B12: งานอุปกรณ์ติดตั้งเครื่องกำเนิดไฟฟ้าสำรอง | E12: 1 | F12: งาน | I12: =I64 -> 283342.58 | L12: =L64 -> 9349.0805 | M12: =I12+L12 -> 292691.66 | O12: =P12*0.934908047 -> 292691.66 | P12: 313070 | Q12: =M12-O12 -> 0
A13: 4 | B13: งานอุปกรณ์ติดตั้งเครื่องจ่ายไฟแบบต่อเนื่อง UPS | E13: 1 | F13: งาน | I13: =I70 -> 1332244 | L13: =L70 -> 11218.897 | M13: =I13+L13 -> 1343462.9 | O13: =P13*0.934908047 -> 1343462.9 | P13: 1437000 | Q13: =M13-O13 -> 0
A14: 5 | B14: ตู้ไฟฟ้า | E14: 1 | F14: งาน | I14: =I280 -> 6719742.3 | L14: =L280 -> 209690.53 | M14: =I14+L14 -> 6929432.8 | O14: =P14*0.934908047 -> 6929432.8 | P14: 7411887 | Q14: =M14-O14 -> 0
A15: 6 | B15: สายไฟฟ้า | E15: 1 | F15: งาน | I15: =I345 -> 11523545 | L15: =L345 -> 2882715.3 | M15: =I15+L15 -> 14406260 | O15: =P15*0.934908047 -> 14406260 | P15: 15409280 | Q15: =M15-O15 -> 0.010233913
A16: 7 | B16: ท่อและรางเดินสายไฟฟ้า | E16: 1 | F16: งาน | I16: =I378 -> 6246690.4 | L16: =L378 -> 2305984.6 | M16: =I16+L16 -> 8552675 | O16: =P16*0.934908047 -> 8552675 | P16: 9148145.7 | Q16: =M16-O16 -> 0.0009349063
A17: 8 | B17: ดวงโคมไฟฟ้า | E17: 1 | F17: งาน | I17: =I610 -> 24481952 | L17: =L610 -> 1153765.2 | M17: =I17+L17 -> 25635717 | O17: =P17*0.934908047 -> 25635717 | P17: 27420576 | Q17: =M17-O17 -> 0.0029356107
A18: 9 | B18: แสงสว่างฉุกเฉิน และป้ายทางออกฉุกเฉิน | E18: 1 | F18: งาน | I18: =I620 -> 477146.4 | L18: =L620 -> 42358.028 | M18: =I18+L18 -> 519504.43 | O18: =P18*0.934908047 -> 519504.43 | P18: 555674.36 | Q18: =M18-O18 -> 0
A19: 10 | B19: สวิตช์ เต้ารับไฟฟ้า | E19: 1 | F19: งาน | I19: =I640 -> 550802.95 | L19: =L640 -> 229861.73 | M19: =I19+L19 -> 780664.67 | O19: =P19*0.934908047 -> 780664.67 | P19: 835017.6 | Q19: =M19-O19 -> 0
A20: 11 | B20: ระบบการต่อลงดิน และการป้องกันฟ้าผ่า | E20: 1 | F20: งาน | I20: =I659 -> 1048308.7 | L20: =L659 -> 151413.03 | M20: =I20+L20 -> 1199721.7 | O20: =P20*0.934908047 -> 1199721.7 | P20: 1283251 | Q20: =M20-O20 -> 0
A21: 12 | B21: ระบบป้องกันไฟลาม | E21: 1 | F21: งาน | I21: =I663 -> 420708.62 | L21: =L663 -> 56094.483 | M21: =I21+L21 -> 476803.1 | O21: =P21*0.934908047 -> 476803.1 | P21: 510000 | Q21: =M21-O21 -> 0
A22: 13 | B22: ระบบควบคุมไฟฟ้าแสงสว่าง | E22: 1 | F22: งาน | I22: =I768 -> 1861265.8 | L22: =L768 -> 110562.23 | M22: =I22+L22 -> 1971828 | O22: =P22*0.934908047 -> 1971828 | P22: 2109114.4 | Q22: =M22-O22 -> 0
A23: 14 | B23: ระบบเสียงประกาศ | E23: 1 | F23: งาน | I23: =I869 -> 5073142.9 | L23: =L869 -> 394120.03 | M23: =M869 -> 5467263 | O23: =P23*0.934908047 -> 5467262.9 | P23: 5847915.1 | Q23: =M23-O23 -> 0.037583306
A24: 15 | B24: ระบบแจ้งเหตุเพลิงไหม้ | E24: 1 | F24: งาน | I24: =I974 -> 2319862.2 | L24: =L974 -> 690369.32 | M24: =I24+L24 -> 3010231.5 | O24: =P24*0.934908047 -> 3010231.4 | P24: 3219815.5 | Q24: =M24-O24 -> 0.034077398
A25: 16 | B25: ระบบกล้องวงจรปิด | E25: 1 | F25: งาน | I25: =I1082 -> 5181020.4 | L25: =L1082 -> 408122.19 | M25: =I25+L25 -> 5589142.6 | O25: =P25*0.934908047 -> 5589142.6 | P25: 5978280.6 | Q25: =M25-O25 -> -0.088396592
A26: 17 | B26: ระบบคอมพิวเตอร์ | E26: 1 | F26: งาน | I26: =I1114 -> 2278030.1 | L26: =L1114 -> 1015526.6 | M26: =I26+L26 -> 3293556.7 | O26: =P26*0.934908047 -> 3293556.7 | P26: 3522867 | Q26: =M26-O26 -> 0.0051419949
A27: 18 | B27: ระบบบริหารจัดการอาคาร | E27: 1 | F27: งาน | I27: =I1172 -> 3250040.5 | L27: =L1172 -> 891995.77 | M27: =I27+L27 -> 4142036.2 | O27: =P27*0.934908047 -> 4142036.2 | P27: 4430421 | Q27: =M27-O27 -> 0
A28: 19 | B28: =B1192 -> ระบบบริหารจัดการจอดรถ (Smart parking) | E28: 1 | F28: งาน | I28: =I1246 -> 1552695.3 | L28: =L1246 -> 623583.67 | M28: =I28+L28 -> 2176279 | O28: =P28*0.934908047 -> 2176279 | P28: 2327800 | Q28: =M28-O28 -> 0
A29: 20 | B29: =B1248 -> ระบบประตูอัตโนมัติ (Access control system) | E29: 1 | F29: งาน | I29: =I1296 -> 2959357.9 | L29: =L1296 -> 1277458.4 | M29: =I29+L29 -> 4236816.3 | O29: =P29*0.934908047 -> 4236816.3 | P29: 4531800 | Q29: =M29-O29 -> 0
A30: 21 | B30: =B1298 -> ระบบ Smart Booking & Desk booking | E30: 1 | F30: งาน | I30: =I1316 -> 799533.36 | L30: =L1316 -> 656492.43 | M30: =I30+L30 -> 1456025.8 | O30: =P30*0.934908047 -> 1456025.8 | P30: 1557400 | Q30: =M30-O30 -> 0
A31: 22 | B31: =B1318 -> ระบบตรวจนับคน (People Counting) | E31: 1 | F31: งาน | I31: =I1322 -> 217459.61 | L31: =L1322 -> 207175.62 | M31: =I31+L31 -> 424635.23 | O31: =P31*0.934908047 -> 424635.23 | P31: 454200 | Q31: =M31-O31 -> 0
A32: 23 | B32: ค่าขยายเขตการไฟฟ้า | E32: 1 | F32: งาน | I32: =I1330 -> 0 | L32: =L1330 -> 962955.29 | M32: =I32+L32 -> 962955.29 | O32: =P32*0.934908047 -> 962955.29 | P32: 1030000 | Q32: =M32-O32 -> 0
B34: รวมราคาค่าก่อสร้างงานระบบไฟฟ้าและสื่อสาร | I34: =SUM(I10:I32) -> 82186142 | L34: =SUM(L10:L32) -> 14584645 | M34: =SUM(M10:M32) -> 96770786 | O34: =SUM(O10:O33) -> 96770786 | P34: =SUM(P10:P33) -> 1.0350835e+08 | Q34: =M34-O34 -> 0.0025105327
A37: 1 | B37: ระบบไฟฟ้าแรงสูง
A38: 1.1 | B38: สายไฟฟ้าแรงสูง (HV Cable)
B39: สายไฟแรงสูงชนิด CU XLPE Cable 1C 12/20kV (24kV)
B40: - | C40: 70 มม2 | E40: 169 | F40: ม. | G40: =ROUND(746*80%,0) -> 597 | H40: =G40*O40 -> 558.1401 | I40: =E40*H40 -> 94325.678 | J40: 90 | K40: =J40*O40 -> 84.141724 | L40: =E40*K40 -> 14219.951 | M40: =I40+L40 -> 108545.63 | O40: 0.93490805
B41: - | C41: 240 มม2 | E41: 274 | F41: ม. | G41: =ROUND(1656*80%,0) -> 1325 | H41: =G41*O41 -> 1238.7532 | I41: =E41*H41 -> 339418.37 | J41: 155 | K41: =J41*O41 -> 144.91075 | L41: =E41*K41 -> 39705.545 | M41: =I41+L41 -> 379123.91 | O41: 0.93490805
A42: 1.2 | B42: ท่อร้อยสายไฟฟ้าชนิด IMC | O42: 0.93490805
B43: - | C43: 100 มม. Ø | E43: 57 | F43: ม. | G43: 934 | H43: =G43*O43 -> 873.20412 | I43: =E43*H43 -> 49772.635 | J43: 95 | K43: =J43*O43 -> 88.816264 | L43: =E43*K43 -> 5062.5271 | M43: =I43+L43 -> 54835.162 | O43: 0.93490805
A44: 1.3 | B44: HDPE w/ Concrete Encased (Ductbank 2x2) | E44: 30 | F44: ม. | G44: 4500 | H44: =G44*O44 -> 4207.0862 | I44: =E44*H44 -> 126212.59 | J44: 1200 | K44: =J44*O44 -> 1121.8897 | L44: =E44*K44 -> 33656.69 | M44: =I44+L44 -> 159869.28 | O44: 0.93490805
A45: 1.4 | B45: Manhole (TypeA3) | E45: 1 | F45: ชุด | G45: 158460 | H45: =G45*O45 -> 148145.53 | I45: =E45*H45 -> 148145.53 | J45: 35195 | K45: =J45*O45 -> 32904.089 | L45: =E45*K45 -> 32904.089 | M45: =I45+L45 -> 181049.62 | O45: 0.93490805
...

Sheet RC1_San+FP
A1: ชื่อโครงการ | D1: =+'RKCA1_ปร.5 (ก)'!C4 -> โครงการจัดตั้งศูนย์การเรียนรู้แห่งชาติ OKMD : OKMD National Knowledge Center (Ratchadamnoen Center 1 และ 2) | J1: หมวดงาน | K1: หมวดงาน | L1: งานระบบสุขาภิบาลและดับเพลิง (RKCA 1)
A2: สถานที่ก่อสร้าง | D2: =+'RKCA1_ปร.5 (ก)'!C5 -> แขวงตลาดยอด เขตพระนคร กรุงเทพมหานคร | J2: เมื่อวันที่ | K2: เมื่อวันที่ | L2: =+'RKCA1_ปร.5 (ก)'!C10 -> 16 กรกฎาคม 2568
A3: คำนวณราคากลางโดย | D3: =+'RKCA1_ปร.5 (ก)'!C9 -> คณะกรรมการกำหนดราคากลาง
A5: ลำดับ | B5: รายการ | E5: จำนวน | F5: หน่วย | G5: ราคาวัสดุสิ่งของ | J5: ค่าแรงงาน | M5: รวมค่าวัสดุ | N5: หมายเหตุ
G6: ราคา/หน่วย | H6: ราคา/หน่วย | I6: จำนวนเงิน | J6: ราคา/หน่วย | K6: ราคา/หน่วย | L6: จำนวนเงิน | M6: และแรงงาน
B7: สรุปราคาค่าก่อสร้างงานระบบสุขาภิบาลและดับเพลิง
B8: อาคาร Ratchadamnoen Center 1
A10: 1 | B10: งานระบบประปา | E10: 1 | F10: งาน | I10: =I96 -> 1462495.2 | L10: =L96 -> 203507.04 | M10: =I10+L10 -> 1666002.2 | O10: =P10*0.934908047 -> 1666002.2 | P10: 1781995.8 | Q10: =M10-O10 -> 0
A11: 2 | B11: งานระบบนำน้ำผ่านการบำบัดกลับมาใช้ | E11: 1 | F11: งาน | I11: =I180 -> 2380895.5 | L11: =L180 -> 176757.45 | M11: =I11+L11 -> 2557652.9 | O11: =P11*0.934908047 -> 2557652.9 | P11: 2735726.7 | Q11: =M11-O11 -> 0
A12: 3 | B12: งานระบบน้ำเสีย | E12: 1 | F12: งาน | I12: =I271 -> 2916366.7 | L12: =L271 -> 517763.3 | M12: =I12+L12 -> 3434130 | O12: =P12*0.934908047 -> 3434130 | P12: 3673227.5 | Q12: =M12-O12 -> -0.0046745404
A13: 4 | B13: งานระบบระบายน้ำฝน | E13: 1 | F13: งาน | I13: =I330 -> 2327576 | L13: =L330 -> 547716.79 | M13: =I13+L13 -> 2875292.8 | O13: =P13*0.934908047 -> 2875292.8 | P13: 3075481.9 | Q13: =M13-O13 -> 0
A14: 5 | B14: งานระบบดับเพลิง | E14: 1 | F14: งาน | I14: =I437 -> 10169033 | L14: =L437 -> 2613664.5 | M14: =I14+L14 -> 12782698 | O14: =P14*0.934908047 -> 12782698 | P14: 13672679 | Q14: =M14-O14 -> -0.004674539
Q15: =M15-O15 -> 0
B16: รวมราคาค่าก่อสร้างงานระบบสุขาภิบาลและดับเพลิง | M16: =SUM(M10:M15) -> 23315775 | O16: =SUM(O10:O15) -> 23315775 | P16: =SUM(P10:P15) -> 24939111 | Q16: =M16-O16 -> -0.0093490817
A19: 1 | B19: งานระบบประปา
B21: Main Equipment
B22: 1.1 | C22: เครื่องสูบน้ำเพิ่มแรงดัน และอุปกรณ์ประกอบ
C23: - CWPBS-01 | E23: 1 | F23: ชุด | G23: 713000 | H23: =G23*O23 -> 666589.44 | I23: =E23*H23 -> 666589.44 | J23: 10000 | K23: =J23*O23 -> 9349.0805 | L23: =E23*K23 -> 9349.0805 | M23: =I23+L23 -> 675938.52 | O23: 0.93490805
O24: 0.93490805
B25: งานท่อ (Piping Work) | O25: 0.93490805 | Q25: ราคาพาณิชย์เดือนพ.ย
B26: 1.2 | C26: ท่อ PP-R PN 10 | O26: 0.93490805
C27: - Ø 20 มม. (15 มม. ) | E27: 230 | F27: ม. | G27: 35 | H27: =G27*O27 -> 32.721782 | I27: =E27*H27 -> 7526.0098 | J27: 30 | K27: =J27*O27 -> 28.047241 | L27: =E27*K27 -> 6450.8655 | M27: =I27+L27 -> 13976.875 | O27: 0.93490805
C28: - Ø 25 มม. (20 มม. ) | E28: 594 | F28: ม. | G28: 46 | H28: =G28*O28 -> 43.00577 | I28: =E28*H28 -> 25545.427 | J28: 30 | K28: =J28*O28 -> 28.047241 | L28: =E28*K28 -> 16660.061 | M28: =I28+L28 -> 42205.489 | O28: 0.93490805 | Q28: กระทรวงพาณิชย์ | R28: 46
C29: - Ø 32 มม. (25 มม.) | E29: 404 | F29: ม. | G29: 76 | H29: =G29*O29 -> 71.053012 | I29: =E29*H29 -> 28705.417 | J29: 30 | K29: =J29*O29 -> 28.047241 | L29: =E29*K29 -> 11331.086 | M29: =I29+L29 -> 40036.502 | O29: 0.93490805 | Q29: กระทรวงพาณิชย์ | R29: 76
C30: - Ø 40 มม. (32 มม.) | E30: 3 | F30: ม. | G30: 113 | H30: =G30*O30 -> 105.64461 | I30: =E30*H30 -> 316.93383 | J30: 30 | K30: =J30*O30 -> 28.047241 | L30: =E30*K30 -> 84.141724 | M30: =I30+L30 -> 401.07555 | O30: 0.93490805 | Q30: กระทรวงพาณิชย์ | R30: 113
C31: - Ø 50 มม. (40 มม.) | E31: 76 | F31: ม. | G31: 180 | H31: =G31*O31 -> 168.28345 | I31: =E31*H31 -> 12789.542 | J31: 50 | K31: =J31*O31 -> 46.745402 | L31: =E31*K31 -> 3552.6506 | M31: =I31+L31 -> 16342.193 | O31: 0.93490805 | Q31: กระทรวงพาณิชย์ | R31: 180
C32: - Ø 63 มม. (50 มม.) | E32: 134 | F32: ม. | G32: 287 | H32: =G32*O32 -> 268.31861 | I32: =E32*H32 -> 35954.694 | J32: 75 | K32: =J32*O32 -> 70.118104 | L32: =E32*K32 -> 9395.8259 | M32: =I32+L32 -> 45350.52 | O32: 0.93490805 | Q32: กระทรวงพาณิชย์ | R32: 287
C33: - Ø 75 มม. (65 มม.) | E33: 91 | F33: ม. | G33: 402 | H33: =G33*O33 -> 375.83303 | I33: =E33*H33 -> 34200.806 | J33: 100 | K33: =J33*O33 -> 93.490805 | L33: =E33*K33 -> 8507.6632 | M33: =I33+L33 -> 42708.469 | O33: 0.93490805 | Q33: กระทรวงพาณิชย์ | R33: 402
C34: - Ø 90 มม. (80 มม.) | E34: 35 | F34: ม. | G34: 562 | H34: =G34*O34 -> 525.41832 | I34: =E34*H34 -> 18389.641 | J34: 120 | K34: =J34*O34 -> 112.18897 | L34: =E34*K34 -> 3926.6138 | M34: =I34+L34 -> 22316.255 | O34: 0.93490805 | Q34: กระทรวงพาณิชย์ | R34: 562
C35: - Ø 110 มม. (100 มม.) | E35: 96 | F35: ม. | G35: 834 | H35: =G35*O35 -> 779.71331 | I35: =E35*H35 -> 74852.478 | J35: 150 | K35: =J35*O35 -> 140.23621 | L35: =E35*K35 -> 13462.676 | M35: =I35+L35 -> 88315.154 | O35: 0.93490805 | Q35: กระทรวงพาณิชย์ | R35: 834
B36: 1.3 | C36: ท่อ HDPE PN 10 | O36: 0.93490805
C37: - Ø 32 มม. (25 มม.) | E37: 74 | F37: ม. | G37: 33 | H37: =G37*O37 -> 30.851966 | I37: =E37*H37 -> 2283.0455 | J37: 30 | K37: =J37*O37 -> 28.047241 | L37: =E37*K37 -> 2075.4959 | M37: =I37+L37 -> 4358.5413 | O37: 0.93490805 | Q37: TAP | R37: 33
C38: - Ø 63 มม. (50 มม.) | E38: 0 | F38: ม. | G38: 117.7 | H38: =G38*O38 -> 110.03868 | I38: =E38*H38 -> 0 | J38: 75 | K38: =J38*O38 -> 70.118104 | L38: =E38*K38 -> 0 | M38: =I38+L38 -> 0 | O38: 0.93490805 | Q38: TAP | R38: 117.7
C39: - Ø 75 มม. (65 มม.) | E39: 0 | F39: ม. | G39: 166.1 | H39: =G39*O39 -> 155.28823 | I39: =E39*H39 -> 0 | J39: 100 | K39: =J39*O39 -> 93.490805 | L39: =E39*K39 -> 0 | M39: =I39+L39 -> 0 | O39: 0.93490805 | Q39: TAP | R39: 166.1
C40: - Ø 90 มม. (80 มม.) | E40: 51 | F40: ม. | G40: 228.8 | H40: =G40*O40 -> 213.90696 | I40: =E40*H40 -> 10909.255 | J40: 120 | K40: =J40*O40 -> 112.18897 | L40: =E40*K40 -> 5721.6372 | M40: =I40+L40 -> 16630.892 | O40: 0.93490805 | Q40: TAP | R40: 228.8
C41: - Ø 110 มม. (100 มม.) | E41: 0 | F41: ม. | G41: 341 | H41: =G41*O41 -> 318.80364 | I41: =E41*H41 -> 0 | J41: 150 | K41: =J41*O41 -> 140.23621 | L41: =E41*K41 -> 0 | M41: =I41+L41 -> 0 | O41: 0.93490805 | Q41: TAP | R41: 341
B42: 1.4 | C42: ข้อต่ออุปกรณ์ท่อ | E42: 1 | F42: เหมา | G42: 125323 | H42: =G42*O42 -> 117165.48 | I42: =E42*H42 -> 117165.48 | J42: 37597 | K42: =J42*O42 -> 35149.738 | L42: =E42*K42 -> 35149.738 | M42: =I42+L42 -> 152315.22 | O42: 0.93490805
B43: 1.5 | C43: เหล็กยึดท่อ | E43: 1 | F43: เหมา | G43: 50130 | H43: =G43*O43 -> 46866.94 | I43: =E43*H43 -> 46866.94 | J43: 15039 | K43: =J43*O43 -> 14060.082 | L43: =E43*K43 -> 14060.082 | M43: =I43+L43 -> 60927.023 | O43: 0.93490805
B44: 1.6 | C44: ทดสอบ ทำความสะอาด ทาสีทำสัญลักษณ์ | E44: 1 | F44: เหมา | G44: 25065 | H44: =G44*O44 -> 23433.47 | I44: =E44*H44 -> 23433.47 | J44: 7520 | K44: =J44*O44 -> 7030.5085 | L44: =E44*K44 -> 7030.5085 | M44: =I44+L44 -> 30463.979 | O44: 0.93490805
O45: 0.93490805
...

Sheet RC1_Air
