Workbook

Sheet SCH
A1: WBS | B1: Activities | C1: Amount(THB) | D1: %W | E1: DataType | F1: Progress | G1: %Progress | H1: 46060 | I1: =H1+7 -> 46067 | J1: =I1+7 -> 46074 | K1: =J1+7 -> 46081 | L1: =K1+7 -> 46088 | M1: =L1+7 -> 46095 | N1: =M1+7 -> 46102 | O1: =N1+7 -> 46109 | P1: =O1+7 -> 46116 | ... CE1: =CD1+7 -> 46585 | CF1: Recheck Sum Percent
A2: 1 | B2: Preliminaries
A4: 1.1 | B4: เตรียมการก่อสร้าง | C4: 2566437 | D4: =C4/$C$86 -> 0.021229926 | E4: Plan | F4: =G4*$C$4 -> 2566437 | G4: =SUM(H4:CE4)/100 -> 1 | H4: =100/8 -> 12.5 | I4: =100/8 -> 12.5 | J4: =100/8 -> 12.5 | K4: =100/8 -> 12.5 | L4: =100/8 -> 12.5 | M4: =100/8 -> 12.5 | N4: =100/8 -> 12.5 | O4: 12.5 | CF4: =SUM(H4:CE4) -> 100
D5: =D4 -> 0.021229926 | E5: Actual | F5: =G5*$C$4 -> 2566437 | G5: =SUM(H5:CE5)/100 -> 1 | H5: 15 | I5: 15 | J5: 15 | K5: 15 | L5: 15 | M5: 15 | N5: 5 | O5: 5 | CF5: =SUM(H5:CE5) -> 100
A6: 1.2 | B6: ดำเนินการก่อสร้าง | C6: 11648830 | D6: =C6/$C$86 -> 0.096360755 | E6: Plan | F6: =G6*$C$6 -> 11648830 | G6: =SUM(H6:CE6)/100 -> 1 | P6: =100/46 -> 2.173913 | Q6: =P6 -> 2.173913 | R6: =Q6 -> 2.173913 | S6: =R6 -> 2.173913 | T6: =S6 -> 2.173913 | U6: =T6 -> 2.173913 | V6: =U6 -> 2.173913 | W6: =V6 -> 2.173913 | X6: =W6 -> 2.173913 | ... Z6: =Y6 -> 2.173913 | AB6: =Z6 -> 2.173913 | AC6: =AB6 -> 2.173913 | AD6: =AC6 -> 2.173913 | AE6: =AD6 -> 2.173913 | AF6: =AE6 -> 2.173913 | AG6: =AF6 -> 2.173913 | AH6: =AG6 -> 2.173913 | AI6: =AH6 -> 2.173913 | AJ6: =AI6 -> 2.173913 | ... AN6: =AM6 -> 2.173913 | AP6: =AN6 -> 2.173913 | AQ6: =AP6 -> 2.173913 | AR6: =AQ6 -> 2.173913 | AS6: =AR6 -> 2.173913 | AT6: =AS6 -> 2.173913 | AU6: =AT6 -> 2.173913 | AV6: =AU6 -> 2.173913 | AW6: =AV6 -> 2.173913 | AX6: =AW6 -> 2.173913 | ... BK6: =BJ6 -> 2.173913 | CF6: =SUM(H6:CE6) -> 100
D7: =D6 -> 0.096360755 | E7: Actual | F7: =G7*$C$6 -> 11648830 | G7: =SUM(H7:CE7)/100 -> 1 | P7: =100/46 -> 2.173913 | Q7: =100/46 -> 2.173913 | R7: =100/46 -> 2.173913 | S7: =100/46 -> 2.173913 | T7: =100/46 -> 2.173913 | U7: =100/46 -> 2.173913 | V7: =100/46 -> 2.173913 | W7: =100/46 -> 2.173913 | ... Z7: =100/46 -> 2.173913 | AB7: =100/46 -> 2.173913 | AC7: =100/46 -> 2.173913 | AD7: =100/46 -> 2.173913 | AE7: =100/46 -> 2.173913 | AF7: =100/46 -> 2.173913 | AG7: =100/46 -> 2.173913 | AH7: =100/46 -> 2.173913 | AI7: =100/46 -> 2.173913 | ... AN7: =100/46 -> 2.173913 | AP7: =100/46 -> 2.173913 | AQ7: =100/46 -> 2.173913 | AR7: =100/46 -> 2.173913 | AS7: =100/46 -> 2.173913 | AT7: =100/46 -> 2.173913 | AU7: =100/46 -> 2.173913 | AV7: =100/46 -> 2.173913 | AW7: =100/46 -> 2.173913 | ... BK7: =100/46 -> 2.173913 | CF7: =SUM(H7:CE7) -> 100
A8: 1.3 | B8: การส่งมอบงาน | C8: 260000 | D8: =C8/$C$86 -> 0.0021507565 | E8: Plan | F8: =G8*$C$8 -> 260000 | G8: =SUM(H8:CE8)/100 -> 1 | BL8: =100/6 -> 16.666667 | BM8: =BL8 -> 16.666667 | BN8: =BM8 -> 16.666667 | BO8: =BN8 -> 16.666667 | BP8: =BO8 -> 16.666667 | BQ8: =BP8 -> 16.666667 | CF8: =SUM(H8:CE8) -> 100
D9: =D8 -> 0.0021507565 | E9: Actual | F9: =G9*$C$8 -> 260000 | G9: =SUM(H9:CE9)/100 -> 1 | BL9: =100/6 -> 16.666667 | BM9: =100/6 -> 16.666667 | BN9: =100/6 -> 16.666667 | BO9: =100/6 -> 16.666667 | BP9: =100/6 -> 16.666667 | BQ9: =100/6 -> 16.666667 | CF9: =SUM(H9:CE9) -> 100
A10: 2 | B10: Structure | CF10: =SUM(H10:CE10) -> 0
CF11: =SUM(H11:CE11) -> 0
A12: 2.1 | B12: งานเสาเข็ม | C12: 11469839 | D12: =C12/$C$86 -> 0.094880113 | E12: Plan | F12: =G12*$C$12 -> 11469839 | G12: =SUM(H12:CE12)/100 -> 1 | Q12: =100/8 -> 12.5 | R12: =100/8 -> 12.5 | S12: =100/8 -> 12.5 | T12: =S12 -> 12.5 | U12: =T12 -> 12.5 | V12: =U12 -> 12.5 | W12: =V12 -> 12.5 | X12: =W12 -> 12.5 | CF12: =SUM(H12:CE12) -> 100
D13: =D12 -> 0.094880113 | E13: Actual | F13: =G13*$C$12 -> 11469839 | G13: =SUM(H13:CE13)/100 -> 1 | Q13: 4.67 | R13: 10.27 | S13: 11.06 | T13: 8 | U13: 14 | V13: 16 | W13: 16 | X13: 14 | Y13: 6 | CF13: =SUM(H13:CE13) -> 100
A14: 2.2 | B14: งานฐานราก | C14: 8375914 | D14: =C14/$C$86 -> 0.069286736 | E14: Plan | F14: =G14*$C$14 -> 8375914 | G14: =SUM(H14:CE14)/100 -> 1 | V14: =100/5 -> 20 | W14: =V14 -> 20 | X14: =W14 -> 20 | Y14: =X14 -> 20 | Z14: =Y14 -> 20 | CF14: =SUM(H14:CE14) -> 100
D15: =D14 -> 0.069286736 | E15: Actual | F15: =G15*$C$14 -> 8375914 | G15: =SUM(H15:CE15)/100 -> 1 | U15: 15 | V15: 13 | W15: 3 | X15: 15 | Y15: 16 | Z15: 38 | CF15: =SUM(H15:CE15) -> 100
A16: 2.3 | B16: งานเสา | C16: 3045675.9 | D16: =C16/$C$86 -> 0.025194258 | E16: Plan | F16: =G16*$C$16 -> 3045675.9 | G16: =SUM(H16:CE16)/100 -> 1 | AB16: =100/6 -> 16.666667 | AC16: =AB16 -> 16.666667 | AD16: =AC16 -> 16.666667 | AE16: =AD16 -> 16.666667 | AF16: =AE16 -> 16.666667 | AG16: =AF16 -> 16.666667 | CF16: =SUM(H16:CE16) -> 100
D17: =D16 -> 0.025194258 | E17: Actual | F17: =G17*$C$16 -> 3045675.9 | G17: =SUM(H17:CE17)/100 -> 1 | AB17: 2.24 | AC17: 6.74 | AD17: 35.02 | AE17: 26 | AF17: 6 | AG17: 4 | AH17: 4 | AI17: 2 | AJ17: 8 | AK17: 6 | CF17: =SUM(H17:CE17) -> 100
A18: 2.4 | B18: งานคาน | C18: 4095836.8 | D18: =C18/$C$86 -> 0.033881336 | E18: Plan | F18: =G18*$C$18 -> 4095836.8 | G18: =SUM(H18:CE18)/100 -> 1 | AC18: =100/7 -> 14.285714 | AD18: =AC18 -> 14.285714 | AE18: =AD18 -> 14.285714 | AF18: =AE18 -> 14.285714 | AG18: =AF18 -> 14.285714 | AH18: =AG18 -> 14.285714 | AI18: =AH18 -> 14.285714 | CF18: =SUM(H18:CE18) -> 100
D19: =D18 -> 0.033881336 | E19: Actual | F19: =G19*$C$18 -> 4095836.8 | G19: =SUM(H19:CE19)/100 -> 1 | AF19: 10 | AG19: 10 | AH19: 10 | AI19: 20 | AJ19: 20 | AK19: 10 | AL19: 10 | AM19: 10 | CF19: =SUM(H19:CE19) -> 100
A20: 2.5 | B20: งานพื้น | C20: 17041214 | D20: =C20/$C$86 -> 0.14096731 | E20: Plan | F20: =G20*$C$20 -> 17041214 | G20: =SUM(H20:CE20)/100 -> 1 | AP20: =100/8 -> 12.5 | AQ20: =100/8 -> 12.5 | AR20: =100/8 -> 12.5 | AS20: =100/8 -> 12.5 | AT20: =100/8 -> 12.5 | AU20: =100/8 -> 12.5 | AV20: =100/8 -> 12.5 | AW20: =100/8 -> 12.5 | CF20: =SUM(H20:CE20) -> 100
D21: =D20 -> 0.14096731 | E21: Actual | F21: =G21*$C$20 -> 0 | G21: =SUM(H21:CE21)/100 -> 0 | CF21: =SUM(H21:CE21) -> 0
A22: 2.6 | B22: งานผนัง ค.ส.ล. | C22: 57078 | D22: =C22/$C$86 -> 0.00047215722 | E22: Plan | F22: =G22*$C$22 -> 57078 | G22: =SUM(H22:CE22)/100 -> 1 | AR22: =100/4 -> 25 | AS22: =100/4 -> 25 | AT22: =100/4 -> 25 | AU22: =100/4 -> 25 | CF22: =SUM(H22:CE22) -> 100
D23: =D22 -> 0.00047215722 | E23: Actual | F23: =G23*$C$22 -> 57078 | G23: =SUM(H23:CE23)/100 -> 1 | AR23: 25 | AS23: 25 | AT23: 25 | AU23: 25 | CF23: =SUM(H23:CE23) -> 100
A24: 2.7 | B24: งานบันได ค.ส.ล. | C24: 66738.5 | D24: =C24/$C$86 -> 0.00055207023 | E24: Plan | F24: =G24*$C$24 -> 66738.5 | G24: =SUM(H24:CE24)/100 -> 1 | AV24: =100/4 -> 25 | AW24: =100/4 -> 25 | AX24: =100/4 -> 25 | AY24: =100/4 -> 25 | CF24: =SUM(H24:CE24) -> 100
D25: =D24 -> 0.00055207023 | E25: Actual | F25: =G25*$C$24 -> 66738.5 | G25: =SUM(H25:CE25)/100 -> 1 | BH25: 25 | BI25: 25 | BL25: 10 | BQ25: 40 | CF25: =SUM(H25:CE25) -> 100
A26: 2.8 | B26: งาน Ramp | C26: 242035.7 | D26: =C26/$C$86 -> 0.0020021533 | E26: Plan | F26: =G26*$C$26 -> 242035.7 | G26: =SUM(H26:CE26)/100 -> 1 | AV26: =100/4 -> 25 | AW26: =100/4 -> 25 | AX26: =100/4 -> 25 | AY26: =100/4 -> 25 | CF26: =SUM(H26:CE26) -> 100
D27: =D26 -> 0.0020021533 | E27: Actual | F27: =G27*$C$26 -> 242035.7 | G27: =SUM(H27:CE27)/100 -> 1 | BH27: 25 | BI27: 25 | BL27: 10 | BP27: 15 | BQ27: 25 | CF27: =SUM(H27:CE27) -> 100
A28: 2.1 | B28: งานเบ็ดเตล็ด | C28: 1352696 | D28: =C28/$C$86 -> 0.011189691 | E28: Plan | F28: =G28*$C$28 -> 1352696 | G28: =SUM(H28:CE28)/100 -> 1 | BD28: 25 | BE28: 25 | BF28: 25 | BG28: 25 | CF28: =SUM(H28:CE28) -> 100
D29: =D28 -> 0.011189691 | E29: Actual | F29: =G29*$C$28 -> 0 | G29: =SUM(H29:CE29)/100 -> 0 | CF29: =SUM(H29:CE29) -> 0
A30: 3 | B30: Architecture | CF30: =SUM(H30:CE30) -> 0
CF31: =SUM(H31:CE31) -> 0
A32: A | B32: หมวดงานสถาปัตยกรรม (คลังสินค้า) | CF32: =SUM(H32:CE32) -> 0
CF33: =SUM(H33:CE33) -> 0
A34: 3.1 | B34: งานผนังและวัสดุตกแต่งผิวผนัง | C34: 11322420 | D34: =C34/$C$86 -> 0.093660646 | E34: Plan | F34: =G34*$C$34 -> 11322420 | G34: =SUM(H34:CE34)/100 -> 1 | AV34: =100/14 -> 7.1428571 | AW34: =100/14 -> 7.1428571 | AX34: =100/14 -> 7.1428571 | AY34: =100/14 -> 7.1428571 | AZ34: =100/14 -> 7.1428571 | BA34: =100/14 -> 7.1428571 | BB34: =100/14 -> 7.1428571 | BC34: =100/14 -> 7.1428571 | ... BI34: =100/14 -> 7.1428571 | CF34: =SUM(H34:CE34) -> 100
D35: =D34 -> 0.093660646 | E35: Actual | F35: =G35*$C$34/10 -> 0 | G35: =SUM(H35:CE35)/100 -> 0 | CF35: =SUM(H35:CE35) -> 0
A36: 3.2 | B36: งานพื้นและวัสดุตกแต่งผิวพื้น | C36: 27880 | D36: =C36/$C$86 -> 0.00023062727 | E36: Plan | F36: =G36*$C$36 -> 27880 | G36: =SUM(H36:CE36)/100 -> 1 | AX36: =100/8 -> 12.5 | AY36: =100/8 -> 12.5 | AZ36: =100/8 -> 12.5 | BA36: =100/8 -> 12.5 | BB36: =100/8 -> 12.5 | BC36: =100/8 -> 12.5 | BD36: =100/8 -> 12.5 | BE36: =100/8 -> 12.5 | CF36: =SUM(H36:CE36) -> 100
D37: =D36 -> 0.00023062727 | E37: Actual | F37: =G37*$C$36 -> 27880 | G37: =SUM(H37:CE37)/100 -> 1 | BR37: 100 | CF37: =SUM(H37:CE37) -> 100
A38: 3.3 | B38: งานหลังคา | C38: 9512634 | D38: =C38/$C$86 -> 0.078689843 | E38: Plan | F38: =G38*$C$38 -> 9512634 | G38: =SUM(H38:CE38)/100 -> 1 | AN38: =100/6 -> 16.666667 | AP38: =100/6 -> 16.666667 | AQ38: =100/6 -> 16.666667 | AR38: =100/6 -> 16.666667 | AS38: =100/6 -> 16.666667 | AT38: =100/6 -> 16.666667 | CF38: =SUM(H38:CE38) -> 100
D39: =D38 -> 0.078689843 | E39: Actual | F39: =G39*$C$38 -> 0 | G39: =SUM(H39:CE39)/100 -> 0 | CF39: =SUM(H39:CE39) -> 0
A40: 3.4 | B40: งานฝ้าเพดาน | C40: 31320 | D40: =C40/$C$86 -> 0.00025908343 | E40: Plan | F40: =G40*$C$40 -> 31320 | G40: =SUM(H40:CE40)/100 -> 1 | AT40: =100/3 -> 33.333333 | AU40: =100/3 -> 33.333333 | AV40: =100/3 -> 33.333333 | CF40: =SUM(H40:CE40) -> 100
D41: =D40 -> 0.00025908343 | E41: Actual | F41: =G41*$C$40 -> 31320 | G41: =SUM(H41:CE41)/100 -> 1 | BM41: 20 | BN41: 20 | BO41: 20 | BP41: 10 | BQ41: 20 | BR41: 10 | CF41: =SUM(H41:CE41) -> 100
...

Sheet Progress_Summary
A1: =SCH!H1 -> 46060 | B1: =SCH!I1 -> 46067 | C1: =SCH!J1 -> 46074 | D1: =SCH!K1 -> 46081 | E1: =SCH!L1 -> 46088 | F1: =SCH!M1 -> 46095 | G1: =SCH!N1 -> 46102 | H1: =SCH!O1 -> 46109 | ... BX1: =SCH!CE1 -> 46585
A2: =SCH!H98 -> 0.26537408 | B2: =SCH!I98 -> 0.53074816 | C2: =SCH!J98 -> 0.79612224 | D2: =SCH!K98 -> 1.0614963 | E2: =SCH!L98 -> 1.3268704 | F2: =SCH!M98 -> 1.5922445 | G2: =SCH!N98 -> 1.8576186 | H2: =SCH!O98 -> 2.1229926 | ... BX2: =SCH!CE98 -> 100
A3: =SCH!H99 -> 0.3184489 | B3: =SCH!I99 -> 0.63689779 | C3: =SCH!J99 -> 0.95534669 | D3: =SCH!K99 -> 1.2737956 | E3: =SCH!L99 -> 1.5922445 | F3: =SCH!M99 -> 1.9106934 | G3: =SCH!N99 -> 2.016843 | H3: =SCH!O99 -> 2.1229926 | ... BX3: =SCH!CE99 -> 0

Sheet man_power
B7: 0.0024230454
D8: date | F8: 1to7 | G8: 8to14 | H8: 15to22 | I8: 23to30 | J8: 1to7 | K8: 8to14 | L8: 15to22 | M8: 23to30 | N8: 1to7 | O8: 8to14 | P8: 15to22 | Q8: 23to30 | R8: 1to7 | S8: 8to14 | T8: 15to22 | U8: 23to30 | V8: 1to7 | W8: 8to14 | X8: 15to22 | Y8: 23to30 | Z8: 1to7 | AA8: 8to14 | AB8: 15to22 | AC8: 23to30 | AD8: 1to7 | AE8: 8to14 | AF8: 15to22 | AG8: 23to30 | AH8: 1to7 | AI8: 8to14 | AJ8: 15to22 | AK8: 23to30 | AL8: 1to7 | AM8: 8to14 | AN8: 15to22 | AO8: 23to30 | AP8: 1to7 | AQ8: 8to14 | AR8: 15to22 | AS8: 23to30 | AT8: 1to7 | AU8: 8to14 | AV8: 15to22 | AW8: 23to30 | AX8: 1to7 | AY8: 8to14 | AZ8: 15to22 | BA8: 23to30 | BB8: 1to7 | BC8: 8to14 | BD8: 15to22 | BE8: 23to30 | BF8: 1to7 | BG8: 8to14 | BH8: 15to22 | BI8: 23to30 | BJ8: 1to7 | BK8: 8to14 | BL8: 15to22 | BM8: 23to30 | BN8: 1to7 | BO8: 8to14 | BP8: 15to22 | BQ8: 23to30
D9: Num | F9: 7 | G9: 7 | H9: 8 | I9: 8 | J9: 7 | K9: 7 | L9: 8 | M9: 8 | N9: 7 | O9: 7 | P9: 8 | Q9: 8 | R9: 7 | S9: 7 | T9: 8 | U9: 8 | V9: 7 | W9: 7 | X9: 8 | Y9: 8 | Z9: 7 | AA9: 7 | AB9: 8 | AC9: 8 | AD9: 7 | AE9: 7 | AF9: 8 | AG9: 8 | AH9: 7 | AI9: 7 | AJ9: 8 | AK9: 8 | AL9: 7 | AM9: 7 | AN9: 8 | AO9: 8 | AP9: 7 | AQ9: 7 | AR9: 8 | AS9: 8 | AT9: 7 | AU9: 7 | AV9: 8 | AW9: 8 | AX9: 7 | AY9: 7 | AZ9: 8 | BA9: 8 | BB9: 7 | BC9: 7 | BD9: 8 | BE9: 8 | BF9: 7 | BG9: 7 | BH9: 8 | BI9: 8 | BJ9: 7 | BK9: 7 | BL9: 8 | BM9: 8 | BN9: 7 | BO9: 7 | BP9: 8 | BQ9: 8
A10: ลำดับ | B10: รายการ | C10: Amount (THB) | D10: %W | F10: 1 | J10: 2 | N10: 3 | R10: 4 | V10: 5 | Z10: 6 | AD10: 7 | AH10: 8 | AL10: 9 | AP10: 10 | AT10: 11 | AX10: 12 | BB10: 13 | BF10: 14 | BJ10: 15 | BN10: 16 | BR10: Man-Hr | BS10: Remark
F11: 45139 | J11: 45170 | N11: 45200 | R11: 45231 | V11: 45261 | Z11: 45292 | AD11: 45323 | AH11: 45352 | AL11: 45383 | AP11: 45413 | AT11: 45444 | AX11: 45474 | BB11: 45505 | BF11: 45536 | BJ11: 45566 | BN11: 45597
F12: 1 | G12: 2 | H12: 3 | I12: 4 | J12: 5 | K12: 6 | L12: 7 | M12: 8 | N12: 9 | O12: 10 | P12: 11 | Q12: 12 | R12: 13 | S12: 14 | T12: 15 | U12: 16 | V12: 17 | W12: 18 | X12: 19 | Y12: 20 | Z12: 21 | AA12: 22 | AB12: 23 | AC12: 24 | AD12: 25 | AE12: 26 | AF12: 27 | AG12: 28 | AH12: 29 | AI12: 30 | AJ12: 31 | AK12: 32 | AL12: 33 | AM12: 34 | AN12: 35 | AO12: 36 | AP12: 37 | AQ12: 38 | AR12: 39 | AS12: 40 | AT12: 41 | AU12: 42 | AV12: 43 | AW12: 44 | AX12: 45 | AY12: 46 | AZ12: 47 | BA12: 48 | BB12: 49 | BC12: 50 | BD12: 51 | BE12: 52 | BF12: 53 | BG12: 54 | BH12: 55 | BI12: 56 | BJ12: 57 | BK12: 58 | BL12: 59 | BM12: 60 | BN12: 61 | BO12: 62 | BP12: 63 | BQ12: 64
A13: 1 | B13: งานเตรียมการและดำเนินงาน | C13: =SUM(C15:C20) -> 6269532.9
A15: 1.1 | B15: เตรียมการก่อสร้าง | C15: 2220160.6 | F15: 20 | G15: =F15 -> 20 | H15: =G15 -> 20 | I15: =H15 -> 20 | J15: =I15 -> 20 | K15: =J15 -> 20 | BR15: =SUM(F15:BQ15)*8 -> 960
BR16: =SUM(F16:BQ16)*8 -> 0 | BS16: =1-BR16 -> 1
A17: 1.2 | B17: ดำเนินการก่อสร้าง | C17: 3725346.6 | L17: 5 | M17: =L17 -> 5 | N17: =M17 -> 5 | O17: =N17 -> 5 | P17: =O17 -> 5 | Q17: =P17 -> 5 | R17: =Q17 -> 5 | S17: =R17 -> 5 | T17: =S17 -> 5 | ... X17: =W17 -> 5 | Z17: =X17 -> 5 | AA17: =Z17 -> 5 | AB17: =AA17 -> 5 | AC17: =AB17 -> 5 | AD17: =AC17 -> 5 | AE17: =AD17 -> 5 | AF17: =AE17 -> 5 | AG17: =AF17 -> 5 | AH17: =AG17 -> 5 | ... AL17: =AK17 -> 5 | AN17: =AL17 -> 5 | AO17: =AN17 -> 5 | AP17: =AO17 -> 5 | AQ17: =AP17 -> 5 | AR17: =AQ17 -> 5 | AS17: =AR17 -> 5 | AT17: =AS17 -> 5 | AU17: =AT17 -> 5 | AV17: =AU17 -> 5 | ... BI17: =BH17 -> 5 | BR17: =SUM(F17:BQ17)*8 -> 1920
BR18: =SUM(F18:BQ18)*8 -> 0
A19: 1.3 | B19: การส่งมอบงาน | C19: 324025.76 | BJ19: 5 | BK19: =BJ19 -> 5 | BL19: =BK19 -> 5 | BM19: =BL19 -> 5 | BN19: =BM19 -> 5 | BO19: =BN19 -> 5 | BP19: =BO19 -> 5 | BQ19: =BP19 -> 5 | BR19: =SUM(F19:BQ19)*8 -> 320
BR20: =SUM(F20:BQ20)*8 -> 0
A21: 2 | B21: งานโครสร้างอาคารโรงงาน | C21: =SUM(C23:C40) -> 54647766 | BR21: =SUM(F21:BQ21)*8 -> 0
BR22: =SUM(F22:BQ22)*8 -> 0
A23: 2.1 | B23: งานถมดินพร้อมบดอัด | C23: 0 | H23: =1/4 -> 0.25 | I23: =H23 -> 0.25 | J23: =I23 -> 0.25 | K23: =J23 -> 0.25 | BR23: =SUM(F23:BQ23)*8 -> 8
BR24: =SUM(F24:BQ24)*8 -> 0
A25: 2.2 | B25: งานเข็มตอก | C25: 15715922 | BR25: =SUM(F25:BQ25)*8 -> 0
BR26: =SUM(F26:BQ26)*8 -> 0
A27: 2.3 | B27: งานฐานรากและตอม่อ | C27: 1336651.7 | R27: 25 | S27: =R27 -> 25 | T27: =S27 -> 25 | U27: =T27 -> 25 | V27: =U27 -> 25 | W27: =V27 -> 25 | X27: =W27 -> 25 | BR27: =SUM(F27:BQ27)*8 -> 1400
BR28: =SUM(F28:BQ28)*8 -> 0
A29: 2.4 | B29: งานติดตั้งเสา | C29: 4751536.3 | V29: 7 | W29: =V29 -> 7 | X29: =W29 -> 7 | Z29: =X29 -> 7 | AA29: =Z29 -> 7 | AB29: =AA29 -> 7 | AC29: =AB29 -> 7 | AD29: =AC29 -> 7 | BR29: =SUM(F29:BQ29)*8 -> 448
BR30: =SUM(F30:BQ30)*8 -> 0
A31: 2.5 | B31: งานติดตั้งคาน | C31: 3464852.2 | AA31: 7 | AB31: =AA31 -> 7 | AC31: =AB31 -> 7 | AD31: =AC31 -> 7 | AE31: =AD31 -> 7 | AF31: =AE31 -> 7 | AG31: =AF31 -> 7 | AH31: =AG31 -> 7 | AI31: =AH31 -> 7 | AJ31: =AI31 -> 7 | BR31: =SUM(F31:BQ31)*8 -> 560
BR32: =SUM(F32:BQ32)*8 -> 0 | BS32: =1-BR32 -> 1
A33: 2.6 | B33: งานโครงสร้างหลังคา TRUSS | C33: 4819226.1 | AD33: 15 | AE33: =AD33 -> 15 | AF33: =AE33 -> 15 | AG33: =AF33 -> 15 | AH33: =AG33 -> 15 | AI33: =AH33 -> 15 | AJ33: =AI33 -> 15 | AK33: =AJ33 -> 15 | BR33: =SUM(F33:BQ33)*8 -> 960
BR34: =SUM(F34:BQ34)*8 -> 0
A35: 2.7 | B35: งานโครงสร้างพื้นชั้นที่ 1 | C35: 21495535 | AN35: 40 | AO35: =AN35 -> 40 | AP35: =AO35 -> 40 | AQ35: =AP35 -> 40 | AR35: =AQ35 -> 40 | AS35: =AR35 -> 40 | AT35: =AS35 -> 40 | AU35: =AT35 -> 40 | BR35: =SUM(F35:BQ35)*8 -> 2560
BR36: =SUM(F36:BQ36)*8 -> 0
A37: 2.8 | B37: งานบันได คสล | C37: 93301.39 | AQ37: 7 | AR37: =AQ37 -> 7 | AS37: =AR37 -> 7 | AT37: =AS37 -> 7 | AU37: =AT37 -> 7 | AV37: =AU37 -> 7 | AW37: =AV37 -> 7 | BR37: =SUM(F37:BQ37)*8 -> 392
BR38: =SUM(F38:BQ38)*8 -> 0
A39: 2.9 | B39: งานโครงสร้างอาคารสำนักงาน | C39: 2970741.4 | AN39: 25 | AO39: =AN39 -> 25 | AP39: =AO39 -> 25 | AQ39: =AP39 -> 25 | AR39: =AQ39 -> 25 | AS39: =AR39 -> 25 | AT39: =AS39 -> 25 | AU39: =AT39 -> 25 | AV39: =AU39 -> 25 | AW39: =AV39 -> 25 | BR39: =SUM(F39:BQ39)*8 -> 2000
BR40: =SUM(F40:BQ40)*8 -> 0
A41: 3 | B41: งานสถาปัตยกรรม | C41: =C43+C63 -> 22218557 | BR41: =SUM(F41:BQ41)*8 -> 0
BR42: =SUM(F42:BQ42)*8 -> 0
A43: B | B43: งานสถาปัตยกรรมโรงงาน | C43: =SUM(C45:C62) -> 17700507 | BR43: =SUM(F43:BQ43)*8 -> 0
BR44: =SUM(F44:BQ44)*8 -> 0
A45: 3.1 | B45: งานผนังและวัสดุตกแต่งผนัง | C45: 3350611.1 | AR45: 30 | AS45: =AR45 -> 30 | AT45: =AS45 -> 30 | AU45: =AT45 -> 30 | AV45: =AU45 -> 30 | AW45: =AV45 -> 30 | AX45: =AW45 -> 30 | AY45: =AX45 -> 30 | AZ45: =AY45 -> 30 | BA45: =AZ45 -> 30 | BR45: =SUM(F45:BQ45)*8 -> 2400
BR46: =SUM(F46:BQ46)*8 -> 0
A47: 3.2 | B47: งานพื้นและวัสดุตกแต่งพื้น | C47: 1378000 | AV47: 30 | AW47: =AV47 -> 30 | AX47: =AW47 -> 30 | AY47: =AX47 -> 30 | AZ47: =AY47 -> 30 | BA47: =AZ47 -> 30 | BB47: =BA47 -> 30 | BC47: =BB47 -> 30 | BD47: =BC47 -> 30 | BE47: =BD47 -> 30 | BR47: =SUM(F47:BQ47)*8 -> 2400
...
